Watching for file changes with StatReloader
"GET / HTTP/1.1" 200 1824
"GET /login/ HTTP/1.1" 200 697
Internal Server Error: /login/
Traceback (most recent call last):
  File "C:\mysite\venv\Lib\site-packages\django\core\handlers\exception.py", line 55, in inner
    response = get_response(request)
               ^^^^^^^^^^^^^^^^^^^^^
  File "C:\mysite\venv\Lib\site-packages\django\core\handlers\base.py", line 197, in _get_response
    response = wrapped_callback(request, *callback_args, **callback_kwargs)
               ^^^^^^^^^^^^^^^^^^^^^^^^^^^^^^^^^^^^^^^^^^^^^^^^^^^^^^^^^^^^
  File "C:\mysite\venv\Lib\site-packages\django\views\generic\base.py", line 104, in view
    return self.dispatch(request, *args, **kwargs)
           ^^^^^^^^^^^^^^^^^^^^^^^^^^^^^^^^^^^^^^^
  File "C:\mysite\venv\Lib\site-packages\django\views\generic\base.py", line 143, in dispatch
    return handler(request, *args, **kwargs)
           ^^^^^^^^^^^^^^^^^^^^^^^^^^^^^^^^^
  File "C:\mysite\shop\store\views.py", line 561, in post
    response = requests.post(f"{API_BASE_URL}auth/login/", json=data)
               ^^^^^^^^^^^^^^^^^^^^^^^^^^^^^^^^^^^^^^^^^^^^^^^^^^^^^^
  File "C:\mysite\venv\Lib\site-packages\requests\api.py", line 115, in post
    return request("post", url, data=data, json=json, **kwargs)
           ^^^^^^^^^^^^^^^^^^^^^^^^^^^^^^^^^^^^^^^^^^^^^^^^^^^^
  File "C:\mysite\venv\Lib\site-packages\requests\api.py", line 59, in request
    return session.request(method=method, url=url, **kwargs)
           ^^^^^^^^^^^^^^^^^^^^^^^^^^^^^^^^^^^^^^^^^^^^^^^^^
  File "C:\mysite\venv\Lib\site-packages\requests\sessions.py", line 575, in request
    prep = self.prepare_request(req)
           ^^^^^^^^^^^^^^^^^^^^^^^^^
  File "C:\mysite\venv\Lib\site-packages\requests\sessions.py", line 484, in prepare_request
    p.prepare(
  File "C:\mysite\venv\Lib\site-packages\requests\models.py", line 367, in prepare
    self.prepare_url(url, params)
  File "C:\mysite\venv\Lib\site-packages\requests\models.py", line 438, in prepare_url
    raise MissingSchema(
requests.exceptions.MissingSchema: Invalid URL '/api/auth/login/': No scheme supplied. Perhaps you meant https:///api/auth/login/?
"POST /login/ HTTP/1.1" 500 113802
Watching for file changes with StatReloader
"GET / HTTP/1.1" 200 1824
Internal Server Error: /products/
Traceback (most recent call last):
  File "C:\mysite\venv\Lib\site-packages\django\core\handlers\exception.py", line 55, in inner
    response = get_response(request)
               ^^^^^^^^^^^^^^^^^^^^^
  File "C:\mysite\venv\Lib\site-packages\django\core\handlers\base.py", line 197, in _get_response
    response = wrapped_callback(request, *callback_args, **callback_kwargs)
               ^^^^^^^^^^^^^^^^^^^^^^^^^^^^^^^^^^^^^^^^^^^^^^^^^^^^^^^^^^^^
  File "C:\mysite\shop\store\views.py", line 408, in products
    response = requests.get(f"{API_BASE_URL}products/")
               ^^^^^^^^^^^^^^^^^^^^^^^^^^^^^^^^^^^^^^^^
  File "C:\mysite\venv\Lib\site-packages\requests\api.py", line 73, in get
    return request("get", url, params=params, **kwargs)
           ^^^^^^^^^^^^^^^^^^^^^^^^^^^^^^^^^^^^^^^^^^^^
  File "C:\mysite\venv\Lib\site-packages\requests\api.py", line 59, in request
    return session.request(method=method, url=url, **kwargs)
           ^^^^^^^^^^^^^^^^^^^^^^^^^^^^^^^^^^^^^^^^^^^^^^^^^
  File "C:\mysite\venv\Lib\site-packages\requests\sessions.py", line 575, in request
    prep = self.prepare_request(req)
           ^^^^^^^^^^^^^^^^^^^^^^^^^
  File "C:\mysite\venv\Lib\site-packages\requests\sessions.py", line 484, in prepare_request
    p.prepare(
  File "C:\mysite\venv\Lib\site-packages\requests\models.py", line 367, in prepare
    self.prepare_url(url, params)
  File "C:\mysite\venv\Lib\site-packages\requests\models.py", line 438, in prepare_url
    raise MissingSchema(
requests.exceptions.MissingSchema: Invalid URL '/api/products/': No scheme supplied. Perhaps you meant https:///api/products/?
"GET /products/ HTTP/1.1" 500 102428
Internal Server Error: /products/
Traceback (most recent call last):
  File "C:\mysite\venv\Lib\site-packages\django\core\handlers\exception.py", line 55, in inner
    response = get_response(request)
               ^^^^^^^^^^^^^^^^^^^^^
  File "C:\mysite\venv\Lib\site-packages\django\core\handlers\base.py", line 197, in _get_response
    response = wrapped_callback(request, *callback_args, **callback_kwargs)
               ^^^^^^^^^^^^^^^^^^^^^^^^^^^^^^^^^^^^^^^^^^^^^^^^^^^^^^^^^^^^
  File "C:\mysite\shop\store\views.py", line 408, in products
    response = requests.get(f"{API_BASE_URL}products/")
               ^^^^^^^^^^^^^^^^^^^^^^^^^^^^^^^^^^^^^^^^
  File "C:\mysite\venv\Lib\site-packages\requests\api.py", line 73, in get
    return request("get", url, params=params, **kwargs)
           ^^^^^^^^^^^^^^^^^^^^^^^^^^^^^^^^^^^^^^^^^^^^
  File "C:\mysite\venv\Lib\site-packages\requests\api.py", line 59, in request
    return session.request(method=method, url=url, **kwargs)
           ^^^^^^^^^^^^^^^^^^^^^^^^^^^^^^^^^^^^^^^^^^^^^^^^^
  File "C:\mysite\venv\Lib\site-packages\requests\sessions.py", line 575, in request
    prep = self.prepare_request(req)
           ^^^^^^^^^^^^^^^^^^^^^^^^^
  File "C:\mysite\venv\Lib\site-packages\requests\sessions.py", line 484, in prepare_request
    p.prepare(
  File "C:\mysite\venv\Lib\site-packages\requests\models.py", line 367, in prepare
    self.prepare_url(url, params)
  File "C:\mysite\venv\Lib\site-packages\requests\models.py", line 438, in prepare_url
    raise MissingSchema(
requests.exceptions.MissingSchema: Invalid URL '/api/products/': No scheme supplied. Perhaps you meant https:///api/products/?
"GET /products/ HTTP/1.1" 500 102428
"GET /register/ HTTP/1.1" 200 0
"GET /login/ HTTP/1.1" 200 697
Internal Server Error: /products/
Traceback (most recent call last):
  File "C:\mysite\venv\Lib\site-packages\django\core\handlers\exception.py", line 55, in inner
    response = get_response(request)
               ^^^^^^^^^^^^^^^^^^^^^
  File "C:\mysite\venv\Lib\site-packages\django\core\handlers\base.py", line 197, in _get_response
    response = wrapped_callback(request, *callback_args, **callback_kwargs)
               ^^^^^^^^^^^^^^^^^^^^^^^^^^^^^^^^^^^^^^^^^^^^^^^^^^^^^^^^^^^^
  File "C:\mysite\shop\store\views.py", line 408, in products
    response = requests.get(f"{API_BASE_URL}products/")
               ^^^^^^^^^^^^^^^^^^^^^^^^^^^^^^^^^^^^^^^^
  File "C:\mysite\venv\Lib\site-packages\requests\api.py", line 73, in get
    return request("get", url, params=params, **kwargs)
           ^^^^^^^^^^^^^^^^^^^^^^^^^^^^^^^^^^^^^^^^^^^^
  File "C:\mysite\venv\Lib\site-packages\requests\api.py", line 59, in request
    return session.request(method=method, url=url, **kwargs)
           ^^^^^^^^^^^^^^^^^^^^^^^^^^^^^^^^^^^^^^^^^^^^^^^^^
  File "C:\mysite\venv\Lib\site-packages\requests\sessions.py", line 575, in request
    prep = self.prepare_request(req)
           ^^^^^^^^^^^^^^^^^^^^^^^^^
  File "C:\mysite\venv\Lib\site-packages\requests\sessions.py", line 484, in prepare_request
    p.prepare(
  File "C:\mysite\venv\Lib\site-packages\requests\models.py", line 367, in prepare
    self.prepare_url(url, params)
  File "C:\mysite\venv\Lib\site-packages\requests\models.py", line 438, in prepare_url
    raise MissingSchema(
requests.exceptions.MissingSchema: Invalid URL '/api/products/': No scheme supplied. Perhaps you meant https:///api/products/?
"GET /products/ HTTP/1.1" 500 102428
"GET /cart/ HTTP/1.1" 302 0
"GET /login/?next=/cart/ HTTP/1.1" 200 697
Watching for file changes with StatReloader
"GET / HTTP/1.1" 200 1824
Internal Server Error: /products/
Traceback (most recent call last):
  File "C:\mysite\venv\Lib\site-packages\django\core\handlers\exception.py", line 55, in inner
    response = get_response(request)
               ^^^^^^^^^^^^^^^^^^^^^
  File "C:\mysite\venv\Lib\site-packages\django\core\handlers\base.py", line 197, in _get_response
    response = wrapped_callback(request, *callback_args, **callback_kwargs)
               ^^^^^^^^^^^^^^^^^^^^^^^^^^^^^^^^^^^^^^^^^^^^^^^^^^^^^^^^^^^^
  File "C:\mysite\shop\store\views.py", line 21, in products
    response = requests.get(f"{API_BASE_URL}products/")
               ^^^^^^^^^^^^^^^^^^^^^^^^^^^^^^^^^^^^^^^^
  File "C:\mysite\venv\Lib\site-packages\requests\api.py", line 73, in get
    return request("get", url, params=params, **kwargs)
           ^^^^^^^^^^^^^^^^^^^^^^^^^^^^^^^^^^^^^^^^^^^^
  File "C:\mysite\venv\Lib\site-packages\requests\api.py", line 59, in request
    return session.request(method=method, url=url, **kwargs)
           ^^^^^^^^^^^^^^^^^^^^^^^^^^^^^^^^^^^^^^^^^^^^^^^^^
  File "C:\mysite\venv\Lib\site-packages\requests\sessions.py", line 575, in request
    prep = self.prepare_request(req)
           ^^^^^^^^^^^^^^^^^^^^^^^^^
  File "C:\mysite\venv\Lib\site-packages\requests\sessions.py", line 484, in prepare_request
    p.prepare(
  File "C:\mysite\venv\Lib\site-packages\requests\models.py", line 367, in prepare
    self.prepare_url(url, params)
  File "C:\mysite\venv\Lib\site-packages\requests\models.py", line 438, in prepare_url
    raise MissingSchema(
requests.exceptions.MissingSchema: Invalid URL '/api/products/': No scheme supplied. Perhaps you meant https:///api/products/?
"GET /products/ HTTP/1.1" 500 102411
C:\mysite\shop\store\urls.py changed, reloading.
Watching for file changes with StatReloader
"GET / HTTP/1.1" 200 1824
Internal Server Error: /products/
Traceback (most recent call last):
  File "C:\mysite\venv\Lib\site-packages\django\core\handlers\exception.py", line 55, in inner
    response = get_response(request)
               ^^^^^^^^^^^^^^^^^^^^^
  File "C:\mysite\venv\Lib\site-packages\django\core\handlers\base.py", line 197, in _get_response
    response = wrapped_callback(request, *callback_args, **callback_kwargs)
               ^^^^^^^^^^^^^^^^^^^^^^^^^^^^^^^^^^^^^^^^^^^^^^^^^^^^^^^^^^^^
  File "C:\mysite\shop\store\views.py", line 21, in products
    response = requests.get(f"{API_BASE_URL}products/")
               ^^^^^^^^^^^^^^^^^^^^^^^^^^^^^^^^^^^^^^^^
  File "C:\mysite\venv\Lib\site-packages\requests\api.py", line 73, in get
    return request("get", url, params=params, **kwargs)
           ^^^^^^^^^^^^^^^^^^^^^^^^^^^^^^^^^^^^^^^^^^^^
  File "C:\mysite\venv\Lib\site-packages\requests\api.py", line 59, in request
    return session.request(method=method, url=url, **kwargs)
           ^^^^^^^^^^^^^^^^^^^^^^^^^^^^^^^^^^^^^^^^^^^^^^^^^
  File "C:\mysite\venv\Lib\site-packages\requests\sessions.py", line 575, in request
    prep = self.prepare_request(req)
           ^^^^^^^^^^^^^^^^^^^^^^^^^
  File "C:\mysite\venv\Lib\site-packages\requests\sessions.py", line 484, in prepare_request
    p.prepare(
  File "C:\mysite\venv\Lib\site-packages\requests\models.py", line 367, in prepare
    self.prepare_url(url, params)
  File "C:\mysite\venv\Lib\site-packages\requests\models.py", line 438, in prepare_url
    raise MissingSchema(
requests.exceptions.MissingSchema: Invalid URL '/api/products/': No scheme supplied. Perhaps you meant https:///api/products/?
"GET /products/ HTTP/1.1" 500 102411
Internal Server Error: /products/
Traceback (most recent call last):
  File "C:\mysite\venv\Lib\site-packages\django\core\handlers\exception.py", line 55, in inner
    response = get_response(request)
               ^^^^^^^^^^^^^^^^^^^^^
  File "C:\mysite\venv\Lib\site-packages\django\core\handlers\base.py", line 197, in _get_response
    response = wrapped_callback(request, *callback_args, **callback_kwargs)
               ^^^^^^^^^^^^^^^^^^^^^^^^^^^^^^^^^^^^^^^^^^^^^^^^^^^^^^^^^^^^
  File "C:\mysite\shop\store\views.py", line 21, in products
    response = requests.get(f"{API_BASE_URL}products/")
               ^^^^^^^^^^^^^^^^^^^^^^^^^^^^^^^^^^^^^^^^
  File "C:\mysite\venv\Lib\site-packages\requests\api.py", line 73, in get
    return request("get", url, params=params, **kwargs)
           ^^^^^^^^^^^^^^^^^^^^^^^^^^^^^^^^^^^^^^^^^^^^
  File "C:\mysite\venv\Lib\site-packages\requests\api.py", line 59, in request
    return session.request(method=method, url=url, **kwargs)
           ^^^^^^^^^^^^^^^^^^^^^^^^^^^^^^^^^^^^^^^^^^^^^^^^^
  File "C:\mysite\venv\Lib\site-packages\requests\sessions.py", line 575, in request
    prep = self.prepare_request(req)
           ^^^^^^^^^^^^^^^^^^^^^^^^^
  File "C:\mysite\venv\Lib\site-packages\requests\sessions.py", line 484, in prepare_request
    p.prepare(
  File "C:\mysite\venv\Lib\site-packages\requests\models.py", line 367, in prepare
    self.prepare_url(url, params)
  File "C:\mysite\venv\Lib\site-packages\requests\models.py", line 438, in prepare_url
    raise MissingSchema(
requests.exceptions.MissingSchema: Invalid URL '/api/products/': No scheme supplied. Perhaps you meant https:///api/products/?
"GET /products/ HTTP/1.1" 500 102411
Watching for file changes with StatReloader
"GET / HTTP/1.1" 200 1824
"GET /api/products/ HTTP/1.1" 200 361
"GET /products/ HTTP/1.1" 200 4822
"GET /login/ HTTP/1.1" 200 697
Internal Server Error: /login/
Traceback (most recent call last):
  File "C:\mysite\venv\Lib\site-packages\django\core\handlers\exception.py", line 55, in inner
    response = get_response(request)
               ^^^^^^^^^^^^^^^^^^^^^
  File "C:\mysite\venv\Lib\site-packages\django\core\handlers\base.py", line 197, in _get_response
    response = wrapped_callback(request, *callback_args, **callback_kwargs)
               ^^^^^^^^^^^^^^^^^^^^^^^^^^^^^^^^^^^^^^^^^^^^^^^^^^^^^^^^^^^^
  File "C:\mysite\venv\Lib\site-packages\django\views\generic\base.py", line 104, in view
    return self.dispatch(request, *args, **kwargs)
           ^^^^^^^^^^^^^^^^^^^^^^^^^^^^^^^^^^^^^^^
  File "C:\mysite\venv\Lib\site-packages\django\views\generic\base.py", line 143, in dispatch
    return handler(request, *args, **kwargs)
           ^^^^^^^^^^^^^^^^^^^^^^^^^^^^^^^^^
  File "C:\mysite\shop\store\views.py", line 171, in post
    response = requests.post(f"{API_BASE_URL}auth/login/", json=data)
               ^^^^^^^^^^^^^^^^^^^^^^^^^^^^^^^^^^^^^^^^^^^^^^^^^^^^^^
  File "C:\mysite\venv\Lib\site-packages\requests\api.py", line 115, in post
    return request("post", url, data=data, json=json, **kwargs)
           ^^^^^^^^^^^^^^^^^^^^^^^^^^^^^^^^^^^^^^^^^^^^^^^^^^^^
  File "C:\mysite\venv\Lib\site-packages\requests\api.py", line 59, in request
    return session.request(method=method, url=url, **kwargs)
           ^^^^^^^^^^^^^^^^^^^^^^^^^^^^^^^^^^^^^^^^^^^^^^^^^
  File "C:\mysite\venv\Lib\site-packages\requests\sessions.py", line 575, in request
    prep = self.prepare_request(req)
           ^^^^^^^^^^^^^^^^^^^^^^^^^
  File "C:\mysite\venv\Lib\site-packages\requests\sessions.py", line 484, in prepare_request
    p.prepare(
  File "C:\mysite\venv\Lib\site-packages\requests\models.py", line 367, in prepare
    self.prepare_url(url, params)
  File "C:\mysite\venv\Lib\site-packages\requests\models.py", line 438, in prepare_url
    raise MissingSchema(
requests.exceptions.MissingSchema: Invalid URL '/api/auth/login/': No scheme supplied. Perhaps you meant https:///api/auth/login/?
"POST /login/ HTTP/1.1" 500 114140
Internal Server Error: /login/
Traceback (most recent call last):
  File "C:\mysite\venv\Lib\site-packages\django\core\handlers\exception.py", line 55, in inner
    response = get_response(request)
               ^^^^^^^^^^^^^^^^^^^^^
  File "C:\mysite\venv\Lib\site-packages\django\core\handlers\base.py", line 197, in _get_response
    response = wrapped_callback(request, *callback_args, **callback_kwargs)
               ^^^^^^^^^^^^^^^^^^^^^^^^^^^^^^^^^^^^^^^^^^^^^^^^^^^^^^^^^^^^
  File "C:\mysite\venv\Lib\site-packages\django\views\generic\base.py", line 104, in view
    return self.dispatch(request, *args, **kwargs)
           ^^^^^^^^^^^^^^^^^^^^^^^^^^^^^^^^^^^^^^^
  File "C:\mysite\venv\Lib\site-packages\django\views\generic\base.py", line 143, in dispatch
    return handler(request, *args, **kwargs)
           ^^^^^^^^^^^^^^^^^^^^^^^^^^^^^^^^^
  File "C:\mysite\shop\store\views.py", line 171, in post
    response = requests.post(f"{API_BASE_URL}auth/login/", json=data)
               ^^^^^^^^^^^^^^^^^^^^^^^^^^^^^^^^^^^^^^^^^^^^^^^^^^^^^^
  File "C:\mysite\venv\Lib\site-packages\requests\api.py", line 115, in post
    return request("post", url, data=data, json=json, **kwargs)
           ^^^^^^^^^^^^^^^^^^^^^^^^^^^^^^^^^^^^^^^^^^^^^^^^^^^^
  File "C:\mysite\venv\Lib\site-packages\requests\api.py", line 59, in request
    return session.request(method=method, url=url, **kwargs)
           ^^^^^^^^^^^^^^^^^^^^^^^^^^^^^^^^^^^^^^^^^^^^^^^^^
  File "C:\mysite\venv\Lib\site-packages\requests\sessions.py", line 575, in request
    prep = self.prepare_request(req)
           ^^^^^^^^^^^^^^^^^^^^^^^^^
  File "C:\mysite\venv\Lib\site-packages\requests\sessions.py", line 484, in prepare_request
    p.prepare(
  File "C:\mysite\venv\Lib\site-packages\requests\models.py", line 367, in prepare
    self.prepare_url(url, params)
  File "C:\mysite\venv\Lib\site-packages\requests\models.py", line 438, in prepare_url
    raise MissingSchema(
requests.exceptions.MissingSchema: Invalid URL '/api/auth/login/': No scheme supplied. Perhaps you meant https:///api/auth/login/?
"POST /login/ HTTP/1.1" 500 114188
"GET /api/products/ HTTP/1.1" 200 361
"GET /products/ HTTP/1.1" 200 4822
"GET /login/ HTTP/1.1" 200 697
"GET /register/ HTTP/1.1" 200 0
"GET /register/ HTTP/1.1" 200 0
C:\mysite\shop\store\views.py changed, reloading.
Watching for file changes with StatReloader
C:\mysite\shop\store\views.py changed, reloading.
Watching for file changes with StatReloader
Watching for file changes with StatReloader
"GET / HTTP/1.1" 200 1824
"GET /api/products/ HTTP/1.1" 200 361
"GET /products/ HTTP/1.1" 200 4822
"GET /api/products/ HTTP/1.1" 200 361
"GET /products/ HTTP/1.1" 200 4822
"GET /login/ HTTP/1.1" 200 697
"POST /api/auth/login/ HTTP/1.1" 200 483
"POST /login/ HTTP/1.1" 302 0
"GET / HTTP/1.1" 200 1815
"GET /profile/ HTTP/1.1" 200 0
"GET /api/products/ HTTP/1.1" 200 361
"GET /products/ HTTP/1.1" 200 4833
"GET /api/carts/ HTTP/1.1" 200 140
"POST /api/cart-items/ HTTP/1.1" 201 33
"POST /cart/ HTTP/1.1" 200 21
"GET /api/carts/ HTTP/1.1" 200 174
Internal Server Error: /cart/
Traceback (most recent call last):
  File "C:\mysite\venv\Lib\site-packages\django\core\handlers\exception.py", line 55, in inner
    response = get_response(request)
               ^^^^^^^^^^^^^^^^^^^^^
  File "C:\mysite\venv\Lib\site-packages\django\core\handlers\base.py", line 197, in _get_response
    response = wrapped_callback(request, *callback_args, **callback_kwargs)
               ^^^^^^^^^^^^^^^^^^^^^^^^^^^^^^^^^^^^^^^^^^^^^^^^^^^^^^^^^^^^
  File "C:\mysite\venv\Lib\site-packages\django\contrib\auth\decorators.py", line 59, in _view_wrapper
    return view_func(request, *args, **kwargs)
           ^^^^^^^^^^^^^^^^^^^^^^^^^^^^^^^^^^^
  File "C:\mysite\shop\store\views.py", line 153, in cart
    return render(request, 'store/cart.html', {'cart': cart})
           ^^^^^^^^^^^^^^^^^^^^^^^^^^^^^^^^^^^^^^^^^^^^^^^^^^
  File "C:\mysite\venv\Lib\site-packages\django\shortcuts.py", line 25, in render
    content = loader.render_to_string(template_name, context, request, using=using)
              ^^^^^^^^^^^^^^^^^^^^^^^^^^^^^^^^^^^^^^^^^^^^^^^^^^^^^^^^^^^^^^^^^^^^^
  File "C:\mysite\venv\Lib\site-packages\django\template\loader.py", line 61, in render_to_string
    template = get_template(template_name, using=using)
               ^^^^^^^^^^^^^^^^^^^^^^^^^^^^^^^^^^^^^^^^
  File "C:\mysite\venv\Lib\site-packages\django\template\loader.py", line 15, in get_template
    return engine.get_template(template_name)
           ^^^^^^^^^^^^^^^^^^^^^^^^^^^^^^^^^^
  File "C:\mysite\venv\Lib\site-packages\django\template\backends\django.py", line 79, in get_template
    return Template(self.engine.get_template(template_name), self)
                    ^^^^^^^^^^^^^^^^^^^^^^^^^^^^^^^^^^^^^^^
  File "C:\mysite\venv\Lib\site-packages\django\template\engine.py", line 177, in get_template
    template, origin = self.find_template(template_name)
                       ^^^^^^^^^^^^^^^^^^^^^^^^^^^^^^^^^
  File "C:\mysite\venv\Lib\site-packages\django\template\engine.py", line 159, in find_template
    template = loader.get_template(name, skip=skip)
               ^^^^^^^^^^^^^^^^^^^^^^^^^^^^^^^^^^^^
  File "C:\mysite\venv\Lib\site-packages\django\template\loaders\cached.py", line 57, in get_template
    template = super().get_template(template_name, skip)
               ^^^^^^^^^^^^^^^^^^^^^^^^^^^^^^^^^^^^^^^^^
  File "C:\mysite\venv\Lib\site-packages\django\template\loaders\base.py", line 28, in get_template
    return Template(
           ^^^^^^^^^
  File "C:\mysite\venv\Lib\site-packages\django\template\base.py", line 154, in __init__
    self.nodelist = self.compile_nodelist()
                    ^^^^^^^^^^^^^^^^^^^^^^^
  File "C:\mysite\venv\Lib\site-packages\django\template\base.py", line 196, in compile_nodelist
    nodelist = parser.parse()
               ^^^^^^^^^^^^^^
  File "C:\mysite\venv\Lib\site-packages\django\template\base.py", line 518, in parse
    raise self.error(token, e)
  File "C:\mysite\venv\Lib\site-packages\django\template\base.py", line 516, in parse
    compiled_result = compile_func(self, token)
                      ^^^^^^^^^^^^^^^^^^^^^^^^^
  File "C:\mysite\venv\Lib\site-packages\django\template\loader_tags.py", line 299, in do_extends
    nodelist = parser.parse()
               ^^^^^^^^^^^^^^
  File "C:\mysite\venv\Lib\site-packages\django\template\base.py", line 518, in parse
    raise self.error(token, e)
  File "C:\mysite\venv\Lib\site-packages\django\template\base.py", line 516, in parse
    compiled_result = compile_func(self, token)
                      ^^^^^^^^^^^^^^^^^^^^^^^^^
  File "C:\mysite\venv\Lib\site-packages\django\template\loader_tags.py", line 234, in do_block
    nodelist = parser.parse(("endblock",))
               ^^^^^^^^^^^^^^^^^^^^^^^^^^^
  File "C:\mysite\venv\Lib\site-packages\django\template\base.py", line 518, in parse
    raise self.error(token, e)
  File "C:\mysite\venv\Lib\site-packages\django\template\base.py", line 516, in parse
    compiled_result = compile_func(self, token)
                      ^^^^^^^^^^^^^^^^^^^^^^^^^
  File "C:\mysite\venv\Lib\site-packages\django\template\defaulttags.py", line 962, in do_if
    nodelist = parser.parse(("elif", "else", "endif"))
               ^^^^^^^^^^^^^^^^^^^^^^^^^^^^^^^^^^^^^^^
  File "C:\mysite\venv\Lib\site-packages\django\template\base.py", line 518, in parse
    raise self.error(token, e)
  File "C:\mysite\venv\Lib\site-packages\django\template\base.py", line 516, in parse
    compiled_result = compile_func(self, token)
                      ^^^^^^^^^^^^^^^^^^^^^^^^^
  File "C:\mysite\venv\Lib\site-packages\django\template\defaulttags.py", line 862, in do_for
    nodelist_loop = parser.parse(
                    ^^^^^^^^^^^^^
  File "C:\mysite\venv\Lib\site-packages\django\template\base.py", line 489, in parse
    raise self.error(token, e)
  File "C:\mysite\venv\Lib\site-packages\django\template\base.py", line 487, in parse
    filter_expression = self.compile_filter(token.contents)
                        ^^^^^^^^^^^^^^^^^^^^^^^^^^^^^^^^^^^
  File "C:\mysite\venv\Lib\site-packages\django\template\base.py", line 609, in compile_filter
    return FilterExpression(token, self)
           ^^^^^^^^^^^^^^^^^^^^^^^^^^^^^
  File "C:\mysite\venv\Lib\site-packages\django\template\base.py", line 710, in __init__
    raise TemplateSyntaxError(
django.template.exceptions.TemplateSyntaxError: Could not parse the remainder: ' * item.quantity' from 'item.product.price * item.quantity'
"GET /cart/ HTTP/1.1" 500 248185
"GET /api/carts/ HTTP/1.1" 200 174
Internal Server Error: /cart/
Traceback (most recent call last):
  File "C:\mysite\venv\Lib\site-packages\django\core\handlers\exception.py", line 55, in inner
    response = get_response(request)
               ^^^^^^^^^^^^^^^^^^^^^
  File "C:\mysite\venv\Lib\site-packages\django\core\handlers\base.py", line 197, in _get_response
    response = wrapped_callback(request, *callback_args, **callback_kwargs)
               ^^^^^^^^^^^^^^^^^^^^^^^^^^^^^^^^^^^^^^^^^^^^^^^^^^^^^^^^^^^^
  File "C:\mysite\venv\Lib\site-packages\django\contrib\auth\decorators.py", line 59, in _view_wrapper
    return view_func(request, *args, **kwargs)
           ^^^^^^^^^^^^^^^^^^^^^^^^^^^^^^^^^^^
  File "C:\mysite\shop\store\views.py", line 153, in cart
    return render(request, 'store/cart.html', {'cart': cart})
           ^^^^^^^^^^^^^^^^^^^^^^^^^^^^^^^^^^^^^^^^^^^^^^^^^^
  File "C:\mysite\venv\Lib\site-packages\django\shortcuts.py", line 25, in render
    content = loader.render_to_string(template_name, context, request, using=using)
              ^^^^^^^^^^^^^^^^^^^^^^^^^^^^^^^^^^^^^^^^^^^^^^^^^^^^^^^^^^^^^^^^^^^^^
  File "C:\mysite\venv\Lib\site-packages\django\template\loader.py", line 61, in render_to_string
    template = get_template(template_name, using=using)
               ^^^^^^^^^^^^^^^^^^^^^^^^^^^^^^^^^^^^^^^^
  File "C:\mysite\venv\Lib\site-packages\django\template\loader.py", line 15, in get_template
    return engine.get_template(template_name)
           ^^^^^^^^^^^^^^^^^^^^^^^^^^^^^^^^^^
  File "C:\mysite\venv\Lib\site-packages\django\template\backends\django.py", line 79, in get_template
    return Template(self.engine.get_template(template_name), self)
                    ^^^^^^^^^^^^^^^^^^^^^^^^^^^^^^^^^^^^^^^
  File "C:\mysite\venv\Lib\site-packages\django\template\engine.py", line 177, in get_template
    template, origin = self.find_template(template_name)
                       ^^^^^^^^^^^^^^^^^^^^^^^^^^^^^^^^^
  File "C:\mysite\venv\Lib\site-packages\django\template\engine.py", line 159, in find_template
    template = loader.get_template(name, skip=skip)
               ^^^^^^^^^^^^^^^^^^^^^^^^^^^^^^^^^^^^
  File "C:\mysite\venv\Lib\site-packages\django\template\loaders\cached.py", line 57, in get_template
    template = super().get_template(template_name, skip)
               ^^^^^^^^^^^^^^^^^^^^^^^^^^^^^^^^^^^^^^^^^
  File "C:\mysite\venv\Lib\site-packages\django\template\loaders\base.py", line 28, in get_template
    return Template(
           ^^^^^^^^^
  File "C:\mysite\venv\Lib\site-packages\django\template\base.py", line 154, in __init__
    self.nodelist = self.compile_nodelist()
                    ^^^^^^^^^^^^^^^^^^^^^^^
  File "C:\mysite\venv\Lib\site-packages\django\template\base.py", line 196, in compile_nodelist
    nodelist = parser.parse()
               ^^^^^^^^^^^^^^
  File "C:\mysite\venv\Lib\site-packages\django\template\base.py", line 518, in parse
    raise self.error(token, e)
  File "C:\mysite\venv\Lib\site-packages\django\template\base.py", line 516, in parse
    compiled_result = compile_func(self, token)
                      ^^^^^^^^^^^^^^^^^^^^^^^^^
  File "C:\mysite\venv\Lib\site-packages\django\template\loader_tags.py", line 299, in do_extends
    nodelist = parser.parse()
               ^^^^^^^^^^^^^^
  File "C:\mysite\venv\Lib\site-packages\django\template\base.py", line 518, in parse
    raise self.error(token, e)
  File "C:\mysite\venv\Lib\site-packages\django\template\base.py", line 516, in parse
    compiled_result = compile_func(self, token)
                      ^^^^^^^^^^^^^^^^^^^^^^^^^
  File "C:\mysite\venv\Lib\site-packages\django\template\loader_tags.py", line 234, in do_block
    nodelist = parser.parse(("endblock",))
               ^^^^^^^^^^^^^^^^^^^^^^^^^^^
  File "C:\mysite\venv\Lib\site-packages\django\template\base.py", line 518, in parse
    raise self.error(token, e)
  File "C:\mysite\venv\Lib\site-packages\django\template\base.py", line 516, in parse
    compiled_result = compile_func(self, token)
                      ^^^^^^^^^^^^^^^^^^^^^^^^^
  File "C:\mysite\venv\Lib\site-packages\django\template\defaulttags.py", line 962, in do_if
    nodelist = parser.parse(("elif", "else", "endif"))
               ^^^^^^^^^^^^^^^^^^^^^^^^^^^^^^^^^^^^^^^
  File "C:\mysite\venv\Lib\site-packages\django\template\base.py", line 518, in parse
    raise self.error(token, e)
  File "C:\mysite\venv\Lib\site-packages\django\template\base.py", line 516, in parse
    compiled_result = compile_func(self, token)
                      ^^^^^^^^^^^^^^^^^^^^^^^^^
  File "C:\mysite\venv\Lib\site-packages\django\template\defaulttags.py", line 862, in do_for
    nodelist_loop = parser.parse(
                    ^^^^^^^^^^^^^
  File "C:\mysite\venv\Lib\site-packages\django\template\base.py", line 489, in parse
    raise self.error(token, e)
  File "C:\mysite\venv\Lib\site-packages\django\template\base.py", line 487, in parse
    filter_expression = self.compile_filter(token.contents)
                        ^^^^^^^^^^^^^^^^^^^^^^^^^^^^^^^^^^^
  File "C:\mysite\venv\Lib\site-packages\django\template\base.py", line 609, in compile_filter
    return FilterExpression(token, self)
           ^^^^^^^^^^^^^^^^^^^^^^^^^^^^^
  File "C:\mysite\venv\Lib\site-packages\django\template\base.py", line 705, in __init__
    filter_func = parser.find_filter(filter_name)
                  ^^^^^^^^^^^^^^^^^^^^^^^^^^^^^^^
  File "C:\mysite\venv\Lib\site-packages\django\template\base.py", line 615, in find_filter
    raise TemplateSyntaxError("Invalid filter: '%s'" % filter_name)
django.template.exceptions.TemplateSyntaxError: Invalid filter: 'mul'
"GET /cart/ HTTP/1.1" 500 247669
"GET /api/carts/ HTTP/1.1" 200 174
Internal Server Error: /cart/
Traceback (most recent call last):
  File "C:\mysite\venv\Lib\site-packages\django\core\handlers\exception.py", line 55, in inner
    response = get_response(request)
               ^^^^^^^^^^^^^^^^^^^^^
  File "C:\mysite\venv\Lib\site-packages\django\core\handlers\base.py", line 197, in _get_response
    response = wrapped_callback(request, *callback_args, **callback_kwargs)
               ^^^^^^^^^^^^^^^^^^^^^^^^^^^^^^^^^^^^^^^^^^^^^^^^^^^^^^^^^^^^
  File "C:\mysite\venv\Lib\site-packages\django\contrib\auth\decorators.py", line 59, in _view_wrapper
    return view_func(request, *args, **kwargs)
           ^^^^^^^^^^^^^^^^^^^^^^^^^^^^^^^^^^^
  File "C:\mysite\shop\store\views.py", line 153, in cart
    return render(request, 'store/cart.html', {'cart': cart})
           ^^^^^^^^^^^^^^^^^^^^^^^^^^^^^^^^^^^^^^^^^^^^^^^^^^
  File "C:\mysite\venv\Lib\site-packages\django\shortcuts.py", line 25, in render
    content = loader.render_to_string(template_name, context, request, using=using)
              ^^^^^^^^^^^^^^^^^^^^^^^^^^^^^^^^^^^^^^^^^^^^^^^^^^^^^^^^^^^^^^^^^^^^^
  File "C:\mysite\venv\Lib\site-packages\django\template\loader.py", line 61, in render_to_string
    template = get_template(template_name, using=using)
               ^^^^^^^^^^^^^^^^^^^^^^^^^^^^^^^^^^^^^^^^
  File "C:\mysite\venv\Lib\site-packages\django\template\loader.py", line 15, in get_template
    return engine.get_template(template_name)
           ^^^^^^^^^^^^^^^^^^^^^^^^^^^^^^^^^^
  File "C:\mysite\venv\Lib\site-packages\django\template\backends\django.py", line 79, in get_template
    return Template(self.engine.get_template(template_name), self)
                    ^^^^^^^^^^^^^^^^^^^^^^^^^^^^^^^^^^^^^^^
  File "C:\mysite\venv\Lib\site-packages\django\template\engine.py", line 177, in get_template
    template, origin = self.find_template(template_name)
                       ^^^^^^^^^^^^^^^^^^^^^^^^^^^^^^^^^
  File "C:\mysite\venv\Lib\site-packages\django\template\engine.py", line 159, in find_template
    template = loader.get_template(name, skip=skip)
               ^^^^^^^^^^^^^^^^^^^^^^^^^^^^^^^^^^^^
  File "C:\mysite\venv\Lib\site-packages\django\template\loaders\cached.py", line 57, in get_template
    template = super().get_template(template_name, skip)
               ^^^^^^^^^^^^^^^^^^^^^^^^^^^^^^^^^^^^^^^^^
  File "C:\mysite\venv\Lib\site-packages\django\template\loaders\base.py", line 28, in get_template
    return Template(
           ^^^^^^^^^
  File "C:\mysite\venv\Lib\site-packages\django\template\base.py", line 154, in __init__
    self.nodelist = self.compile_nodelist()
                    ^^^^^^^^^^^^^^^^^^^^^^^
  File "C:\mysite\venv\Lib\site-packages\django\template\base.py", line 196, in compile_nodelist
    nodelist = parser.parse()
               ^^^^^^^^^^^^^^
  File "C:\mysite\venv\Lib\site-packages\django\template\base.py", line 518, in parse
    raise self.error(token, e)
  File "C:\mysite\venv\Lib\site-packages\django\template\base.py", line 516, in parse
    compiled_result = compile_func(self, token)
                      ^^^^^^^^^^^^^^^^^^^^^^^^^
  File "C:\mysite\venv\Lib\site-packages\django\template\loader_tags.py", line 299, in do_extends
    nodelist = parser.parse()
               ^^^^^^^^^^^^^^
  File "C:\mysite\venv\Lib\site-packages\django\template\base.py", line 518, in parse
    raise self.error(token, e)
  File "C:\mysite\venv\Lib\site-packages\django\template\base.py", line 516, in parse
    compiled_result = compile_func(self, token)
                      ^^^^^^^^^^^^^^^^^^^^^^^^^
  File "C:\mysite\venv\Lib\site-packages\django\template\loader_tags.py", line 234, in do_block
    nodelist = parser.parse(("endblock",))
               ^^^^^^^^^^^^^^^^^^^^^^^^^^^
  File "C:\mysite\venv\Lib\site-packages\django\template\base.py", line 518, in parse
    raise self.error(token, e)
  File "C:\mysite\venv\Lib\site-packages\django\template\base.py", line 516, in parse
    compiled_result = compile_func(self, token)
                      ^^^^^^^^^^^^^^^^^^^^^^^^^
  File "C:\mysite\venv\Lib\site-packages\django\template\defaulttags.py", line 962, in do_if
    nodelist = parser.parse(("elif", "else", "endif"))
               ^^^^^^^^^^^^^^^^^^^^^^^^^^^^^^^^^^^^^^^
  File "C:\mysite\venv\Lib\site-packages\django\template\base.py", line 518, in parse
    raise self.error(token, e)
  File "C:\mysite\venv\Lib\site-packages\django\template\base.py", line 516, in parse
    compiled_result = compile_func(self, token)
                      ^^^^^^^^^^^^^^^^^^^^^^^^^
  File "C:\mysite\venv\Lib\site-packages\django\template\defaulttags.py", line 862, in do_for
    nodelist_loop = parser.parse(
                    ^^^^^^^^^^^^^
  File "C:\mysite\venv\Lib\site-packages\django\template\base.py", line 489, in parse
    raise self.error(token, e)
  File "C:\mysite\venv\Lib\site-packages\django\template\base.py", line 487, in parse
    filter_expression = self.compile_filter(token.contents)
                        ^^^^^^^^^^^^^^^^^^^^^^^^^^^^^^^^^^^
  File "C:\mysite\venv\Lib\site-packages\django\template\base.py", line 609, in compile_filter
    return FilterExpression(token, self)
           ^^^^^^^^^^^^^^^^^^^^^^^^^^^^^
  File "C:\mysite\venv\Lib\site-packages\django\template\base.py", line 705, in __init__
    filter_func = parser.find_filter(filter_name)
                  ^^^^^^^^^^^^^^^^^^^^^^^^^^^^^^^
  File "C:\mysite\venv\Lib\site-packages\django\template\base.py", line 615, in find_filter
    raise TemplateSyntaxError("Invalid filter: '%s'" % filter_name)
django.template.exceptions.TemplateSyntaxError: Invalid filter: 'mul'
"GET /cart/ HTTP/1.1" 500 247532
Watching for file changes with StatReloader
"GET / HTTP/1.1" 200 1815
"GET /api/products/ HTTP/1.1" 200 360
"GET /products/ HTTP/1.1" 200 4832
"GET /api/carts/ HTTP/1.1" 200 152
"POST /api/cart-items/ HTTP/1.1" 201 33
"POST /cart/ HTTP/1.1" 200 21
"GET /api/carts/ HTTP/1.1" 200 186
"POST /api/cart-items/ HTTP/1.1" 201 33
"POST /cart/ HTTP/1.1" 200 21
"GET /api/carts/ HTTP/1.1" 200 220
Internal Server Error: /cart/
Traceback (most recent call last):
  File "C:\mysite\venv\Lib\site-packages\django\core\handlers\exception.py", line 55, in inner
    response = get_response(request)
               ^^^^^^^^^^^^^^^^^^^^^
  File "C:\mysite\venv\Lib\site-packages\django\core\handlers\base.py", line 197, in _get_response
    response = wrapped_callback(request, *callback_args, **callback_kwargs)
               ^^^^^^^^^^^^^^^^^^^^^^^^^^^^^^^^^^^^^^^^^^^^^^^^^^^^^^^^^^^^
  File "C:\mysite\venv\Lib\site-packages\django\contrib\auth\decorators.py", line 59, in _view_wrapper
    return view_func(request, *args, **kwargs)
           ^^^^^^^^^^^^^^^^^^^^^^^^^^^^^^^^^^^
  File "C:\mysite\shop\store\views.py", line 155, in cart
    item['total_price'] = float(item['product']['price']) * item['quantity']
                                ~~~~~~~~~~~~~~~^^^^^^^^^
TypeError: 'int' object is not subscriptable
"GET /cart/ HTTP/1.1" 500 80719
Watching for file changes with StatReloader
"GET / HTTP/1.1" 200 1815
"GET /api/products/ HTTP/1.1" 200 360
"GET /products/ HTTP/1.1" 200 4832
Fetching cart from: http://localhost:8000/api/carts/
"GET /api/carts/ HTTP/1.1" 200 220
Cart API response: 200, [{"id":3,"user":5,"items":[{"id":4,"product":1,"quantity":2},{"id":5,"product":2,"quantity":1},{"id":6,"product":4,"quantity":1},{"id":7,"product":1,"quantity":1},{"id":8,"product":3,"quantity":1}],"total_price":6500.0}]
Internal Server Error: /cart/
Traceback (most recent call last):
  File "C:\mysite\venv\Lib\site-packages\django\core\handlers\exception.py", line 55, in inner
    response = get_response(request)
               ^^^^^^^^^^^^^^^^^^^^^
  File "C:\mysite\venv\Lib\site-packages\django\core\handlers\base.py", line 197, in _get_response
    response = wrapped_callback(request, *callback_args, **callback_kwargs)
               ^^^^^^^^^^^^^^^^^^^^^^^^^^^^^^^^^^^^^^^^^^^^^^^^^^^^^^^^^^^^
  File "C:\mysite\venv\Lib\site-packages\django\contrib\auth\decorators.py", line 59, in _view_wrapper
    return view_func(request, *args, **kwargs)
           ^^^^^^^^^^^^^^^^^^^^^^^^^^^^^^^^^^^
  File "C:\mysite\shop\store\views.py", line 182, in cart
    return render(request, 'store/cart.html', {'cart': cart})
           ^^^^^^^^^^^^^^^^^^^^^^^^^^^^^^^^^^^^^^^^^^^^^^^^^^
  File "C:\mysite\venv\Lib\site-packages\django\shortcuts.py", line 25, in render
    content = loader.render_to_string(template_name, context, request, using=using)
              ^^^^^^^^^^^^^^^^^^^^^^^^^^^^^^^^^^^^^^^^^^^^^^^^^^^^^^^^^^^^^^^^^^^^^
  File "C:\mysite\venv\Lib\site-packages\django\template\loader.py", line 61, in render_to_string
    template = get_template(template_name, using=using)
               ^^^^^^^^^^^^^^^^^^^^^^^^^^^^^^^^^^^^^^^^
  File "C:\mysite\venv\Lib\site-packages\django\template\loader.py", line 15, in get_template
    return engine.get_template(template_name)
           ^^^^^^^^^^^^^^^^^^^^^^^^^^^^^^^^^^
  File "C:\mysite\venv\Lib\site-packages\django\template\backends\django.py", line 79, in get_template
    return Template(self.engine.get_template(template_name), self)
                    ^^^^^^^^^^^^^^^^^^^^^^^^^^^^^^^^^^^^^^^
  File "C:\mysite\venv\Lib\site-packages\django\template\engine.py", line 177, in get_template
    template, origin = self.find_template(template_name)
                       ^^^^^^^^^^^^^^^^^^^^^^^^^^^^^^^^^
  File "C:\mysite\venv\Lib\site-packages\django\template\engine.py", line 159, in find_template
    template = loader.get_template(name, skip=skip)
               ^^^^^^^^^^^^^^^^^^^^^^^^^^^^^^^^^^^^
  File "C:\mysite\venv\Lib\site-packages\django\template\loaders\cached.py", line 57, in get_template
    template = super().get_template(template_name, skip)
               ^^^^^^^^^^^^^^^^^^^^^^^^^^^^^^^^^^^^^^^^^
  File "C:\mysite\venv\Lib\site-packages\django\template\loaders\base.py", line 28, in get_template
    return Template(
           ^^^^^^^^^
  File "C:\mysite\venv\Lib\site-packages\django\template\base.py", line 154, in __init__
    self.nodelist = self.compile_nodelist()
                    ^^^^^^^^^^^^^^^^^^^^^^^
  File "C:\mysite\venv\Lib\site-packages\django\template\base.py", line 196, in compile_nodelist
    nodelist = parser.parse()
               ^^^^^^^^^^^^^^
  File "C:\mysite\venv\Lib\site-packages\django\template\base.py", line 519, in parse
    self.extend_nodelist(nodelist, compiled_result, token)
  File "C:\mysite\venv\Lib\site-packages\django\template\base.py", line 540, in extend_nodelist
    raise self.error(
django.template.exceptions.TemplateSyntaxError: {% extends 'store/base.html' %} must be the first tag in 'store/cart.html'.
"GET /cart/ HTTP/1.1" 500 161013
Fetching cart from: http://localhost:8000/api/carts/
"GET /api/carts/ HTTP/1.1" 200 220
Cart API response: 200, [{"id":3,"user":5,"items":[{"id":4,"product":1,"quantity":2},{"id":5,"product":2,"quantity":1},{"id":6,"product":4,"quantity":1},{"id":7,"product":1,"quantity":1},{"id":8,"product":3,"quantity":1}],"total_price":6500.0}]
Internal Server Error: /cart/
Traceback (most recent call last):
  File "C:\mysite\venv\Lib\site-packages\django\core\handlers\exception.py", line 55, in inner
    response = get_response(request)
               ^^^^^^^^^^^^^^^^^^^^^
  File "C:\mysite\venv\Lib\site-packages\django\core\handlers\base.py", line 197, in _get_response
    response = wrapped_callback(request, *callback_args, **callback_kwargs)
               ^^^^^^^^^^^^^^^^^^^^^^^^^^^^^^^^^^^^^^^^^^^^^^^^^^^^^^^^^^^^
  File "C:\mysite\venv\Lib\site-packages\django\contrib\auth\decorators.py", line 59, in _view_wrapper
    return view_func(request, *args, **kwargs)
           ^^^^^^^^^^^^^^^^^^^^^^^^^^^^^^^^^^^
  File "C:\mysite\shop\store\views.py", line 182, in cart
    return render(request, 'store/cart.html', {'cart': cart})
           ^^^^^^^^^^^^^^^^^^^^^^^^^^^^^^^^^^^^^^^^^^^^^^^^^^
  File "C:\mysite\venv\Lib\site-packages\django\shortcuts.py", line 25, in render
    content = loader.render_to_string(template_name, context, request, using=using)
              ^^^^^^^^^^^^^^^^^^^^^^^^^^^^^^^^^^^^^^^^^^^^^^^^^^^^^^^^^^^^^^^^^^^^^
  File "C:\mysite\venv\Lib\site-packages\django\template\loader.py", line 61, in render_to_string
    template = get_template(template_name, using=using)
               ^^^^^^^^^^^^^^^^^^^^^^^^^^^^^^^^^^^^^^^^
  File "C:\mysite\venv\Lib\site-packages\django\template\loader.py", line 15, in get_template
    return engine.get_template(template_name)
           ^^^^^^^^^^^^^^^^^^^^^^^^^^^^^^^^^^
  File "C:\mysite\venv\Lib\site-packages\django\template\backends\django.py", line 79, in get_template
    return Template(self.engine.get_template(template_name), self)
                    ^^^^^^^^^^^^^^^^^^^^^^^^^^^^^^^^^^^^^^^
  File "C:\mysite\venv\Lib\site-packages\django\template\engine.py", line 177, in get_template
    template, origin = self.find_template(template_name)
                       ^^^^^^^^^^^^^^^^^^^^^^^^^^^^^^^^^
  File "C:\mysite\venv\Lib\site-packages\django\template\engine.py", line 159, in find_template
    template = loader.get_template(name, skip=skip)
               ^^^^^^^^^^^^^^^^^^^^^^^^^^^^^^^^^^^^
  File "C:\mysite\venv\Lib\site-packages\django\template\loaders\cached.py", line 57, in get_template
    template = super().get_template(template_name, skip)
               ^^^^^^^^^^^^^^^^^^^^^^^^^^^^^^^^^^^^^^^^^
  File "C:\mysite\venv\Lib\site-packages\django\template\loaders\base.py", line 28, in get_template
    return Template(
           ^^^^^^^^^
  File "C:\mysite\venv\Lib\site-packages\django\template\base.py", line 154, in __init__
    self.nodelist = self.compile_nodelist()
                    ^^^^^^^^^^^^^^^^^^^^^^^
  File "C:\mysite\venv\Lib\site-packages\django\template\base.py", line 196, in compile_nodelist
    nodelist = parser.parse()
               ^^^^^^^^^^^^^^
  File "C:\mysite\venv\Lib\site-packages\django\template\base.py", line 519, in parse
    self.extend_nodelist(nodelist, compiled_result, token)
  File "C:\mysite\venv\Lib\site-packages\django\template\base.py", line 540, in extend_nodelist
    raise self.error(
django.template.exceptions.TemplateSyntaxError: {% extends 'store/base.html' %} must be the first tag in 'store/cart.html'.
"GET /cart/ HTTP/1.1" 500 161150
Unauthorized: /api/carts/
"GET /api/carts/ HTTP/1.1" 401 5148
"GET /static/rest_framework/css/prettify.css HTTP/1.1" 200 817
"GET /static/rest_framework/css/default.css HTTP/1.1" 200 1152
"GET /static/rest_framework/css/bootstrap-tweaks.css HTTP/1.1" 200 3426
"GET /static/rest_framework/css/bootstrap.min.css HTTP/1.1" 200 121457
"GET /static/rest_framework/js/ajax-form.js HTTP/1.1" 200 3796
"GET /static/rest_framework/js/csrf.js HTTP/1.1" 200 1793
"GET /static/rest_framework/js/jquery-3.7.1.min.js HTTP/1.1" 200 87533
"GET /static/rest_framework/js/default.js HTTP/1.1" 200 1268
"GET /static/rest_framework/js/load-ajax-form.js HTTP/1.1" 200 59
"GET /static/rest_framework/js/prettify-min.js HTTP/1.1" 200 13632
"GET /static/rest_framework/js/bootstrap.min.js HTTP/1.1" 200 39680
"GET /static/rest_framework/img/grid.png HTTP/1.1" 200 1458
Fetching cart from: http://localhost:8000/api/carts/
"GET /api/carts/ HTTP/1.1" 200 220
Cart API response: 200, [{"id":3,"user":5,"items":[{"id":4,"product":1,"quantity":2},{"id":5,"product":2,"quantity":1},{"id":6,"product":4,"quantity":1},{"id":7,"product":1,"quantity":1},{"id":8,"product":3,"quantity":1}],"total_price":6500.0}]
Internal Server Error: /cart/
Traceback (most recent call last):
  File "C:\mysite\venv\Lib\site-packages\django\core\handlers\exception.py", line 55, in inner
    response = get_response(request)
               ^^^^^^^^^^^^^^^^^^^^^
  File "C:\mysite\venv\Lib\site-packages\django\core\handlers\base.py", line 197, in _get_response
    response = wrapped_callback(request, *callback_args, **callback_kwargs)
               ^^^^^^^^^^^^^^^^^^^^^^^^^^^^^^^^^^^^^^^^^^^^^^^^^^^^^^^^^^^^
  File "C:\mysite\venv\Lib\site-packages\django\contrib\auth\decorators.py", line 59, in _view_wrapper
    return view_func(request, *args, **kwargs)
           ^^^^^^^^^^^^^^^^^^^^^^^^^^^^^^^^^^^
  File "C:\mysite\shop\store\views.py", line 182, in cart
    return render(request, 'store/cart.html', {'cart': cart})
           ^^^^^^^^^^^^^^^^^^^^^^^^^^^^^^^^^^^^^^^^^^^^^^^^^^
  File "C:\mysite\venv\Lib\site-packages\django\shortcuts.py", line 25, in render
    content = loader.render_to_string(template_name, context, request, using=using)
              ^^^^^^^^^^^^^^^^^^^^^^^^^^^^^^^^^^^^^^^^^^^^^^^^^^^^^^^^^^^^^^^^^^^^^
  File "C:\mysite\venv\Lib\site-packages\django\template\loader.py", line 61, in render_to_string
    template = get_template(template_name, using=using)
               ^^^^^^^^^^^^^^^^^^^^^^^^^^^^^^^^^^^^^^^^
  File "C:\mysite\venv\Lib\site-packages\django\template\loader.py", line 15, in get_template
    return engine.get_template(template_name)
           ^^^^^^^^^^^^^^^^^^^^^^^^^^^^^^^^^^
  File "C:\mysite\venv\Lib\site-packages\django\template\backends\django.py", line 79, in get_template
    return Template(self.engine.get_template(template_name), self)
                    ^^^^^^^^^^^^^^^^^^^^^^^^^^^^^^^^^^^^^^^
  File "C:\mysite\venv\Lib\site-packages\django\template\engine.py", line 177, in get_template
    template, origin = self.find_template(template_name)
                       ^^^^^^^^^^^^^^^^^^^^^^^^^^^^^^^^^
  File "C:\mysite\venv\Lib\site-packages\django\template\engine.py", line 159, in find_template
    template = loader.get_template(name, skip=skip)
               ^^^^^^^^^^^^^^^^^^^^^^^^^^^^^^^^^^^^
  File "C:\mysite\venv\Lib\site-packages\django\template\loaders\cached.py", line 57, in get_template
    template = super().get_template(template_name, skip)
               ^^^^^^^^^^^^^^^^^^^^^^^^^^^^^^^^^^^^^^^^^
  File "C:\mysite\venv\Lib\site-packages\django\template\loaders\base.py", line 28, in get_template
    return Template(
           ^^^^^^^^^
  File "C:\mysite\venv\Lib\site-packages\django\template\base.py", line 154, in __init__
    self.nodelist = self.compile_nodelist()
                    ^^^^^^^^^^^^^^^^^^^^^^^
  File "C:\mysite\venv\Lib\site-packages\django\template\base.py", line 196, in compile_nodelist
    nodelist = parser.parse()
               ^^^^^^^^^^^^^^
  File "C:\mysite\venv\Lib\site-packages\django\template\base.py", line 519, in parse
    self.extend_nodelist(nodelist, compiled_result, token)
  File "C:\mysite\venv\Lib\site-packages\django\template\base.py", line 540, in extend_nodelist
    raise self.error(
django.template.exceptions.TemplateSyntaxError: {% extends 'store/base.html' %} must be the first tag in 'store/cart.html'.
"GET /cart/ HTTP/1.1" 500 161013
Watching for file changes with StatReloader
"GET / HTTP/1.1" 200 1815
"GET /api/carts/ HTTP/1.1" 200 220
"GET /cart/ HTTP/1.1" 200 4902
"DELETE /api/cart-items/8/ HTTP/1.1" 204 0
"DELETE /cart/ HTTP/1.1" 200 21
"GET /api/carts/ HTTP/1.1" 200 186
"GET /cart/ HTTP/1.1" 200 4499
"GET /api/products/ HTTP/1.1" 200 360
"GET /products/ HTTP/1.1" 200 4832
"GET /api/carts/ HTTP/1.1" 200 186
"POST /api/cart-items/ HTTP/1.1" 201 33
"POST /cart/ HTTP/1.1" 200 21
"GET /api/carts/ HTTP/1.1" 200 220
"GET /cart/ HTTP/1.1" 200 4902
"DELETE /api/cart-items/6/ HTTP/1.1" 204 0
"DELETE /cart/ HTTP/1.1" 200 21
"GET /api/carts/ HTTP/1.1" 200 186
"GET /cart/ HTTP/1.1" 200 4499
"GET /api/products/ HTTP/1.1" 200 361
"GET /products/ HTTP/1.1" 200 4833
"GET /api/carts/ HTTP/1.1" 200 186
"POST /api/cart-items/ HTTP/1.1" 201 34
"POST /cart/ HTTP/1.1" 200 21
"GET /api/carts/ HTTP/1.1" 200 221
"GET /cart/ HTTP/1.1" 200 4903
"GET /profile/ HTTP/1.1" 200 0
Watching for file changes with StatReloader
"GET / HTTP/1.1" 200 1815
"POST /api/auth/logout/ HTTP/1.1" 205 31
Internal Server Error: /logout/
Traceback (most recent call last):
  File "C:\mysite\venv\Lib\site-packages\django\core\handlers\exception.py", line 55, in inner
    response = get_response(request)
               ^^^^^^^^^^^^^^^^^^^^^
  File "C:\mysite\venv\Lib\site-packages\django\core\handlers\base.py", line 204, in _get_response
    self.check_response(response, callback)
  File "C:\mysite\venv\Lib\site-packages\django\core\handlers\base.py", line 332, in check_response
    raise ValueError(
ValueError: The view store.views.logout_view didn't return an HttpResponse object. It returned None instead.
"GET /logout/ HTTP/1.1" 500 74207
Watching for file changes with StatReloader
"GET /api/carts/ HTTP/1.1" 200 221
"POST /api/auth/login/ HTTP/1.1" 200 483
"POST /api/auth/register/ HTTP/1.1" 201 102
"POST /api/auth/login/ HTTP/1.1" 200 483
"POST /api/cart-items/ HTTP/1.1" 201 34
"GET / HTTP/1.1" 200 1815
Bad Request: /api/auth/logout/
"POST /api/auth/logout/ HTTP/1.1" 400 32
Internal Server Error: /logout/
Traceback (most recent call last):
  File "C:\mysite\venv\Lib\site-packages\django\core\handlers\exception.py", line 55, in inner
    response = get_response(request)
               ^^^^^^^^^^^^^^^^^^^^^
  File "C:\mysite\venv\Lib\site-packages\django\core\handlers\base.py", line 204, in _get_response
    self.check_response(response, callback)
  File "C:\mysite\venv\Lib\site-packages\django\core\handlers\base.py", line 332, in check_response
    raise ValueError(
ValueError: The view store.views.logout_view didn't return an HttpResponse object. It returned None instead.
"GET /logout/ HTTP/1.1" 500 74207
"GET /api/carts/ HTTP/1.1" 200 256
"GET /cart/ HTTP/1.1" 200 5307
"DELETE /api/cart-items/4/ HTTP/1.1" 204 0
"DELETE /cart/ HTTP/1.1" 200 21
"GET /api/carts/ HTTP/1.1" 200 222
"GET /cart/ HTTP/1.1" 200 4904
"GET /api/products/ HTTP/1.1" 200 361
"GET /products/ HTTP/1.1" 200 4833
"GET /api/products/ HTTP/1.1" 200 361
"GET /products/ HTTP/1.1" 200 4833
Watching for file changes with StatReloader
Forbidden (CSRF cookie not set.): /logout/
"POST /logout/ HTTP/1.1" 403 2855
Watching for file changes with StatReloader
Forbidden (CSRF cookie not set.): /logout/
"POST /logout/ HTTP/1.1" 403 2855
"POST /api/auth/login/ HTTP/1.1" 200 483
Forbidden (CSRF cookie not set.): /logout/
"POST /logout/ HTTP/1.1" 403 2855
C:\mysite\shop\store\views.py changed, reloading.
Watching for file changes with StatReloader
C:\mysite\shop\store\urls.py changed, reloading.
Watching for file changes with StatReloader
Forbidden (CSRF cookie not set.): /logout/
"POST /logout/ HTTP/1.1" 403 2855
C:\mysite\shop\shop\settings.py changed, reloading.
Watching for file changes with StatReloader
C:\mysite\shop\shop\settings.py changed, reloading.
Watching for file changes with StatReloader
C:\mysite\shop\shop\settings.py changed, reloading.
Watching for file changes with StatReloader
Watching for file changes with StatReloader
Forbidden (CSRF cookie not set.): /logout/
"POST /logout/ HTTP/1.1" 403 2855
Watching for file changes with StatReloader
Forbidden (CSRF cookie not set.): /logout/
"POST /logout/ HTTP/1.1" 403 2855
C:\mysite\shop\store\views.py changed, reloading.
Watching for file changes with StatReloader
Watching for file changes with StatReloader
Forbidden (CSRF cookie not set.): /logout/
"POST /logout/ HTTP/1.1" 403 2855
Watching for file changes with StatReloader
"POST /logout/ HTTP/1.1" 302 0
"GET / HTTP/1.1" 200 2388
"GET / HTTP/1.1" 200 2403
"GET /api/products/ HTTP/1.1" 200 361
"GET /products/ HTTP/1.1" 200 5421
Bad Request: /api/auth/logout/
"POST /api/auth/logout/ HTTP/1.1" 400 32
"POST /logout/ HTTP/1.1" 302 0
"GET / HTTP/1.1" 200 2388
"GET /login/ HTTP/1.1" 200 697
"POST /api/auth/login/ HTTP/1.1" 200 483
"POST /login/ HTTP/1.1" 302 0
"GET / HTTP/1.1" 200 2403
"GET /api/products/ HTTP/1.1" 200 361
"GET /products/ HTTP/1.1" 200 5421
"GET /api/carts/ HTTP/1.1" 200 222
"GET /cart/ HTTP/1.1" 200 5492
Watching for file changes with StatReloader
"POST /api/auth/logout/ HTTP/1.1" 205 31
"POST /logout/ HTTP/1.1" 302 0
"GET / HTTP/1.1" 200 2388
"GET /login/ HTTP/1.1" 200 697
"POST /api/auth/login/ HTTP/1.1" 200 483
"POST /login/ HTTP/1.1" 302 0
"GET / HTTP/1.1" 200 2403
"GET /api/carts/ HTTP/1.1" 200 84
"GET /cart/ HTTP/1.1" 200 3878
"GET /api/products/ HTTP/1.1" 200 361
"GET /products/ HTTP/1.1" 200 5421
"POST /api/auth/logout/ HTTP/1.1" 205 31
"POST /logout/ HTTP/1.1" 302 0
"GET / HTTP/1.1" 200 2388
"GET /login/ HTTP/1.1" 200 697
"GET / HTTP/1.1" 200 2049
"GET /register/ HTTP/1.1" 200 0
Watching for file changes with StatReloader
"GET /register/ HTTP/1.1" 200 6105
"POST /api/auth/register/ HTTP/1.1" 201 96
"POST /register/ HTTP/1.1" 200 6720
"GET /api/products/ HTTP/1.1" 200 361
"GET /products/ HTTP/1.1" 200 5421
"GET /profile/ HTTP/1.1" 200 0
Watching for file changes with StatReloader
Internal Server Error: /profile/
Traceback (most recent call last):
  File "C:\mysite\venv\Lib\site-packages\django\core\handlers\exception.py", line 55, in inner
    response = get_response(request)
               ^^^^^^^^^^^^^^^^^^^^^
  File "C:\mysite\venv\Lib\site-packages\django\core\handlers\base.py", line 197, in _get_response
    response = wrapped_callback(request, *callback_args, **callback_kwargs)
               ^^^^^^^^^^^^^^^^^^^^^^^^^^^^^^^^^^^^^^^^^^^^^^^^^^^^^^^^^^^^
  File "C:\mysite\venv\Lib\site-packages\django\contrib\auth\decorators.py", line 59, in _view_wrapper
    return view_func(request, *args, **kwargs)
           ^^^^^^^^^^^^^^^^^^^^^^^^^^^^^^^^^^^
  File "C:\mysite\shop\store\views.py", line 276, in profile
    return render(request, 'store/profile.html', {'user': request.user})
           ^^^^^^^^^^^^^^^^^^^^^^^^^^^^^^^^^^^^^^^^^^^^^^^^^^^^^^^^^^^^^
  File "C:\mysite\venv\Lib\site-packages\django\shortcuts.py", line 25, in render
    content = loader.render_to_string(template_name, context, request, using=using)
              ^^^^^^^^^^^^^^^^^^^^^^^^^^^^^^^^^^^^^^^^^^^^^^^^^^^^^^^^^^^^^^^^^^^^^
  File "C:\mysite\venv\Lib\site-packages\django\template\loader.py", line 62, in render_to_string
    return template.render(context, request)
           ^^^^^^^^^^^^^^^^^^^^^^^^^^^^^^^^^
  File "C:\mysite\venv\Lib\site-packages\django\template\backends\django.py", line 107, in render
    return self.template.render(context)
           ^^^^^^^^^^^^^^^^^^^^^^^^^^^^^
  File "C:\mysite\venv\Lib\site-packages\django\template\base.py", line 171, in render
    return self._render(context)
           ^^^^^^^^^^^^^^^^^^^^^
  File "C:\mysite\venv\Lib\site-packages\django\template\base.py", line 163, in _render
    return self.nodelist.render(context)
           ^^^^^^^^^^^^^^^^^^^^^^^^^^^^^
  File "C:\mysite\venv\Lib\site-packages\django\template\base.py", line 1016, in render
    return SafeString("".join([node.render_annotated(context) for node in self]))
                               ^^^^^^^^^^^^^^^^^^^^^^^^^^^^^^
  File "C:\mysite\venv\Lib\site-packages\django\template\base.py", line 977, in render_annotated
    return self.render(context)
           ^^^^^^^^^^^^^^^^^^^^
  File "C:\mysite\venv\Lib\site-packages\django\template\loader_tags.py", line 159, in render
    return compiled_parent._render(context)
           ^^^^^^^^^^^^^^^^^^^^^^^^^^^^^^^^
  File "C:\mysite\venv\Lib\site-packages\django\template\base.py", line 163, in _render
    return self.nodelist.render(context)
           ^^^^^^^^^^^^^^^^^^^^^^^^^^^^^
  File "C:\mysite\venv\Lib\site-packages\django\template\base.py", line 1016, in render
    return SafeString("".join([node.render_annotated(context) for node in self]))
                               ^^^^^^^^^^^^^^^^^^^^^^^^^^^^^^
  File "C:\mysite\venv\Lib\site-packages\django\template\base.py", line 977, in render_annotated
    return self.render(context)
           ^^^^^^^^^^^^^^^^^^^^
  File "C:\mysite\venv\Lib\site-packages\django\template\loader_tags.py", line 65, in render
    result = block.nodelist.render(context)
             ^^^^^^^^^^^^^^^^^^^^^^^^^^^^^^
  File "C:\mysite\venv\Lib\site-packages\django\template\base.py", line 1016, in render
    return SafeString("".join([node.render_annotated(context) for node in self]))
                               ^^^^^^^^^^^^^^^^^^^^^^^^^^^^^^
  File "C:\mysite\venv\Lib\site-packages\django\template\base.py", line 977, in render_annotated
    return self.render(context)
           ^^^^^^^^^^^^^^^^^^^^
  File "C:\mysite\venv\Lib\site-packages\django\template\defaulttags.py", line 480, in render
    url = reverse(view_name, args=args, kwargs=kwargs, current_app=current_app)
          ^^^^^^^^^^^^^^^^^^^^^^^^^^^^^^^^^^^^^^^^^^^^^^^^^^^^^^^^^^^^^^^^^^^^^
  File "C:\mysite\venv\Lib\site-packages\django\urls\base.py", line 98, in reverse
    resolved_url = resolver._reverse_with_prefix(view, prefix, *args, **kwargs)
                   ^^^^^^^^^^^^^^^^^^^^^^^^^^^^^^^^^^^^^^^^^^^^^^^^^^^^^^^^^^^^
  File "C:\mysite\venv\Lib\site-packages\django\urls\resolvers.py", line 831, in _reverse_with_prefix
    raise NoReverseMatch(msg)
django.urls.exceptions.NoReverseMatch: Reverse for 'change-password' not found. 'change-password' is not a valid view function or pattern name.
"GET /profile/ HTTP/1.1" 500 163896
C:\mysite\shop\store\urls.py changed, reloading.
Watching for file changes with StatReloader
Watching for file changes with StatReloader
"GET /profile/ HTTP/1.1" 200 8105
"GET /static/store/images/profile-avatar.jpg HTTP/1.1" 404 2020
Unauthorized: /change-password/
"GET /change-password/ HTTP/1.1" 401 3785
"GET /static/rest_framework/css/bootstrap-tweaks.css HTTP/1.1" 200 3426
"GET /static/rest_framework/css/bootstrap.min.css HTTP/1.1" 200 121457
"GET /static/rest_framework/css/prettify.css HTTP/1.1" 200 817
"GET /static/rest_framework/js/csrf.js HTTP/1.1" 200 1793
"GET /static/rest_framework/css/default.css HTTP/1.1" 200 1152
"GET /static/rest_framework/js/ajax-form.js HTTP/1.1" 200 3796
"GET /static/rest_framework/js/jquery-3.7.1.min.js HTTP/1.1" 200 87533
"GET /static/rest_framework/js/default.js HTTP/1.1" 200 1268
"GET /static/rest_framework/js/prettify-min.js HTTP/1.1" 200 13632
"GET /static/rest_framework/js/load-ajax-form.js HTTP/1.1" 200 59
"GET /static/rest_framework/js/bootstrap.min.js HTTP/1.1" 200 39680
"GET /static/rest_framework/img/grid.png HTTP/1.1" 200 1458
"GET /profile/ HTTP/1.1" 200 7906
"GET /static/store/images/profile-avatar.jpg HTTP/1.1" 404 2020
"GET /api/products/ HTTP/1.1" 200 361
"GET /products/ HTTP/1.1" 200 5421
"GET /cart/ HTTP/1.1" 302 0
"GET /login/ HTTP/1.1" 200 697
"POST /api/auth/login/ HTTP/1.1" 200 483
"POST /login/ HTTP/1.1" 302 0
"GET / HTTP/1.1" 200 2403
"GET /api/products/ HTTP/1.1" 200 361
"GET /products/ HTTP/1.1" 200 5421
"GET /api/carts/ HTTP/1.1" 200 2
"GET /cart/ HTTP/1.1" 200 3016
"GET /api/products/ HTTP/1.1" 200 361
"GET /products/ HTTP/1.1" 200 5421
"GET /api/carts/ HTTP/1.1" 200 2
"POST /api/cart-items/ HTTP/1.1" 201 34
"POST /cart/ HTTP/1.1" 200 21
"GET /api/carts/ HTTP/1.1" 200 85
"GET /cart/ HTTP/1.1" 200 3879
"DELETE /api/cart-items/12/ HTTP/1.1" 204 0
"DELETE /cart/ HTTP/1.1" 200 21
"GET /api/carts/ HTTP/1.1" 200 46
"GET /cart/ HTTP/1.1" 200 3016
"GET /profile/ HTTP/1.1" 200 7906
"GET /static/store/images/profile-avatar.jpg HTTP/1.1" 404 2020
"POST /api/auth/logout/ HTTP/1.1" 205 31
"POST /logout/ HTTP/1.1" 302 0
"GET / HTTP/1.1" 200 2388
"GET /login/ HTTP/1.1" 200 697
"POST /api/auth/login/ HTTP/1.1" 200 483
"POST /login/ HTTP/1.1" 302 0
"GET / HTTP/1.1" 200 2403
"GET /profile/ HTTP/1.1" 200 7906
"GET /static/store/images/profile-avatar.jpg HTTP/1.1" 404 2020
"GET /api/carts/ HTTP/1.1" 200 46
"GET /cart/ HTTP/1.1" 200 3016
"GET /api/products/ HTTP/1.1" 200 361
"GET /products/ HTTP/1.1" 200 5421
"GET /api/carts/ HTTP/1.1" 200 46
"POST /api/cart-items/ HTTP/1.1" 201 34
"POST /cart/ HTTP/1.1" 200 21
"GET /api/carts/ HTTP/1.1" 200 85
"POST /api/cart-items/ HTTP/1.1" 201 34
"POST /cart/ HTTP/1.1" 200 21
"GET /api/carts/ HTTP/1.1" 200 120
"GET /cart/ HTTP/1.1" 200 4283
"GET /profile/ HTTP/1.1" 200 7906
"GET /static/store/images/profile-avatar.jpg HTTP/1.1" 404 2020
"GET /api/products/ HTTP/1.1" 200 361
"GET /products/ HTTP/1.1" 200 5421
"POST /api/auth/logout/ HTTP/1.1" 205 31
"POST /logout/ HTTP/1.1" 302 0
"GET / HTTP/1.1" 200 2388
"GET /register/ HTTP/1.1" 200 6105
Bad Request: /api/auth/register/
"POST /api/auth/register/ HTTP/1.1" 400 42
Internal Server Error: /register/
Traceback (most recent call last):
  File "C:\mysite\venv\Lib\site-packages\django\core\handlers\exception.py", line 55, in inner
    response = get_response(request)
               ^^^^^^^^^^^^^^^^^^^^^
  File "C:\mysite\venv\Lib\site-packages\django\core\handlers\base.py", line 204, in _get_response
    self.check_response(response, callback)
  File "C:\mysite\venv\Lib\site-packages\django\core\handlers\base.py", line 332, in check_response
    raise ValueError(
ValueError: The view store.views.view didn't return an HttpResponse object. It returned None instead.
"POST /register/ HTTP/1.1" 500 75656
"POST /api/auth/register/ HTTP/1.1" 201 107
"POST /register/ HTTP/1.1" 200 6720
"GET /cart/ HTTP/1.1" 302 0
"GET /login/ HTTP/1.1" 200 697
"POST /api/auth/login/ HTTP/1.1" 200 483
"POST /login/ HTTP/1.1" 302 0
"GET / HTTP/1.1" 200 2403
"GET /api/products/ HTTP/1.1" 200 361
"GET /products/ HTTP/1.1" 200 5421
"GET /api/carts/ HTTP/1.1" 200 2
"GET /cart/ HTTP/1.1" 200 3016
"GET /api/products/ HTTP/1.1" 200 361
"GET /products/ HTTP/1.1" 200 5421
Watching for file changes with StatReloader
"GET / HTTP/1.1" 200 2049
"GET /api/products/ HTTP/1.1" 200 360
"GET /products/ HTTP/1.1" 200 5046
"GET /login/ HTTP/1.1" 200 697
"POST /api/auth/login/ HTTP/1.1" 200 483
"POST /login/ HTTP/1.1" 302 0
"GET / HTTP/1.1" 200 2403
"GET /api/products/ HTTP/1.1" 200 360
"GET /products/ HTTP/1.1" 200 5420
"GET /api/carts/ HTTP/1.1" 200 2
"GET /cart/ HTTP/1.1" 200 3016
"GET /api/products/ HTTP/1.1" 200 360
"GET /products/ HTTP/1.1" 200 5420
"GET /api/carts/ HTTP/1.1" 200 2
"POST /api/cart-items/ HTTP/1.1" 201 34
"POST /cart/ HTTP/1.1" 200 21
"GET /api/carts/ HTTP/1.1" 200 85
"POST /api/cart-items/ HTTP/1.1" 201 34
"POST /cart/ HTTP/1.1" 200 21
"GET /api/carts/ HTTP/1.1" 200 120
"GET /cart/ HTTP/1.1" 200 4283
"GET /profile/ HTTP/1.1" 200 7927
"GET /static/store/images/profile-avatar.jpg HTTP/1.1" 404 1953
"GET /api/products/ HTTP/1.1" 200 360
"GET /products/ HTTP/1.1" 200 5420
Watching for file changes with StatReloader
"GET / HTTP/1.1" 200 2403
"GET /api/products/ HTTP/1.1" 200 360
"GET /products/ HTTP/1.1" 200 5420
"GET /api/carts/ HTTP/1.1" 200 120
"POST /api/cart-items/ HTTP/1.1" 201 34
"POST /cart/ HTTP/1.1" 200 21
"GET /api/carts/ HTTP/1.1" 200 155
"GET /cart/ HTTP/1.1" 200 4687
"DELETE /api/cart-items/26/ HTTP/1.1" 204 0
"DELETE /cart/ HTTP/1.1" 200 21
"GET /api/carts/ HTTP/1.1" 200 120
"GET /cart/ HTTP/1.1" 200 4283
"DELETE /api/cart-items/27/ HTTP/1.1" 204 0
"DELETE /cart/ HTTP/1.1" 200 21
"GET /api/carts/ HTTP/1.1" 200 85
"GET /cart/ HTTP/1.1" 200 3879
"DELETE /api/cart-items/28/ HTTP/1.1" 204 0
"DELETE /cart/ HTTP/1.1" 200 21
"GET /api/carts/ HTTP/1.1" 200 46
"GET /cart/ HTTP/1.1" 200 3016
"GET /api/products/ HTTP/1.1" 200 360
"GET /products/ HTTP/1.1" 200 5420
"GET /api/carts/ HTTP/1.1" 200 46
"POST /api/cart-items/ HTTP/1.1" 201 34
"POST /cart/ HTTP/1.1" 200 21
"GET /api/carts/ HTTP/1.1" 200 85
"GET /cart/ HTTP/1.1" 200 3879
"GET /profile/ HTTP/1.1" 200 7927
"GET /static/store/images/profile-avatar.jpg HTTP/1.1" 404 1953
Watching for file changes with StatReloader
"GET / HTTP/1.1" 200 2403
"GET /api/products/ HTTP/1.1" 200 360
"GET /products/ HTTP/1.1" 200 5420
"POST /api/auth/logout/ HTTP/1.1" 205 31
"POST /logout/ HTTP/1.1" 302 0
"GET / HTTP/1.1" 200 2388
"GET /login/ HTTP/1.1" 200 697
"POST /api/auth/login/ HTTP/1.1" 200 483
"POST /login/ HTTP/1.1" 302 0
"GET / HTTP/1.1" 200 2403
"GET /api/products/ HTTP/1.1" 200 360
"GET /products/ HTTP/1.1" 200 5420
"GET /api/carts/ HTTP/1.1" 200 260
"GET /cart/ HTTP/1.1" 200 5899
"GET /api/products/ HTTP/1.1" 200 360
"GET /products/ HTTP/1.1" 200 5420
"GET /api/carts/ HTTP/1.1" 200 260
Bad Request: /api/cart-items/
"POST /api/cart-items/ HTTP/1.1" 400 68
"POST /cart/ HTTP/1.1" 200 19
"GET /api/carts/ HTTP/1.1" 200 296
"GET /cart/ HTTP/1.1" 200 6304
"GET /api/products/ HTTP/1.1" 200 360
"GET /products/ HTTP/1.1" 200 5420
"GET /api/carts/ HTTP/1.1" 200 296
Bad Request: /api/cart-items/
"POST /api/cart-items/ HTTP/1.1" 400 68
"POST /cart/ HTTP/1.1" 200 19
"GET /api/carts/ HTTP/1.1" 200 331
"GET /cart/ HTTP/1.1" 200 6708
"POST /api/auth/login/ HTTP/1.1" 200 483
Watching for file changes with StatReloader
Watching for file changes with StatReloader
Watching for file changes with StatReloader
Watching for file changes with StatReloader
"GET / HTTP/1.1" 200 2049
Not Found: /favicon.ico
"GET /favicon.ico HTTP/1.1" 404 5151
"GET /api/products/ HTTP/1.1" 200 360
"GET /products/ HTTP/1.1" 200 5046
"GET /login/ HTTP/1.1" 200 697
"GET /register/ HTTP/1.1" 200 6105
"POST /api/auth/register/ HTTP/1.1" 201 96
"POST /register/ HTTP/1.1" 200 6720
"GET /cart/ HTTP/1.1" 302 0
"GET /login/ HTTP/1.1" 200 697
"POST /api/auth/login/ HTTP/1.1" 200 483
"POST /login/ HTTP/1.1" 302 0
"GET / HTTP/1.1" 200 2403
"GET /profile/ HTTP/1.1" 200 7905
"GET /static/store/images/profile-avatar.jpg HTTP/1.1" 404 1953
"GET /api/products/ HTTP/1.1" 200 360
"GET /products/ HTTP/1.1" 200 5420
"GET /api/carts/ HTTP/1.1" 200 2
"POST /api/cart-items/ HTTP/1.1" 201 34
"POST /cart/ HTTP/1.1" 200 21
"GET /api/carts/ HTTP/1.1" 200 84
"GET /api/carts/ HTTP/1.1" 200 84
"POST /api/cart-items/ HTTP/1.1" 201 34
"POST /cart/ HTTP/1.1" 200 21
"POST /api/cart-items/ HTTP/1.1" 201 34
"POST /cart/ HTTP/1.1" 200 21
"GET /api/carts/ HTTP/1.1" 200 155
Bad Request: /api/cart-items/
"POST /api/cart-items/ HTTP/1.1" 400 68
"POST /cart/ HTTP/1.1" 200 19
"GET /api/carts/ HTTP/1.1" 200 190
"GET /cart/ HTTP/1.1" 200 5091
"DELETE /api/cart-items/32/ HTTP/1.1" 204 0
"DELETE /cart/ HTTP/1.1" 200 21
"GET /api/carts/ HTTP/1.1" 200 155
"GET /cart/ HTTP/1.1" 200 4687
"DELETE /api/cart-items/33/ HTTP/1.1" 204 0
"DELETE /cart/ HTTP/1.1" 200 21
"DELETE /api/cart-items/35/ HTTP/1.1" 204 0
"DELETE /cart/ HTTP/1.1" 200 21
"GET /api/carts/ HTTP/1.1" 200 84
"GET /cart/ HTTP/1.1" 200 3878
"DELETE /api/cart-items/34/ HTTP/1.1" 204 0
"DELETE /cart/ HTTP/1.1" 200 21
"GET /api/carts/ HTTP/1.1" 200 46
"GET /cart/ HTTP/1.1" 200 3016
"GET /profile/ HTTP/1.1" 200 7905
"GET /static/store/images/profile-avatar.jpg HTTP/1.1" 404 1953
"GET /api/products/ HTTP/1.1" 200 360
"GET /products/ HTTP/1.1" 200 5420
"GET /api/carts/ HTTP/1.1" 200 46
"POST /api/cart-items/ HTTP/1.1" 201 34
"POST /cart/ HTTP/1.1" 200 21
"GET /api/carts/ HTTP/1.1" 200 85
"POST /api/cart-items/ HTTP/1.1" 201 34
"POST /cart/ HTTP/1.1" 200 21
"GET /api/carts/ HTTP/1.1" 200 120
"GET /cart/ HTTP/1.1" 200 4283
"GET / HTTP/1.1" 200 2403
"GET /api/products/ HTTP/1.1" 200 360
"GET /products/ HTTP/1.1" 200 5420
"GET /api/products/ HTTP/1.1" 200 360
"GET /products/ HTTP/1.1" 200 5420
"GET /api/carts/ HTTP/1.1" 200 120
Bad Request: /api/cart-items/
"POST /api/cart-items/ HTTP/1.1" 400 68
"POST /cart/ HTTP/1.1" 200 19
"GET /api/carts/ HTTP/1.1" 200 155
"POST /api/cart-items/ HTTP/1.1" 201 34
"POST /cart/ HTTP/1.1" 200 21
"GET /api/carts/ HTTP/1.1" 200 190
"GET /cart/ HTTP/1.1" 200 5091
"GET /api/products/ HTTP/1.1" 200 360
"GET /products/ HTTP/1.1" 200 5420
"GET /api/carts/ HTTP/1.1" 200 190
"POST /api/cart-items/ HTTP/1.1" 201 34
"POST /cart/ HTTP/1.1" 200 21
"GET /api/carts/ HTTP/1.1" 200 225
Bad Request: /api/cart-items/
"POST /api/cart-items/ HTTP/1.1" 400 68
"POST /cart/ HTTP/1.1" 200 19
"GET /api/carts/ HTTP/1.1" 200 260
"GET /cart/ HTTP/1.1" 200 5899
"GET / HTTP/1.1" 200 2403
"GET /api/products/ HTTP/1.1" 200 360
"GET /products/ HTTP/1.1" 200 5420
Watching for file changes with StatReloader
"GET / HTTP/1.1" 200 2049
Not Found: /favicon.ico
"GET /favicon.ico HTTP/1.1" 404 5151
"GET /api/products/ HTTP/1.1" 200 360
"GET /products/ HTTP/1.1" 200 5046
"GET /login/ HTTP/1.1" 200 697
"POST /api/auth/login/ HTTP/1.1" 200 483
"POST /login/ HTTP/1.1" 302 0
"GET / HTTP/1.1" 200 2403
"GET /api/carts/ HTTP/1.1" 200 85
"GET /cart/ HTTP/1.1" 200 3879
"GET /api/products/ HTTP/1.1" 200 360
"GET /products/ HTTP/1.1" 200 5420
"GET /api/carts/ HTTP/1.1" 200 85
"POST /api/cart-items/ HTTP/1.1" 201 34
"POST /cart/ HTTP/1.1" 200 21
"GET /api/carts/ HTTP/1.1" 200 120
"GET /cart/ HTTP/1.1" 200 4283
"GET /api/carts/ HTTP/1.1" 200 120
"GET /cart/ HTTP/1.1" 200 4283
"GET /api/products/ HTTP/1.1" 200 360
"GET /products/ HTTP/1.1" 200 5420
"GET /api/carts/ HTTP/1.1" 200 120
"GET /cart/ HTTP/1.1" 200 4283
"GET /api/products/ HTTP/1.1" 200 360
"GET /products/ HTTP/1.1" 200 5420
Not Found: /favicon.ico
"GET /favicon.ico HTTP/1.1" 404 5151
"GET /api/products/ HTTP/1.1" 200 360
"GET /products/ HTTP/1.1" 200 5420
"GET /api/products/ HTTP/1.1" 200 360
"GET /products/ HTTP/1.1" 200 5420
"GET /api/products/ HTTP/1.1" 200 360
"GET /products/ HTTP/1.1" 200 5420
"GET /api/carts/ HTTP/1.1" 200 260
"GET /cart/ HTTP/1.1" 200 5899
"GET /api/carts/ HTTP/1.1" 200 260
"GET /cart/ HTTP/1.1" 200 5899
Internal Server Error: /cart/
Traceback (most recent call last):
  File "C:\mysite\venv\Lib\site-packages\django\contrib\sessions\backends\base.py", line 187, in _get_session
    return self._session_cache
           ^^^^^^^^^^^^^^^^^^^
AttributeError: 'SessionStore' object has no attribute '_session_cache'

During handling of the above exception, another exception occurred:

Traceback (most recent call last):
  File "C:\mysite\venv\Lib\site-packages\django\db\backends\base\base.py", line 289, in ensure_connection
    self.connect()
  File "C:\mysite\venv\Lib\site-packages\django\utils\asyncio.py", line 26, in inner
    return func(*args, **kwargs)
           ^^^^^^^^^^^^^^^^^^^^^
  File "C:\mysite\venv\Lib\site-packages\django\db\backends\base\base.py", line 270, in connect
    self.connection = self.get_new_connection(conn_params)
                      ^^^^^^^^^^^^^^^^^^^^^^^^^^^^^^^^^^^^
  File "C:\mysite\venv\Lib\site-packages\django\utils\asyncio.py", line 26, in inner
    return func(*args, **kwargs)
           ^^^^^^^^^^^^^^^^^^^^^
  File "C:\mysite\venv\Lib\site-packages\django\db\backends\postgresql\base.py", line 275, in get_new_connection
    connection = self.Database.connect(**conn_params)
                 ^^^^^^^^^^^^^^^^^^^^^^^^^^^^^^^^^^^^
  File "C:\mysite\venv\Lib\site-packages\psycopg2\__init__.py", line 122, in connect
    conn = _connect(dsn, connection_factory=connection_factory, **kwasync)
           ^^^^^^^^^^^^^^^^^^^^^^^^^^^^^^^^^^^^^^^^^^^^^^^^^^^^^^^^^^^^^^^
psycopg2.OperationalError: connection to server at "localhost" (::1), port 5433 failed: Connection refused (0x0000274D/10061)
	Is the server running on that host and accepting TCP/IP connections?
connection to server at "localhost" (127.0.0.1), port 5433 failed: Connection refused (0x0000274D/10061)
	Is the server running on that host and accepting TCP/IP connections?


The above exception was the direct cause of the following exception:

Traceback (most recent call last):
  File "C:\mysite\venv\Lib\site-packages\django\core\handlers\exception.py", line 55, in inner
    response = get_response(request)
               ^^^^^^^^^^^^^^^^^^^^^
  File "C:\mysite\venv\Lib\site-packages\django\core\handlers\base.py", line 197, in _get_response
    response = wrapped_callback(request, *callback_args, **callback_kwargs)
               ^^^^^^^^^^^^^^^^^^^^^^^^^^^^^^^^^^^^^^^^^^^^^^^^^^^^^^^^^^^^
  File "C:\mysite\venv\Lib\site-packages\django\contrib\auth\decorators.py", line 22, in _wrapper_view
    if test_func(request.user):
       ^^^^^^^^^^^^^^^^^^^^^^^
  File "C:\mysite\venv\Lib\site-packages\django\contrib\auth\decorators.py", line 51, in <lambda>
    lambda u: u.is_authenticated,
              ^^^^^^^^^^^^^^^^^^
  File "C:\mysite\venv\Lib\site-packages\django\utils\functional.py", line 266, in inner
    self._setup()
  File "C:\mysite\venv\Lib\site-packages\django\utils\functional.py", line 419, in _setup
    self._wrapped = self._setupfunc()
                    ^^^^^^^^^^^^^^^^^
  File "C:\mysite\venv\Lib\site-packages\django\contrib\auth\middleware.py", line 25, in <lambda>
    request.user = SimpleLazyObject(lambda: get_user(request))
                                            ^^^^^^^^^^^^^^^^^
  File "C:\mysite\venv\Lib\site-packages\django\contrib\auth\middleware.py", line 11, in get_user
    request._cached_user = auth.get_user(request)
                           ^^^^^^^^^^^^^^^^^^^^^^
  File "C:\mysite\venv\Lib\site-packages\django\contrib\auth\__init__.py", line 191, in get_user
    user_id = _get_user_session_key(request)
              ^^^^^^^^^^^^^^^^^^^^^^^^^^^^^^
  File "C:\mysite\venv\Lib\site-packages\django\contrib\auth\__init__.py", line 60, in _get_user_session_key
    return get_user_model()._meta.pk.to_python(request.session[SESSION_KEY])
                                               ~~~~~~~~~~~~~~~^^^^^^^^^^^^^
  File "C:\mysite\venv\Lib\site-packages\django\contrib\sessions\backends\base.py", line 53, in __getitem__
    return self._session[key]
           ^^^^^^^^^^^^^
  File "C:\mysite\venv\Lib\site-packages\django\contrib\sessions\backends\base.py", line 192, in _get_session
    self._session_cache = self.load()
                          ^^^^^^^^^^^
  File "C:\mysite\venv\Lib\site-packages\django\contrib\sessions\backends\db.py", line 42, in load
    s = self._get_session_from_db()
        ^^^^^^^^^^^^^^^^^^^^^^^^^^^
  File "C:\mysite\venv\Lib\site-packages\django\contrib\sessions\backends\db.py", line 32, in _get_session_from_db
    return self.model.objects.get(
           ^^^^^^^^^^^^^^^^^^^^^^^
  File "C:\mysite\venv\Lib\site-packages\django\db\models\manager.py", line 87, in manager_method
    return getattr(self.get_queryset(), name)(*args, **kwargs)
           ^^^^^^^^^^^^^^^^^^^^^^^^^^^^^^^^^^^^^^^^^^^^^^^^^^^
  File "C:\mysite\venv\Lib\site-packages\django\db\models\query.py", line 633, in get
    num = len(clone)
          ^^^^^^^^^^
  File "C:\mysite\venv\Lib\site-packages\django\db\models\query.py", line 380, in __len__
    self._fetch_all()
  File "C:\mysite\venv\Lib\site-packages\django\db\models\query.py", line 1881, in _fetch_all
    self._result_cache = list(self._iterable_class(self))
                         ^^^^^^^^^^^^^^^^^^^^^^^^^^^^^^^^
  File "C:\mysite\venv\Lib\site-packages\django\db\models\query.py", line 91, in __iter__
    results = compiler.execute_sql(
              ^^^^^^^^^^^^^^^^^^^^^
  File "C:\mysite\venv\Lib\site-packages\django\db\models\sql\compiler.py", line 1560, in execute_sql
    cursor = self.connection.cursor()
             ^^^^^^^^^^^^^^^^^^^^^^^^
  File "C:\mysite\venv\Lib\site-packages\django\utils\asyncio.py", line 26, in inner
    return func(*args, **kwargs)
           ^^^^^^^^^^^^^^^^^^^^^
  File "C:\mysite\venv\Lib\site-packages\django\db\backends\base\base.py", line 330, in cursor
    return self._cursor()
           ^^^^^^^^^^^^^^
  File "C:\mysite\venv\Lib\site-packages\django\db\backends\base\base.py", line 306, in _cursor
    self.ensure_connection()
  File "C:\mysite\venv\Lib\site-packages\django\utils\asyncio.py", line 26, in inner
    return func(*args, **kwargs)
           ^^^^^^^^^^^^^^^^^^^^^
  File "C:\mysite\venv\Lib\site-packages\django\db\backends\base\base.py", line 288, in ensure_connection
    with self.wrap_database_errors:
  File "C:\mysite\venv\Lib\site-packages\django\db\utils.py", line 91, in __exit__
    raise dj_exc_value.with_traceback(traceback) from exc_value
  File "C:\mysite\venv\Lib\site-packages\django\db\backends\base\base.py", line 289, in ensure_connection
    self.connect()
  File "C:\mysite\venv\Lib\site-packages\django\utils\asyncio.py", line 26, in inner
    return func(*args, **kwargs)
           ^^^^^^^^^^^^^^^^^^^^^
  File "C:\mysite\venv\Lib\site-packages\django\db\backends\base\base.py", line 270, in connect
    self.connection = self.get_new_connection(conn_params)
                      ^^^^^^^^^^^^^^^^^^^^^^^^^^^^^^^^^^^^
  File "C:\mysite\venv\Lib\site-packages\django\utils\asyncio.py", line 26, in inner
    return func(*args, **kwargs)
           ^^^^^^^^^^^^^^^^^^^^^
  File "C:\mysite\venv\Lib\site-packages\django\db\backends\postgresql\base.py", line 275, in get_new_connection
    connection = self.Database.connect(**conn_params)
                 ^^^^^^^^^^^^^^^^^^^^^^^^^^^^^^^^^^^^
  File "C:\mysite\venv\Lib\site-packages\psycopg2\__init__.py", line 122, in connect
    conn = _connect(dsn, connection_factory=connection_factory, **kwasync)
           ^^^^^^^^^^^^^^^^^^^^^^^^^^^^^^^^^^^^^^^^^^^^^^^^^^^^^^^^^^^^^^^
django.db.utils.OperationalError: connection to server at "localhost" (::1), port 5433 failed: Connection refused (0x0000274D/10061)
	Is the server running on that host and accepting TCP/IP connections?
connection to server at "localhost" (127.0.0.1), port 5433 failed: Connection refused (0x0000274D/10061)
	Is the server running on that host and accepting TCP/IP connections?

Internal Server Error: /cart/
Traceback (most recent call last):
  File "C:\mysite\venv\Lib\site-packages\django\contrib\sessions\backends\base.py", line 187, in _get_session
    return self._session_cache
           ^^^^^^^^^^^^^^^^^^^
AttributeError: 'SessionStore' object has no attribute '_session_cache'

During handling of the above exception, another exception occurred:

Traceback (most recent call last):
  File "C:\mysite\venv\Lib\site-packages\django\db\backends\base\base.py", line 289, in ensure_connection
    self.connect()
  File "C:\mysite\venv\Lib\site-packages\django\utils\asyncio.py", line 26, in inner
    return func(*args, **kwargs)
           ^^^^^^^^^^^^^^^^^^^^^
  File "C:\mysite\venv\Lib\site-packages\django\db\backends\base\base.py", line 270, in connect
    self.connection = self.get_new_connection(conn_params)
                      ^^^^^^^^^^^^^^^^^^^^^^^^^^^^^^^^^^^^
  File "C:\mysite\venv\Lib\site-packages\django\utils\asyncio.py", line 26, in inner
    return func(*args, **kwargs)
           ^^^^^^^^^^^^^^^^^^^^^
  File "C:\mysite\venv\Lib\site-packages\django\db\backends\postgresql\base.py", line 275, in get_new_connection
    connection = self.Database.connect(**conn_params)
                 ^^^^^^^^^^^^^^^^^^^^^^^^^^^^^^^^^^^^
  File "C:\mysite\venv\Lib\site-packages\psycopg2\__init__.py", line 122, in connect
    conn = _connect(dsn, connection_factory=connection_factory, **kwasync)
           ^^^^^^^^^^^^^^^^^^^^^^^^^^^^^^^^^^^^^^^^^^^^^^^^^^^^^^^^^^^^^^^
psycopg2.OperationalError: connection to server at "localhost" (::1), port 5433 failed: Connection refused (0x0000274D/10061)
	Is the server running on that host and accepting TCP/IP connections?
connection to server at "localhost" (127.0.0.1), port 5433 failed: Connection refused (0x0000274D/10061)
	Is the server running on that host and accepting TCP/IP connections?


The above exception was the direct cause of the following exception:

Traceback (most recent call last):
  File "C:\mysite\venv\Lib\site-packages\django\core\handlers\exception.py", line 55, in inner
    response = get_response(request)
               ^^^^^^^^^^^^^^^^^^^^^
  File "C:\mysite\venv\Lib\site-packages\django\utils\deprecation.py", line 136, in __call__
    response = self.process_response(request, response)
               ^^^^^^^^^^^^^^^^^^^^^^^^^^^^^^^^^^^^^^^^
  File "C:\mysite\venv\Lib\site-packages\django\contrib\sessions\middleware.py", line 48, in process_response
    if request.session.get_expire_at_browser_close():
       ^^^^^^^^^^^^^^^^^^^^^^^^^^^^^^^^^^^^^^^^^^^^^
  File "C:\mysite\venv\Lib\site-packages\django\contrib\sessions\backends\base.py", line 285, in get_expire_at_browser_close
    if (expiry := self.get("_session_expiry")) is None:
                  ^^^^^^^^^^^^^^^^^^^^^^^^^^^
  File "C:\mysite\venv\Lib\site-packages\django\contrib\sessions\backends\base.py", line 68, in get
    return self._session.get(key, default)
           ^^^^^^^^^^^^^
  File "C:\mysite\venv\Lib\site-packages\django\contrib\sessions\backends\base.py", line 192, in _get_session
    self._session_cache = self.load()
                          ^^^^^^^^^^^
  File "C:\mysite\venv\Lib\site-packages\django\contrib\sessions\backends\db.py", line 42, in load
    s = self._get_session_from_db()
        ^^^^^^^^^^^^^^^^^^^^^^^^^^^
  File "C:\mysite\venv\Lib\site-packages\django\contrib\sessions\backends\db.py", line 32, in _get_session_from_db
    return self.model.objects.get(
           ^^^^^^^^^^^^^^^^^^^^^^^
  File "C:\mysite\venv\Lib\site-packages\django\db\models\manager.py", line 87, in manager_method
    return getattr(self.get_queryset(), name)(*args, **kwargs)
           ^^^^^^^^^^^^^^^^^^^^^^^^^^^^^^^^^^^^^^^^^^^^^^^^^^^
  File "C:\mysite\venv\Lib\site-packages\django\db\models\query.py", line 633, in get
    num = len(clone)
          ^^^^^^^^^^
  File "C:\mysite\venv\Lib\site-packages\django\db\models\query.py", line 380, in __len__
    self._fetch_all()
  File "C:\mysite\venv\Lib\site-packages\django\db\models\query.py", line 1881, in _fetch_all
    self._result_cache = list(self._iterable_class(self))
                         ^^^^^^^^^^^^^^^^^^^^^^^^^^^^^^^^
  File "C:\mysite\venv\Lib\site-packages\django\db\models\query.py", line 91, in __iter__
    results = compiler.execute_sql(
              ^^^^^^^^^^^^^^^^^^^^^
  File "C:\mysite\venv\Lib\site-packages\django\db\models\sql\compiler.py", line 1560, in execute_sql
    cursor = self.connection.cursor()
             ^^^^^^^^^^^^^^^^^^^^^^^^
  File "C:\mysite\venv\Lib\site-packages\django\utils\asyncio.py", line 26, in inner
    return func(*args, **kwargs)
           ^^^^^^^^^^^^^^^^^^^^^
  File "C:\mysite\venv\Lib\site-packages\django\db\backends\base\base.py", line 330, in cursor
    return self._cursor()
           ^^^^^^^^^^^^^^
  File "C:\mysite\venv\Lib\site-packages\django\db\backends\base\base.py", line 306, in _cursor
    self.ensure_connection()
  File "C:\mysite\venv\Lib\site-packages\django\utils\asyncio.py", line 26, in inner
    return func(*args, **kwargs)
           ^^^^^^^^^^^^^^^^^^^^^
  File "C:\mysite\venv\Lib\site-packages\django\db\backends\base\base.py", line 288, in ensure_connection
    with self.wrap_database_errors:
  File "C:\mysite\venv\Lib\site-packages\django\db\utils.py", line 91, in __exit__
    raise dj_exc_value.with_traceback(traceback) from exc_value
  File "C:\mysite\venv\Lib\site-packages\django\db\backends\base\base.py", line 289, in ensure_connection
    self.connect()
  File "C:\mysite\venv\Lib\site-packages\django\utils\asyncio.py", line 26, in inner
    return func(*args, **kwargs)
           ^^^^^^^^^^^^^^^^^^^^^
  File "C:\mysite\venv\Lib\site-packages\django\db\backends\base\base.py", line 270, in connect
    self.connection = self.get_new_connection(conn_params)
                      ^^^^^^^^^^^^^^^^^^^^^^^^^^^^^^^^^^^^
  File "C:\mysite\venv\Lib\site-packages\django\utils\asyncio.py", line 26, in inner
    return func(*args, **kwargs)
           ^^^^^^^^^^^^^^^^^^^^^
  File "C:\mysite\venv\Lib\site-packages\django\db\backends\postgresql\base.py", line 275, in get_new_connection
    connection = self.Database.connect(**conn_params)
                 ^^^^^^^^^^^^^^^^^^^^^^^^^^^^^^^^^^^^
  File "C:\mysite\venv\Lib\site-packages\psycopg2\__init__.py", line 122, in connect
    conn = _connect(dsn, connection_factory=connection_factory, **kwasync)
           ^^^^^^^^^^^^^^^^^^^^^^^^^^^^^^^^^^^^^^^^^^^^^^^^^^^^^^^^^^^^^^^
django.db.utils.OperationalError: connection to server at "localhost" (::1), port 5433 failed: Connection refused (0x0000274D/10061)
	Is the server running on that host and accepting TCP/IP connections?
connection to server at "localhost" (127.0.0.1), port 5433 failed: Connection refused (0x0000274D/10061)
	Is the server running on that host and accepting TCP/IP connections?

"GET /cart/ HTTP/1.1" 500 205865
Internal Server Error: /
Traceback (most recent call last):
  File "C:\mysite\venv\Lib\site-packages\django\contrib\sessions\backends\base.py", line 187, in _get_session
    return self._session_cache
           ^^^^^^^^^^^^^^^^^^^
AttributeError: 'SessionStore' object has no attribute '_session_cache'

During handling of the above exception, another exception occurred:

Traceback (most recent call last):
  File "C:\mysite\venv\Lib\site-packages\django\db\backends\base\base.py", line 289, in ensure_connection
    self.connect()
  File "C:\mysite\venv\Lib\site-packages\django\utils\asyncio.py", line 26, in inner
    return func(*args, **kwargs)
           ^^^^^^^^^^^^^^^^^^^^^
  File "C:\mysite\venv\Lib\site-packages\django\db\backends\base\base.py", line 270, in connect
    self.connection = self.get_new_connection(conn_params)
                      ^^^^^^^^^^^^^^^^^^^^^^^^^^^^^^^^^^^^
  File "C:\mysite\venv\Lib\site-packages\django\utils\asyncio.py", line 26, in inner
    return func(*args, **kwargs)
           ^^^^^^^^^^^^^^^^^^^^^
  File "C:\mysite\venv\Lib\site-packages\django\db\backends\postgresql\base.py", line 275, in get_new_connection
    connection = self.Database.connect(**conn_params)
                 ^^^^^^^^^^^^^^^^^^^^^^^^^^^^^^^^^^^^
  File "C:\mysite\venv\Lib\site-packages\psycopg2\__init__.py", line 122, in connect
    conn = _connect(dsn, connection_factory=connection_factory, **kwasync)
           ^^^^^^^^^^^^^^^^^^^^^^^^^^^^^^^^^^^^^^^^^^^^^^^^^^^^^^^^^^^^^^^
psycopg2.OperationalError: connection to server at "localhost" (::1), port 5433 failed: Connection refused (0x0000274D/10061)
	Is the server running on that host and accepting TCP/IP connections?
connection to server at "localhost" (127.0.0.1), port 5433 failed: Connection refused (0x0000274D/10061)
	Is the server running on that host and accepting TCP/IP connections?


The above exception was the direct cause of the following exception:

Traceback (most recent call last):
  File "C:\mysite\venv\Lib\site-packages\django\core\handlers\exception.py", line 55, in inner
    response = get_response(request)
               ^^^^^^^^^^^^^^^^^^^^^
  File "C:\mysite\venv\Lib\site-packages\django\core\handlers\base.py", line 197, in _get_response
    response = wrapped_callback(request, *callback_args, **callback_kwargs)
               ^^^^^^^^^^^^^^^^^^^^^^^^^^^^^^^^^^^^^^^^^^^^^^^^^^^^^^^^^^^^
  File "C:\mysite\shop\store\views.py", line 22, in index
    return render(request, 'store/index.html')
           ^^^^^^^^^^^^^^^^^^^^^^^^^^^^^^^^^^^
  File "C:\mysite\venv\Lib\site-packages\django\shortcuts.py", line 24, in render
    content = loader.render_to_string(template_name, context, request, using=using)
              ^^^^^^^^^^^^^^^^^^^^^^^^^^^^^^^^^^^^^^^^^^^^^^^^^^^^^^^^^^^^^^^^^^^^^
  File "C:\mysite\venv\Lib\site-packages\django\template\loader.py", line 62, in render_to_string
    return template.render(context, request)
           ^^^^^^^^^^^^^^^^^^^^^^^^^^^^^^^^^
  File "C:\mysite\venv\Lib\site-packages\django\template\backends\django.py", line 61, in render
    return self.template.render(context)
           ^^^^^^^^^^^^^^^^^^^^^^^^^^^^^
  File "C:\mysite\venv\Lib\site-packages\django\template\base.py", line 175, in render
    return self._render(context)
           ^^^^^^^^^^^^^^^^^^^^^
  File "C:\mysite\venv\Lib\site-packages\django\template\base.py", line 167, in _render
    return self.nodelist.render(context)
           ^^^^^^^^^^^^^^^^^^^^^^^^^^^^^
  File "C:\mysite\venv\Lib\site-packages\django\template\base.py", line 1005, in render
    return SafeString("".join([node.render_annotated(context) for node in self]))
                               ^^^^^^^^^^^^^^^^^^^^^^^^^^^^^^
  File "C:\mysite\venv\Lib\site-packages\django\template\base.py", line 966, in render_annotated
    return self.render(context)
           ^^^^^^^^^^^^^^^^^^^^
  File "C:\mysite\venv\Lib\site-packages\django\template\loader_tags.py", line 157, in render
    return compiled_parent._render(context)
           ^^^^^^^^^^^^^^^^^^^^^^^^^^^^^^^^
  File "C:\mysite\venv\Lib\site-packages\django\template\base.py", line 167, in _render
    return self.nodelist.render(context)
           ^^^^^^^^^^^^^^^^^^^^^^^^^^^^^
  File "C:\mysite\venv\Lib\site-packages\django\template\base.py", line 1005, in render
    return SafeString("".join([node.render_annotated(context) for node in self]))
                               ^^^^^^^^^^^^^^^^^^^^^^^^^^^^^^
  File "C:\mysite\venv\Lib\site-packages\django\template\base.py", line 966, in render_annotated
    return self.render(context)
           ^^^^^^^^^^^^^^^^^^^^
  File "C:\mysite\venv\Lib\site-packages\django\template\defaulttags.py", line 314, in render
    match = condition.eval(context)
            ^^^^^^^^^^^^^^^^^^^^^^^
  File "C:\mysite\venv\Lib\site-packages\django\template\defaulttags.py", line 877, in eval
    return self.value.resolve(context, ignore_failures=True)
           ^^^^^^^^^^^^^^^^^^^^^^^^^^^^^^^^^^^^^^^^^^^^^^^^^
  File "C:\mysite\venv\Lib\site-packages\django\template\base.py", line 715, in resolve
    obj = self.var.resolve(context)
          ^^^^^^^^^^^^^^^^^^^^^^^^^
  File "C:\mysite\venv\Lib\site-packages\django\template\base.py", line 847, in resolve
    value = self._resolve_lookup(context)
            ^^^^^^^^^^^^^^^^^^^^^^^^^^^^^
  File "C:\mysite\venv\Lib\site-packages\django\template\base.py", line 880, in _resolve_lookup
    current = current[bit]
              ~~~~~~~^^^^^
  File "C:\mysite\venv\Lib\site-packages\django\utils\functional.py", line 266, in inner
    self._setup()
  File "C:\mysite\venv\Lib\site-packages\django\utils\functional.py", line 419, in _setup
    self._wrapped = self._setupfunc()
                    ^^^^^^^^^^^^^^^^^
  File "C:\mysite\venv\Lib\site-packages\django\contrib\auth\middleware.py", line 25, in <lambda>
    request.user = SimpleLazyObject(lambda: get_user(request))
                                            ^^^^^^^^^^^^^^^^^
  File "C:\mysite\venv\Lib\site-packages\django\contrib\auth\middleware.py", line 11, in get_user
    request._cached_user = auth.get_user(request)
                           ^^^^^^^^^^^^^^^^^^^^^^
  File "C:\mysite\venv\Lib\site-packages\django\contrib\auth\__init__.py", line 191, in get_user
    user_id = _get_user_session_key(request)
              ^^^^^^^^^^^^^^^^^^^^^^^^^^^^^^
  File "C:\mysite\venv\Lib\site-packages\django\contrib\auth\__init__.py", line 60, in _get_user_session_key
    return get_user_model()._meta.pk.to_python(request.session[SESSION_KEY])
                                               ~~~~~~~~~~~~~~~^^^^^^^^^^^^^
  File "C:\mysite\venv\Lib\site-packages\django\contrib\sessions\backends\base.py", line 53, in __getitem__
    return self._session[key]
           ^^^^^^^^^^^^^
  File "C:\mysite\venv\Lib\site-packages\django\contrib\sessions\backends\base.py", line 192, in _get_session
    self._session_cache = self.load()
                          ^^^^^^^^^^^
  File "C:\mysite\venv\Lib\site-packages\django\contrib\sessions\backends\db.py", line 42, in load
    s = self._get_session_from_db()
        ^^^^^^^^^^^^^^^^^^^^^^^^^^^
  File "C:\mysite\venv\Lib\site-packages\django\contrib\sessions\backends\db.py", line 32, in _get_session_from_db
    return self.model.objects.get(
           ^^^^^^^^^^^^^^^^^^^^^^^
  File "C:\mysite\venv\Lib\site-packages\django\db\models\manager.py", line 87, in manager_method
    return getattr(self.get_queryset(), name)(*args, **kwargs)
           ^^^^^^^^^^^^^^^^^^^^^^^^^^^^^^^^^^^^^^^^^^^^^^^^^^^
  File "C:\mysite\venv\Lib\site-packages\django\db\models\query.py", line 633, in get
    num = len(clone)
          ^^^^^^^^^^
  File "C:\mysite\venv\Lib\site-packages\django\db\models\query.py", line 380, in __len__
    self._fetch_all()
  File "C:\mysite\venv\Lib\site-packages\django\db\models\query.py", line 1881, in _fetch_all
    self._result_cache = list(self._iterable_class(self))
                         ^^^^^^^^^^^^^^^^^^^^^^^^^^^^^^^^
  File "C:\mysite\venv\Lib\site-packages\django\db\models\query.py", line 91, in __iter__
    results = compiler.execute_sql(
              ^^^^^^^^^^^^^^^^^^^^^
  File "C:\mysite\venv\Lib\site-packages\django\db\models\sql\compiler.py", line 1560, in execute_sql
    cursor = self.connection.cursor()
             ^^^^^^^^^^^^^^^^^^^^^^^^
  File "C:\mysite\venv\Lib\site-packages\django\utils\asyncio.py", line 26, in inner
    return func(*args, **kwargs)
           ^^^^^^^^^^^^^^^^^^^^^
  File "C:\mysite\venv\Lib\site-packages\django\db\backends\base\base.py", line 330, in cursor
    return self._cursor()
           ^^^^^^^^^^^^^^
  File "C:\mysite\venv\Lib\site-packages\django\db\backends\base\base.py", line 306, in _cursor
    self.ensure_connection()
  File "C:\mysite\venv\Lib\site-packages\django\utils\asyncio.py", line 26, in inner
    return func(*args, **kwargs)
           ^^^^^^^^^^^^^^^^^^^^^
  File "C:\mysite\venv\Lib\site-packages\django\db\backends\base\base.py", line 288, in ensure_connection
    with self.wrap_database_errors:
  File "C:\mysite\venv\Lib\site-packages\django\db\utils.py", line 91, in __exit__
    raise dj_exc_value.with_traceback(traceback) from exc_value
  File "C:\mysite\venv\Lib\site-packages\django\db\backends\base\base.py", line 289, in ensure_connection
    self.connect()
  File "C:\mysite\venv\Lib\site-packages\django\utils\asyncio.py", line 26, in inner
    return func(*args, **kwargs)
           ^^^^^^^^^^^^^^^^^^^^^
  File "C:\mysite\venv\Lib\site-packages\django\db\backends\base\base.py", line 270, in connect
    self.connection = self.get_new_connection(conn_params)
                      ^^^^^^^^^^^^^^^^^^^^^^^^^^^^^^^^^^^^
  File "C:\mysite\venv\Lib\site-packages\django\utils\asyncio.py", line 26, in inner
    return func(*args, **kwargs)
           ^^^^^^^^^^^^^^^^^^^^^
  File "C:\mysite\venv\Lib\site-packages\django\db\backends\postgresql\base.py", line 275, in get_new_connection
    connection = self.Database.connect(**conn_params)
                 ^^^^^^^^^^^^^^^^^^^^^^^^^^^^^^^^^^^^
  File "C:\mysite\venv\Lib\site-packages\psycopg2\__init__.py", line 122, in connect
    conn = _connect(dsn, connection_factory=connection_factory, **kwasync)
           ^^^^^^^^^^^^^^^^^^^^^^^^^^^^^^^^^^^^^^^^^^^^^^^^^^^^^^^^^^^^^^^
django.db.utils.OperationalError: connection to server at "localhost" (::1), port 5433 failed: Connection refused (0x0000274D/10061)
	Is the server running on that host and accepting TCP/IP connections?
connection to server at "localhost" (127.0.0.1), port 5433 failed: Connection refused (0x0000274D/10061)
	Is the server running on that host and accepting TCP/IP connections?

Internal Server Error: /
Traceback (most recent call last):
  File "C:\mysite\venv\Lib\site-packages\django\contrib\sessions\backends\base.py", line 187, in _get_session
    return self._session_cache
           ^^^^^^^^^^^^^^^^^^^
AttributeError: 'SessionStore' object has no attribute '_session_cache'

During handling of the above exception, another exception occurred:

Traceback (most recent call last):
  File "C:\mysite\venv\Lib\site-packages\django\db\backends\base\base.py", line 289, in ensure_connection
    self.connect()
  File "C:\mysite\venv\Lib\site-packages\django\utils\asyncio.py", line 26, in inner
    return func(*args, **kwargs)
           ^^^^^^^^^^^^^^^^^^^^^
  File "C:\mysite\venv\Lib\site-packages\django\db\backends\base\base.py", line 270, in connect
    self.connection = self.get_new_connection(conn_params)
                      ^^^^^^^^^^^^^^^^^^^^^^^^^^^^^^^^^^^^
  File "C:\mysite\venv\Lib\site-packages\django\utils\asyncio.py", line 26, in inner
    return func(*args, **kwargs)
           ^^^^^^^^^^^^^^^^^^^^^
  File "C:\mysite\venv\Lib\site-packages\django\db\backends\postgresql\base.py", line 275, in get_new_connection
    connection = self.Database.connect(**conn_params)
                 ^^^^^^^^^^^^^^^^^^^^^^^^^^^^^^^^^^^^
  File "C:\mysite\venv\Lib\site-packages\psycopg2\__init__.py", line 122, in connect
    conn = _connect(dsn, connection_factory=connection_factory, **kwasync)
           ^^^^^^^^^^^^^^^^^^^^^^^^^^^^^^^^^^^^^^^^^^^^^^^^^^^^^^^^^^^^^^^
psycopg2.OperationalError: connection to server at "localhost" (::1), port 5433 failed: Connection refused (0x0000274D/10061)
	Is the server running on that host and accepting TCP/IP connections?
connection to server at "localhost" (127.0.0.1), port 5433 failed: Connection refused (0x0000274D/10061)
	Is the server running on that host and accepting TCP/IP connections?


The above exception was the direct cause of the following exception:

Traceback (most recent call last):
  File "C:\mysite\venv\Lib\site-packages\django\core\handlers\exception.py", line 55, in inner
    response = get_response(request)
               ^^^^^^^^^^^^^^^^^^^^^
  File "C:\mysite\venv\Lib\site-packages\django\core\handlers\base.py", line 197, in _get_response
    response = wrapped_callback(request, *callback_args, **callback_kwargs)
               ^^^^^^^^^^^^^^^^^^^^^^^^^^^^^^^^^^^^^^^^^^^^^^^^^^^^^^^^^^^^
  File "C:\mysite\shop\store\views.py", line 22, in index
    return render(request, 'store/index.html')
           ^^^^^^^^^^^^^^^^^^^^^^^^^^^^^^^^^^^
  File "C:\mysite\venv\Lib\site-packages\django\shortcuts.py", line 24, in render
    content = loader.render_to_string(template_name, context, request, using=using)
              ^^^^^^^^^^^^^^^^^^^^^^^^^^^^^^^^^^^^^^^^^^^^^^^^^^^^^^^^^^^^^^^^^^^^^
  File "C:\mysite\venv\Lib\site-packages\django\template\loader.py", line 62, in render_to_string
    return template.render(context, request)
           ^^^^^^^^^^^^^^^^^^^^^^^^^^^^^^^^^
  File "C:\mysite\venv\Lib\site-packages\django\template\backends\django.py", line 61, in render
    return self.template.render(context)
           ^^^^^^^^^^^^^^^^^^^^^^^^^^^^^
  File "C:\mysite\venv\Lib\site-packages\django\template\base.py", line 175, in render
    return self._render(context)
           ^^^^^^^^^^^^^^^^^^^^^
  File "C:\mysite\venv\Lib\site-packages\django\template\base.py", line 167, in _render
    return self.nodelist.render(context)
           ^^^^^^^^^^^^^^^^^^^^^^^^^^^^^
  File "C:\mysite\venv\Lib\site-packages\django\template\base.py", line 1005, in render
    return SafeString("".join([node.render_annotated(context) for node in self]))
                               ^^^^^^^^^^^^^^^^^^^^^^^^^^^^^^
  File "C:\mysite\venv\Lib\site-packages\django\template\base.py", line 966, in render_annotated
    return self.render(context)
           ^^^^^^^^^^^^^^^^^^^^
  File "C:\mysite\venv\Lib\site-packages\django\template\loader_tags.py", line 157, in render
    return compiled_parent._render(context)
           ^^^^^^^^^^^^^^^^^^^^^^^^^^^^^^^^
  File "C:\mysite\venv\Lib\site-packages\django\template\base.py", line 167, in _render
    return self.nodelist.render(context)
           ^^^^^^^^^^^^^^^^^^^^^^^^^^^^^
  File "C:\mysite\venv\Lib\site-packages\django\template\base.py", line 1005, in render
    return SafeString("".join([node.render_annotated(context) for node in self]))
                               ^^^^^^^^^^^^^^^^^^^^^^^^^^^^^^
  File "C:\mysite\venv\Lib\site-packages\django\template\base.py", line 966, in render_annotated
    return self.render(context)
           ^^^^^^^^^^^^^^^^^^^^
  File "C:\mysite\venv\Lib\site-packages\django\template\defaulttags.py", line 314, in render
    match = condition.eval(context)
            ^^^^^^^^^^^^^^^^^^^^^^^
  File "C:\mysite\venv\Lib\site-packages\django\template\defaulttags.py", line 877, in eval
    return self.value.resolve(context, ignore_failures=True)
           ^^^^^^^^^^^^^^^^^^^^^^^^^^^^^^^^^^^^^^^^^^^^^^^^^
  File "C:\mysite\venv\Lib\site-packages\django\template\base.py", line 715, in resolve
    obj = self.var.resolve(context)
          ^^^^^^^^^^^^^^^^^^^^^^^^^
  File "C:\mysite\venv\Lib\site-packages\django\template\base.py", line 847, in resolve
    value = self._resolve_lookup(context)
            ^^^^^^^^^^^^^^^^^^^^^^^^^^^^^
  File "C:\mysite\venv\Lib\site-packages\django\template\base.py", line 880, in _resolve_lookup
    current = current[bit]
              ~~~~~~~^^^^^
  File "C:\mysite\venv\Lib\site-packages\django\utils\functional.py", line 266, in inner
    self._setup()
  File "C:\mysite\venv\Lib\site-packages\django\utils\functional.py", line 419, in _setup
    self._wrapped = self._setupfunc()
                    ^^^^^^^^^^^^^^^^^
  File "C:\mysite\venv\Lib\site-packages\django\contrib\auth\middleware.py", line 25, in <lambda>
    request.user = SimpleLazyObject(lambda: get_user(request))
                                            ^^^^^^^^^^^^^^^^^
  File "C:\mysite\venv\Lib\site-packages\django\contrib\auth\middleware.py", line 11, in get_user
    request._cached_user = auth.get_user(request)
                           ^^^^^^^^^^^^^^^^^^^^^^
  File "C:\mysite\venv\Lib\site-packages\django\contrib\auth\__init__.py", line 191, in get_user
    user_id = _get_user_session_key(request)
              ^^^^^^^^^^^^^^^^^^^^^^^^^^^^^^
  File "C:\mysite\venv\Lib\site-packages\django\contrib\auth\__init__.py", line 60, in _get_user_session_key
    return get_user_model()._meta.pk.to_python(request.session[SESSION_KEY])
                                               ~~~~~~~~~~~~~~~^^^^^^^^^^^^^
  File "C:\mysite\venv\Lib\site-packages\django\contrib\sessions\backends\base.py", line 53, in __getitem__
    return self._session[key]
           ^^^^^^^^^^^^^
  File "C:\mysite\venv\Lib\site-packages\django\contrib\sessions\backends\base.py", line 192, in _get_session
    self._session_cache = self.load()
                          ^^^^^^^^^^^
  File "C:\mysite\venv\Lib\site-packages\django\contrib\sessions\backends\db.py", line 42, in load
    s = self._get_session_from_db()
        ^^^^^^^^^^^^^^^^^^^^^^^^^^^
  File "C:\mysite\venv\Lib\site-packages\django\contrib\sessions\backends\db.py", line 32, in _get_session_from_db
    return self.model.objects.get(
           ^^^^^^^^^^^^^^^^^^^^^^^
  File "C:\mysite\venv\Lib\site-packages\django\db\models\manager.py", line 87, in manager_method
    return getattr(self.get_queryset(), name)(*args, **kwargs)
           ^^^^^^^^^^^^^^^^^^^^^^^^^^^^^^^^^^^^^^^^^^^^^^^^^^^
  File "C:\mysite\venv\Lib\site-packages\django\db\models\query.py", line 633, in get
    num = len(clone)
          ^^^^^^^^^^
  File "C:\mysite\venv\Lib\site-packages\django\db\models\query.py", line 380, in __len__
    self._fetch_all()
  File "C:\mysite\venv\Lib\site-packages\django\db\models\query.py", line 1881, in _fetch_all
    self._result_cache = list(self._iterable_class(self))
                         ^^^^^^^^^^^^^^^^^^^^^^^^^^^^^^^^
  File "C:\mysite\venv\Lib\site-packages\django\db\models\query.py", line 91, in __iter__
    results = compiler.execute_sql(
              ^^^^^^^^^^^^^^^^^^^^^
  File "C:\mysite\venv\Lib\site-packages\django\db\models\sql\compiler.py", line 1560, in execute_sql
    cursor = self.connection.cursor()
             ^^^^^^^^^^^^^^^^^^^^^^^^
  File "C:\mysite\venv\Lib\site-packages\django\utils\asyncio.py", line 26, in inner
    return func(*args, **kwargs)
           ^^^^^^^^^^^^^^^^^^^^^
  File "C:\mysite\venv\Lib\site-packages\django\db\backends\base\base.py", line 330, in cursor
    return self._cursor()
           ^^^^^^^^^^^^^^
  File "C:\mysite\venv\Lib\site-packages\django\db\backends\base\base.py", line 306, in _cursor
    self.ensure_connection()
  File "C:\mysite\venv\Lib\site-packages\django\utils\asyncio.py", line 26, in inner
    return func(*args, **kwargs)
           ^^^^^^^^^^^^^^^^^^^^^
  File "C:\mysite\venv\Lib\site-packages\django\db\backends\base\base.py", line 288, in ensure_connection
    with self.wrap_database_errors:
  File "C:\mysite\venv\Lib\site-packages\django\db\utils.py", line 91, in __exit__
    raise dj_exc_value.with_traceback(traceback) from exc_value
  File "C:\mysite\venv\Lib\site-packages\django\db\backends\base\base.py", line 289, in ensure_connection
    self.connect()
  File "C:\mysite\venv\Lib\site-packages\django\utils\asyncio.py", line 26, in inner
    return func(*args, **kwargs)
           ^^^^^^^^^^^^^^^^^^^^^
  File "C:\mysite\venv\Lib\site-packages\django\db\backends\base\base.py", line 270, in connect
    self.connection = self.get_new_connection(conn_params)
                      ^^^^^^^^^^^^^^^^^^^^^^^^^^^^^^^^^^^^
  File "C:\mysite\venv\Lib\site-packages\django\utils\asyncio.py", line 26, in inner
    return func(*args, **kwargs)
           ^^^^^^^^^^^^^^^^^^^^^
  File "C:\mysite\venv\Lib\site-packages\django\db\backends\postgresql\base.py", line 275, in get_new_connection
    connection = self.Database.connect(**conn_params)
                 ^^^^^^^^^^^^^^^^^^^^^^^^^^^^^^^^^^^^
  File "C:\mysite\venv\Lib\site-packages\psycopg2\__init__.py", line 122, in connect
    conn = _connect(dsn, connection_factory=connection_factory, **kwasync)
           ^^^^^^^^^^^^^^^^^^^^^^^^^^^^^^^^^^^^^^^^^^^^^^^^^^^^^^^^^^^^^^^
django.db.utils.OperationalError: connection to server at "localhost" (::1), port 5433 failed: Connection refused (0x0000274D/10061)
	Is the server running on that host and accepting TCP/IP connections?
connection to server at "localhost" (127.0.0.1), port 5433 failed: Connection refused (0x0000274D/10061)
	Is the server running on that host and accepting TCP/IP connections?

Internal Server Error: /
Traceback (most recent call last):
  File "C:\mysite\venv\Lib\site-packages\django\contrib\sessions\backends\base.py", line 187, in _get_session
    return self._session_cache
           ^^^^^^^^^^^^^^^^^^^
AttributeError: 'SessionStore' object has no attribute '_session_cache'

During handling of the above exception, another exception occurred:

Traceback (most recent call last):
  File "C:\mysite\venv\Lib\site-packages\django\db\backends\base\base.py", line 289, in ensure_connection
    self.connect()
  File "C:\mysite\venv\Lib\site-packages\django\utils\asyncio.py", line 26, in inner
    return func(*args, **kwargs)
           ^^^^^^^^^^^^^^^^^^^^^
  File "C:\mysite\venv\Lib\site-packages\django\db\backends\base\base.py", line 270, in connect
    self.connection = self.get_new_connection(conn_params)
                      ^^^^^^^^^^^^^^^^^^^^^^^^^^^^^^^^^^^^
  File "C:\mysite\venv\Lib\site-packages\django\utils\asyncio.py", line 26, in inner
    return func(*args, **kwargs)
           ^^^^^^^^^^^^^^^^^^^^^
  File "C:\mysite\venv\Lib\site-packages\django\db\backends\postgresql\base.py", line 275, in get_new_connection
    connection = self.Database.connect(**conn_params)
                 ^^^^^^^^^^^^^^^^^^^^^^^^^^^^^^^^^^^^
  File "C:\mysite\venv\Lib\site-packages\psycopg2\__init__.py", line 122, in connect
    conn = _connect(dsn, connection_factory=connection_factory, **kwasync)
           ^^^^^^^^^^^^^^^^^^^^^^^^^^^^^^^^^^^^^^^^^^^^^^^^^^^^^^^^^^^^^^^
psycopg2.OperationalError: connection to server at "localhost" (::1), port 5433 failed: Connection refused (0x0000274D/10061)
	Is the server running on that host and accepting TCP/IP connections?
connection to server at "localhost" (127.0.0.1), port 5433 failed: Connection refused (0x0000274D/10061)
	Is the server running on that host and accepting TCP/IP connections?


The above exception was the direct cause of the following exception:

Traceback (most recent call last):
  File "C:\mysite\venv\Lib\site-packages\django\core\handlers\exception.py", line 55, in inner
    response = get_response(request)
               ^^^^^^^^^^^^^^^^^^^^^
  File "C:\mysite\venv\Lib\site-packages\django\core\handlers\base.py", line 197, in _get_response
    response = wrapped_callback(request, *callback_args, **callback_kwargs)
               ^^^^^^^^^^^^^^^^^^^^^^^^^^^^^^^^^^^^^^^^^^^^^^^^^^^^^^^^^^^^
  File "C:\mysite\shop\store\views.py", line 22, in index
    return render(request, 'store/index.html')
           ^^^^^^^^^^^^^^^^^^^^^^^^^^^^^^^^^^^
  File "C:\mysite\venv\Lib\site-packages\django\shortcuts.py", line 24, in render
    content = loader.render_to_string(template_name, context, request, using=using)
              ^^^^^^^^^^^^^^^^^^^^^^^^^^^^^^^^^^^^^^^^^^^^^^^^^^^^^^^^^^^^^^^^^^^^^
  File "C:\mysite\venv\Lib\site-packages\django\template\loader.py", line 62, in render_to_string
    return template.render(context, request)
           ^^^^^^^^^^^^^^^^^^^^^^^^^^^^^^^^^
  File "C:\mysite\venv\Lib\site-packages\django\template\backends\django.py", line 61, in render
    return self.template.render(context)
           ^^^^^^^^^^^^^^^^^^^^^^^^^^^^^
  File "C:\mysite\venv\Lib\site-packages\django\template\base.py", line 175, in render
    return self._render(context)
           ^^^^^^^^^^^^^^^^^^^^^
  File "C:\mysite\venv\Lib\site-packages\django\template\base.py", line 167, in _render
    return self.nodelist.render(context)
           ^^^^^^^^^^^^^^^^^^^^^^^^^^^^^
  File "C:\mysite\venv\Lib\site-packages\django\template\base.py", line 1005, in render
    return SafeString("".join([node.render_annotated(context) for node in self]))
                               ^^^^^^^^^^^^^^^^^^^^^^^^^^^^^^
  File "C:\mysite\venv\Lib\site-packages\django\template\base.py", line 966, in render_annotated
    return self.render(context)
           ^^^^^^^^^^^^^^^^^^^^
  File "C:\mysite\venv\Lib\site-packages\django\template\loader_tags.py", line 157, in render
    return compiled_parent._render(context)
           ^^^^^^^^^^^^^^^^^^^^^^^^^^^^^^^^
  File "C:\mysite\venv\Lib\site-packages\django\template\base.py", line 167, in _render
    return self.nodelist.render(context)
           ^^^^^^^^^^^^^^^^^^^^^^^^^^^^^
  File "C:\mysite\venv\Lib\site-packages\django\template\base.py", line 1005, in render
    return SafeString("".join([node.render_annotated(context) for node in self]))
                               ^^^^^^^^^^^^^^^^^^^^^^^^^^^^^^
  File "C:\mysite\venv\Lib\site-packages\django\template\base.py", line 966, in render_annotated
    return self.render(context)
           ^^^^^^^^^^^^^^^^^^^^
  File "C:\mysite\venv\Lib\site-packages\django\template\defaulttags.py", line 314, in render
    match = condition.eval(context)
            ^^^^^^^^^^^^^^^^^^^^^^^
  File "C:\mysite\venv\Lib\site-packages\django\template\defaulttags.py", line 877, in eval
    return self.value.resolve(context, ignore_failures=True)
           ^^^^^^^^^^^^^^^^^^^^^^^^^^^^^^^^^^^^^^^^^^^^^^^^^
  File "C:\mysite\venv\Lib\site-packages\django\template\base.py", line 715, in resolve
    obj = self.var.resolve(context)
          ^^^^^^^^^^^^^^^^^^^^^^^^^
  File "C:\mysite\venv\Lib\site-packages\django\template\base.py", line 847, in resolve
    value = self._resolve_lookup(context)
            ^^^^^^^^^^^^^^^^^^^^^^^^^^^^^
  File "C:\mysite\venv\Lib\site-packages\django\template\base.py", line 880, in _resolve_lookup
    current = current[bit]
              ~~~~~~~^^^^^
  File "C:\mysite\venv\Lib\site-packages\django\utils\functional.py", line 266, in inner
    self._setup()
  File "C:\mysite\venv\Lib\site-packages\django\utils\functional.py", line 419, in _setup
    self._wrapped = self._setupfunc()
                    ^^^^^^^^^^^^^^^^^
  File "C:\mysite\venv\Lib\site-packages\django\contrib\auth\middleware.py", line 25, in <lambda>
    request.user = SimpleLazyObject(lambda: get_user(request))
                                            ^^^^^^^^^^^^^^^^^
  File "C:\mysite\venv\Lib\site-packages\django\contrib\auth\middleware.py", line 11, in get_user
    request._cached_user = auth.get_user(request)
                           ^^^^^^^^^^^^^^^^^^^^^^
  File "C:\mysite\venv\Lib\site-packages\django\contrib\auth\__init__.py", line 191, in get_user
    user_id = _get_user_session_key(request)
              ^^^^^^^^^^^^^^^^^^^^^^^^^^^^^^
  File "C:\mysite\venv\Lib\site-packages\django\contrib\auth\__init__.py", line 60, in _get_user_session_key
    return get_user_model()._meta.pk.to_python(request.session[SESSION_KEY])
                                               ~~~~~~~~~~~~~~~^^^^^^^^^^^^^
  File "C:\mysite\venv\Lib\site-packages\django\contrib\sessions\backends\base.py", line 53, in __getitem__
    return self._session[key]
           ^^^^^^^^^^^^^
  File "C:\mysite\venv\Lib\site-packages\django\contrib\sessions\backends\base.py", line 192, in _get_session
    self._session_cache = self.load()
                          ^^^^^^^^^^^
  File "C:\mysite\venv\Lib\site-packages\django\contrib\sessions\backends\db.py", line 42, in load
    s = self._get_session_from_db()
        ^^^^^^^^^^^^^^^^^^^^^^^^^^^
  File "C:\mysite\venv\Lib\site-packages\django\contrib\sessions\backends\db.py", line 32, in _get_session_from_db
    return self.model.objects.get(
           ^^^^^^^^^^^^^^^^^^^^^^^
  File "C:\mysite\venv\Lib\site-packages\django\db\models\manager.py", line 87, in manager_method
    return getattr(self.get_queryset(), name)(*args, **kwargs)
           ^^^^^^^^^^^^^^^^^^^^^^^^^^^^^^^^^^^^^^^^^^^^^^^^^^^
  File "C:\mysite\venv\Lib\site-packages\django\db\models\query.py", line 633, in get
    num = len(clone)
          ^^^^^^^^^^
  File "C:\mysite\venv\Lib\site-packages\django\db\models\query.py", line 380, in __len__
    self._fetch_all()
  File "C:\mysite\venv\Lib\site-packages\django\db\models\query.py", line 1881, in _fetch_all
    self._result_cache = list(self._iterable_class(self))
                         ^^^^^^^^^^^^^^^^^^^^^^^^^^^^^^^^
  File "C:\mysite\venv\Lib\site-packages\django\db\models\query.py", line 91, in __iter__
    results = compiler.execute_sql(
              ^^^^^^^^^^^^^^^^^^^^^
  File "C:\mysite\venv\Lib\site-packages\django\db\models\sql\compiler.py", line 1560, in execute_sql
    cursor = self.connection.cursor()
             ^^^^^^^^^^^^^^^^^^^^^^^^
  File "C:\mysite\venv\Lib\site-packages\django\utils\asyncio.py", line 26, in inner
    return func(*args, **kwargs)
           ^^^^^^^^^^^^^^^^^^^^^
  File "C:\mysite\venv\Lib\site-packages\django\db\backends\base\base.py", line 330, in cursor
    return self._cursor()
           ^^^^^^^^^^^^^^
  File "C:\mysite\venv\Lib\site-packages\django\db\backends\base\base.py", line 306, in _cursor
    self.ensure_connection()
  File "C:\mysite\venv\Lib\site-packages\django\utils\asyncio.py", line 26, in inner
    return func(*args, **kwargs)
           ^^^^^^^^^^^^^^^^^^^^^
  File "C:\mysite\venv\Lib\site-packages\django\db\backends\base\base.py", line 288, in ensure_connection
    with self.wrap_database_errors:
  File "C:\mysite\venv\Lib\site-packages\django\db\utils.py", line 91, in __exit__
    raise dj_exc_value.with_traceback(traceback) from exc_value
  File "C:\mysite\venv\Lib\site-packages\django\db\backends\base\base.py", line 289, in ensure_connection
    self.connect()
  File "C:\mysite\venv\Lib\site-packages\django\utils\asyncio.py", line 26, in inner
    return func(*args, **kwargs)
           ^^^^^^^^^^^^^^^^^^^^^
  File "C:\mysite\venv\Lib\site-packages\django\db\backends\base\base.py", line 270, in connect
    self.connection = self.get_new_connection(conn_params)
                      ^^^^^^^^^^^^^^^^^^^^^^^^^^^^^^^^^^^^
  File "C:\mysite\venv\Lib\site-packages\django\utils\asyncio.py", line 26, in inner
    return func(*args, **kwargs)
           ^^^^^^^^^^^^^^^^^^^^^
  File "C:\mysite\venv\Lib\site-packages\django\db\backends\postgresql\base.py", line 275, in get_new_connection
    connection = self.Database.connect(**conn_params)
                 ^^^^^^^^^^^^^^^^^^^^^^^^^^^^^^^^^^^^
  File "C:\mysite\venv\Lib\site-packages\psycopg2\__init__.py", line 122, in connect
    conn = _connect(dsn, connection_factory=connection_factory, **kwasync)
           ^^^^^^^^^^^^^^^^^^^^^^^^^^^^^^^^^^^^^^^^^^^^^^^^^^^^^^^^^^^^^^^
django.db.utils.OperationalError: connection to server at "localhost" (::1), port 5433 failed: Connection refused (0x0000274D/10061)
	Is the server running on that host and accepting TCP/IP connections?
connection to server at "localhost" (127.0.0.1), port 5433 failed: Connection refused (0x0000274D/10061)
	Is the server running on that host and accepting TCP/IP connections?

Internal Server Error: /
Traceback (most recent call last):
  File "C:\mysite\venv\Lib\site-packages\django\contrib\sessions\backends\base.py", line 187, in _get_session
    return self._session_cache
           ^^^^^^^^^^^^^^^^^^^
AttributeError: 'SessionStore' object has no attribute '_session_cache'

During handling of the above exception, another exception occurred:

Traceback (most recent call last):
  File "C:\mysite\venv\Lib\site-packages\django\db\backends\base\base.py", line 289, in ensure_connection
    self.connect()
  File "C:\mysite\venv\Lib\site-packages\django\utils\asyncio.py", line 26, in inner
    return func(*args, **kwargs)
           ^^^^^^^^^^^^^^^^^^^^^
  File "C:\mysite\venv\Lib\site-packages\django\db\backends\base\base.py", line 270, in connect
    self.connection = self.get_new_connection(conn_params)
                      ^^^^^^^^^^^^^^^^^^^^^^^^^^^^^^^^^^^^
  File "C:\mysite\venv\Lib\site-packages\django\utils\asyncio.py", line 26, in inner
    return func(*args, **kwargs)
           ^^^^^^^^^^^^^^^^^^^^^
  File "C:\mysite\venv\Lib\site-packages\django\db\backends\postgresql\base.py", line 275, in get_new_connection
    connection = self.Database.connect(**conn_params)
                 ^^^^^^^^^^^^^^^^^^^^^^^^^^^^^^^^^^^^
  File "C:\mysite\venv\Lib\site-packages\psycopg2\__init__.py", line 122, in connect
    conn = _connect(dsn, connection_factory=connection_factory, **kwasync)
           ^^^^^^^^^^^^^^^^^^^^^^^^^^^^^^^^^^^^^^^^^^^^^^^^^^^^^^^^^^^^^^^
psycopg2.OperationalError: connection to server at "localhost" (::1), port 5433 failed: Connection refused (0x0000274D/10061)
	Is the server running on that host and accepting TCP/IP connections?
connection to server at "localhost" (127.0.0.1), port 5433 failed: Connection refused (0x0000274D/10061)
	Is the server running on that host and accepting TCP/IP connections?


The above exception was the direct cause of the following exception:

Traceback (most recent call last):
  File "C:\mysite\venv\Lib\site-packages\django\core\handlers\exception.py", line 55, in inner
    response = get_response(request)
               ^^^^^^^^^^^^^^^^^^^^^
  File "C:\mysite\venv\Lib\site-packages\django\core\handlers\base.py", line 197, in _get_response
    response = wrapped_callback(request, *callback_args, **callback_kwargs)
               ^^^^^^^^^^^^^^^^^^^^^^^^^^^^^^^^^^^^^^^^^^^^^^^^^^^^^^^^^^^^
  File "C:\mysite\shop\store\views.py", line 22, in index
    return render(request, 'store/index.html')
           ^^^^^^^^^^^^^^^^^^^^^^^^^^^^^^^^^^^
  File "C:\mysite\venv\Lib\site-packages\django\shortcuts.py", line 24, in render
    content = loader.render_to_string(template_name, context, request, using=using)
              ^^^^^^^^^^^^^^^^^^^^^^^^^^^^^^^^^^^^^^^^^^^^^^^^^^^^^^^^^^^^^^^^^^^^^
  File "C:\mysite\venv\Lib\site-packages\django\template\loader.py", line 62, in render_to_string
    return template.render(context, request)
           ^^^^^^^^^^^^^^^^^^^^^^^^^^^^^^^^^
  File "C:\mysite\venv\Lib\site-packages\django\template\backends\django.py", line 61, in render
    return self.template.render(context)
           ^^^^^^^^^^^^^^^^^^^^^^^^^^^^^
  File "C:\mysite\venv\Lib\site-packages\django\template\base.py", line 175, in render
    return self._render(context)
           ^^^^^^^^^^^^^^^^^^^^^
  File "C:\mysite\venv\Lib\site-packages\django\template\base.py", line 167, in _render
    return self.nodelist.render(context)
           ^^^^^^^^^^^^^^^^^^^^^^^^^^^^^
  File "C:\mysite\venv\Lib\site-packages\django\template\base.py", line 1005, in render
    return SafeString("".join([node.render_annotated(context) for node in self]))
                               ^^^^^^^^^^^^^^^^^^^^^^^^^^^^^^
  File "C:\mysite\venv\Lib\site-packages\django\template\base.py", line 966, in render_annotated
    return self.render(context)
           ^^^^^^^^^^^^^^^^^^^^
  File "C:\mysite\venv\Lib\site-packages\django\template\loader_tags.py", line 157, in render
    return compiled_parent._render(context)
           ^^^^^^^^^^^^^^^^^^^^^^^^^^^^^^^^
  File "C:\mysite\venv\Lib\site-packages\django\template\base.py", line 167, in _render
    return self.nodelist.render(context)
           ^^^^^^^^^^^^^^^^^^^^^^^^^^^^^
  File "C:\mysite\venv\Lib\site-packages\django\template\base.py", line 1005, in render
    return SafeString("".join([node.render_annotated(context) for node in self]))
                               ^^^^^^^^^^^^^^^^^^^^^^^^^^^^^^
  File "C:\mysite\venv\Lib\site-packages\django\template\base.py", line 966, in render_annotated
    return self.render(context)
           ^^^^^^^^^^^^^^^^^^^^
  File "C:\mysite\venv\Lib\site-packages\django\template\defaulttags.py", line 314, in render
    match = condition.eval(context)
            ^^^^^^^^^^^^^^^^^^^^^^^
  File "C:\mysite\venv\Lib\site-packages\django\template\defaulttags.py", line 877, in eval
    return self.value.resolve(context, ignore_failures=True)
           ^^^^^^^^^^^^^^^^^^^^^^^^^^^^^^^^^^^^^^^^^^^^^^^^^
  File "C:\mysite\venv\Lib\site-packages\django\template\base.py", line 715, in resolve
    obj = self.var.resolve(context)
          ^^^^^^^^^^^^^^^^^^^^^^^^^
  File "C:\mysite\venv\Lib\site-packages\django\template\base.py", line 847, in resolve
    value = self._resolve_lookup(context)
            ^^^^^^^^^^^^^^^^^^^^^^^^^^^^^
  File "C:\mysite\venv\Lib\site-packages\django\template\base.py", line 880, in _resolve_lookup
    current = current[bit]
              ~~~~~~~^^^^^
  File "C:\mysite\venv\Lib\site-packages\django\utils\functional.py", line 266, in inner
    self._setup()
  File "C:\mysite\venv\Lib\site-packages\django\utils\functional.py", line 419, in _setup
    self._wrapped = self._setupfunc()
                    ^^^^^^^^^^^^^^^^^
  File "C:\mysite\venv\Lib\site-packages\django\contrib\auth\middleware.py", line 25, in <lambda>
    request.user = SimpleLazyObject(lambda: get_user(request))
                                            ^^^^^^^^^^^^^^^^^
  File "C:\mysite\venv\Lib\site-packages\django\contrib\auth\middleware.py", line 11, in get_user
    request._cached_user = auth.get_user(request)
                           ^^^^^^^^^^^^^^^^^^^^^^
  File "C:\mysite\venv\Lib\site-packages\django\contrib\auth\__init__.py", line 191, in get_user
    user_id = _get_user_session_key(request)
              ^^^^^^^^^^^^^^^^^^^^^^^^^^^^^^
  File "C:\mysite\venv\Lib\site-packages\django\contrib\auth\__init__.py", line 60, in _get_user_session_key
    return get_user_model()._meta.pk.to_python(request.session[SESSION_KEY])
                                               ~~~~~~~~~~~~~~~^^^^^^^^^^^^^
  File "C:\mysite\venv\Lib\site-packages\django\contrib\sessions\backends\base.py", line 53, in __getitem__
    return self._session[key]
           ^^^^^^^^^^^^^
  File "C:\mysite\venv\Lib\site-packages\django\contrib\sessions\backends\base.py", line 192, in _get_session
    self._session_cache = self.load()
                          ^^^^^^^^^^^
  File "C:\mysite\venv\Lib\site-packages\django\contrib\sessions\backends\db.py", line 42, in load
    s = self._get_session_from_db()
        ^^^^^^^^^^^^^^^^^^^^^^^^^^^
  File "C:\mysite\venv\Lib\site-packages\django\contrib\sessions\backends\db.py", line 32, in _get_session_from_db
    return self.model.objects.get(
           ^^^^^^^^^^^^^^^^^^^^^^^
  File "C:\mysite\venv\Lib\site-packages\django\db\models\manager.py", line 87, in manager_method
    return getattr(self.get_queryset(), name)(*args, **kwargs)
           ^^^^^^^^^^^^^^^^^^^^^^^^^^^^^^^^^^^^^^^^^^^^^^^^^^^
  File "C:\mysite\venv\Lib\site-packages\django\db\models\query.py", line 633, in get
    num = len(clone)
          ^^^^^^^^^^
  File "C:\mysite\venv\Lib\site-packages\django\db\models\query.py", line 380, in __len__
    self._fetch_all()
  File "C:\mysite\venv\Lib\site-packages\django\db\models\query.py", line 1881, in _fetch_all
    self._result_cache = list(self._iterable_class(self))
                         ^^^^^^^^^^^^^^^^^^^^^^^^^^^^^^^^
  File "C:\mysite\venv\Lib\site-packages\django\db\models\query.py", line 91, in __iter__
    results = compiler.execute_sql(
              ^^^^^^^^^^^^^^^^^^^^^
  File "C:\mysite\venv\Lib\site-packages\django\db\models\sql\compiler.py", line 1560, in execute_sql
    cursor = self.connection.cursor()
             ^^^^^^^^^^^^^^^^^^^^^^^^
  File "C:\mysite\venv\Lib\site-packages\django\utils\asyncio.py", line 26, in inner
    return func(*args, **kwargs)
           ^^^^^^^^^^^^^^^^^^^^^
  File "C:\mysite\venv\Lib\site-packages\django\db\backends\base\base.py", line 330, in cursor
    return self._cursor()
           ^^^^^^^^^^^^^^
  File "C:\mysite\venv\Lib\site-packages\django\db\backends\base\base.py", line 306, in _cursor
    self.ensure_connection()
  File "C:\mysite\venv\Lib\site-packages\django\utils\asyncio.py", line 26, in inner
    return func(*args, **kwargs)
           ^^^^^^^^^^^^^^^^^^^^^
  File "C:\mysite\venv\Lib\site-packages\django\db\backends\base\base.py", line 288, in ensure_connection
    with self.wrap_database_errors:
  File "C:\mysite\venv\Lib\site-packages\django\db\utils.py", line 91, in __exit__
    raise dj_exc_value.with_traceback(traceback) from exc_value
  File "C:\mysite\venv\Lib\site-packages\django\db\backends\base\base.py", line 289, in ensure_connection
    self.connect()
  File "C:\mysite\venv\Lib\site-packages\django\utils\asyncio.py", line 26, in inner
    return func(*args, **kwargs)
           ^^^^^^^^^^^^^^^^^^^^^
  File "C:\mysite\venv\Lib\site-packages\django\db\backends\base\base.py", line 270, in connect
    self.connection = self.get_new_connection(conn_params)
                      ^^^^^^^^^^^^^^^^^^^^^^^^^^^^^^^^^^^^
  File "C:\mysite\venv\Lib\site-packages\django\utils\asyncio.py", line 26, in inner
    return func(*args, **kwargs)
           ^^^^^^^^^^^^^^^^^^^^^
  File "C:\mysite\venv\Lib\site-packages\django\db\backends\postgresql\base.py", line 275, in get_new_connection
    connection = self.Database.connect(**conn_params)
                 ^^^^^^^^^^^^^^^^^^^^^^^^^^^^^^^^^^^^
  File "C:\mysite\venv\Lib\site-packages\psycopg2\__init__.py", line 122, in connect
    conn = _connect(dsn, connection_factory=connection_factory, **kwasync)
           ^^^^^^^^^^^^^^^^^^^^^^^^^^^^^^^^^^^^^^^^^^^^^^^^^^^^^^^^^^^^^^^
django.db.utils.OperationalError: connection to server at "localhost" (::1), port 5433 failed: Connection refused (0x0000274D/10061)
	Is the server running on that host and accepting TCP/IP connections?
connection to server at "localhost" (127.0.0.1), port 5433 failed: Connection refused (0x0000274D/10061)
	Is the server running on that host and accepting TCP/IP connections?

Internal Server Error: /
Traceback (most recent call last):
  File "C:\mysite\venv\Lib\site-packages\django\contrib\sessions\backends\base.py", line 187, in _get_session
    return self._session_cache
           ^^^^^^^^^^^^^^^^^^^
AttributeError: 'SessionStore' object has no attribute '_session_cache'

During handling of the above exception, another exception occurred:

Traceback (most recent call last):
  File "C:\mysite\venv\Lib\site-packages\django\db\backends\base\base.py", line 289, in ensure_connection
    self.connect()
  File "C:\mysite\venv\Lib\site-packages\django\utils\asyncio.py", line 26, in inner
    return func(*args, **kwargs)
           ^^^^^^^^^^^^^^^^^^^^^
  File "C:\mysite\venv\Lib\site-packages\django\db\backends\base\base.py", line 270, in connect
    self.connection = self.get_new_connection(conn_params)
                      ^^^^^^^^^^^^^^^^^^^^^^^^^^^^^^^^^^^^
  File "C:\mysite\venv\Lib\site-packages\django\utils\asyncio.py", line 26, in inner
    return func(*args, **kwargs)
           ^^^^^^^^^^^^^^^^^^^^^
  File "C:\mysite\venv\Lib\site-packages\django\db\backends\postgresql\base.py", line 275, in get_new_connection
    connection = self.Database.connect(**conn_params)
                 ^^^^^^^^^^^^^^^^^^^^^^^^^^^^^^^^^^^^
  File "C:\mysite\venv\Lib\site-packages\psycopg2\__init__.py", line 122, in connect
    conn = _connect(dsn, connection_factory=connection_factory, **kwasync)
           ^^^^^^^^^^^^^^^^^^^^^^^^^^^^^^^^^^^^^^^^^^^^^^^^^^^^^^^^^^^^^^^
psycopg2.OperationalError: connection to server at "localhost" (::1), port 5433 failed: Connection refused (0x0000274D/10061)
	Is the server running on that host and accepting TCP/IP connections?
connection to server at "localhost" (127.0.0.1), port 5433 failed: Connection refused (0x0000274D/10061)
	Is the server running on that host and accepting TCP/IP connections?


The above exception was the direct cause of the following exception:

Traceback (most recent call last):
  File "C:\mysite\venv\Lib\site-packages\django\core\handlers\exception.py", line 55, in inner
    response = get_response(request)
               ^^^^^^^^^^^^^^^^^^^^^
  File "C:\mysite\venv\Lib\site-packages\django\core\handlers\base.py", line 197, in _get_response
    response = wrapped_callback(request, *callback_args, **callback_kwargs)
               ^^^^^^^^^^^^^^^^^^^^^^^^^^^^^^^^^^^^^^^^^^^^^^^^^^^^^^^^^^^^
  File "C:\mysite\shop\store\views.py", line 22, in index
    return render(request, 'store/index.html')
           ^^^^^^^^^^^^^^^^^^^^^^^^^^^^^^^^^^^
  File "C:\mysite\venv\Lib\site-packages\django\shortcuts.py", line 24, in render
    content = loader.render_to_string(template_name, context, request, using=using)
              ^^^^^^^^^^^^^^^^^^^^^^^^^^^^^^^^^^^^^^^^^^^^^^^^^^^^^^^^^^^^^^^^^^^^^
  File "C:\mysite\venv\Lib\site-packages\django\template\loader.py", line 62, in render_to_string
    return template.render(context, request)
           ^^^^^^^^^^^^^^^^^^^^^^^^^^^^^^^^^
  File "C:\mysite\venv\Lib\site-packages\django\template\backends\django.py", line 61, in render
    return self.template.render(context)
           ^^^^^^^^^^^^^^^^^^^^^^^^^^^^^
  File "C:\mysite\venv\Lib\site-packages\django\template\base.py", line 175, in render
    return self._render(context)
           ^^^^^^^^^^^^^^^^^^^^^
  File "C:\mysite\venv\Lib\site-packages\django\template\base.py", line 167, in _render
    return self.nodelist.render(context)
           ^^^^^^^^^^^^^^^^^^^^^^^^^^^^^
  File "C:\mysite\venv\Lib\site-packages\django\template\base.py", line 1005, in render
    return SafeString("".join([node.render_annotated(context) for node in self]))
                               ^^^^^^^^^^^^^^^^^^^^^^^^^^^^^^
  File "C:\mysite\venv\Lib\site-packages\django\template\base.py", line 966, in render_annotated
    return self.render(context)
           ^^^^^^^^^^^^^^^^^^^^
  File "C:\mysite\venv\Lib\site-packages\django\template\loader_tags.py", line 157, in render
    return compiled_parent._render(context)
           ^^^^^^^^^^^^^^^^^^^^^^^^^^^^^^^^
  File "C:\mysite\venv\Lib\site-packages\django\template\base.py", line 167, in _render
    return self.nodelist.render(context)
           ^^^^^^^^^^^^^^^^^^^^^^^^^^^^^
  File "C:\mysite\venv\Lib\site-packages\django\template\base.py", line 1005, in render
    return SafeString("".join([node.render_annotated(context) for node in self]))
                               ^^^^^^^^^^^^^^^^^^^^^^^^^^^^^^
  File "C:\mysite\venv\Lib\site-packages\django\template\base.py", line 966, in render_annotated
    return self.render(context)
           ^^^^^^^^^^^^^^^^^^^^
  File "C:\mysite\venv\Lib\site-packages\django\template\defaulttags.py", line 314, in render
    match = condition.eval(context)
            ^^^^^^^^^^^^^^^^^^^^^^^
  File "C:\mysite\venv\Lib\site-packages\django\template\defaulttags.py", line 877, in eval
    return self.value.resolve(context, ignore_failures=True)
           ^^^^^^^^^^^^^^^^^^^^^^^^^^^^^^^^^^^^^^^^^^^^^^^^^
  File "C:\mysite\venv\Lib\site-packages\django\template\base.py", line 715, in resolve
    obj = self.var.resolve(context)
          ^^^^^^^^^^^^^^^^^^^^^^^^^
  File "C:\mysite\venv\Lib\site-packages\django\template\base.py", line 847, in resolve
    value = self._resolve_lookup(context)
            ^^^^^^^^^^^^^^^^^^^^^^^^^^^^^
  File "C:\mysite\venv\Lib\site-packages\django\template\base.py", line 880, in _resolve_lookup
    current = current[bit]
              ~~~~~~~^^^^^
  File "C:\mysite\venv\Lib\site-packages\django\utils\functional.py", line 266, in inner
    self._setup()
  File "C:\mysite\venv\Lib\site-packages\django\utils\functional.py", line 419, in _setup
    self._wrapped = self._setupfunc()
                    ^^^^^^^^^^^^^^^^^
  File "C:\mysite\venv\Lib\site-packages\django\contrib\auth\middleware.py", line 25, in <lambda>
    request.user = SimpleLazyObject(lambda: get_user(request))
                                            ^^^^^^^^^^^^^^^^^
  File "C:\mysite\venv\Lib\site-packages\django\contrib\auth\middleware.py", line 11, in get_user
    request._cached_user = auth.get_user(request)
                           ^^^^^^^^^^^^^^^^^^^^^^
  File "C:\mysite\venv\Lib\site-packages\django\contrib\auth\__init__.py", line 191, in get_user
    user_id = _get_user_session_key(request)
              ^^^^^^^^^^^^^^^^^^^^^^^^^^^^^^
  File "C:\mysite\venv\Lib\site-packages\django\contrib\auth\__init__.py", line 60, in _get_user_session_key
    return get_user_model()._meta.pk.to_python(request.session[SESSION_KEY])
                                               ~~~~~~~~~~~~~~~^^^^^^^^^^^^^
  File "C:\mysite\venv\Lib\site-packages\django\contrib\sessions\backends\base.py", line 53, in __getitem__
    return self._session[key]
           ^^^^^^^^^^^^^
  File "C:\mysite\venv\Lib\site-packages\django\contrib\sessions\backends\base.py", line 192, in _get_session
    self._session_cache = self.load()
                          ^^^^^^^^^^^
  File "C:\mysite\venv\Lib\site-packages\django\contrib\sessions\backends\db.py", line 42, in load
    s = self._get_session_from_db()
        ^^^^^^^^^^^^^^^^^^^^^^^^^^^
  File "C:\mysite\venv\Lib\site-packages\django\contrib\sessions\backends\db.py", line 32, in _get_session_from_db
    return self.model.objects.get(
           ^^^^^^^^^^^^^^^^^^^^^^^
  File "C:\mysite\venv\Lib\site-packages\django\db\models\manager.py", line 87, in manager_method
    return getattr(self.get_queryset(), name)(*args, **kwargs)
           ^^^^^^^^^^^^^^^^^^^^^^^^^^^^^^^^^^^^^^^^^^^^^^^^^^^
  File "C:\mysite\venv\Lib\site-packages\django\db\models\query.py", line 633, in get
    num = len(clone)
          ^^^^^^^^^^
  File "C:\mysite\venv\Lib\site-packages\django\db\models\query.py", line 380, in __len__
    self._fetch_all()
  File "C:\mysite\venv\Lib\site-packages\django\db\models\query.py", line 1881, in _fetch_all
    self._result_cache = list(self._iterable_class(self))
                         ^^^^^^^^^^^^^^^^^^^^^^^^^^^^^^^^
  File "C:\mysite\venv\Lib\site-packages\django\db\models\query.py", line 91, in __iter__
    results = compiler.execute_sql(
              ^^^^^^^^^^^^^^^^^^^^^
  File "C:\mysite\venv\Lib\site-packages\django\db\models\sql\compiler.py", line 1560, in execute_sql
    cursor = self.connection.cursor()
             ^^^^^^^^^^^^^^^^^^^^^^^^
  File "C:\mysite\venv\Lib\site-packages\django\utils\asyncio.py", line 26, in inner
    return func(*args, **kwargs)
           ^^^^^^^^^^^^^^^^^^^^^
  File "C:\mysite\venv\Lib\site-packages\django\db\backends\base\base.py", line 330, in cursor
    return self._cursor()
           ^^^^^^^^^^^^^^
  File "C:\mysite\venv\Lib\site-packages\django\db\backends\base\base.py", line 306, in _cursor
    self.ensure_connection()
  File "C:\mysite\venv\Lib\site-packages\django\utils\asyncio.py", line 26, in inner
    return func(*args, **kwargs)
           ^^^^^^^^^^^^^^^^^^^^^
  File "C:\mysite\venv\Lib\site-packages\django\db\backends\base\base.py", line 288, in ensure_connection
    with self.wrap_database_errors:
  File "C:\mysite\venv\Lib\site-packages\django\db\utils.py", line 91, in __exit__
    raise dj_exc_value.with_traceback(traceback) from exc_value
  File "C:\mysite\venv\Lib\site-packages\django\db\backends\base\base.py", line 289, in ensure_connection
    self.connect()
  File "C:\mysite\venv\Lib\site-packages\django\utils\asyncio.py", line 26, in inner
    return func(*args, **kwargs)
           ^^^^^^^^^^^^^^^^^^^^^
  File "C:\mysite\venv\Lib\site-packages\django\db\backends\base\base.py", line 270, in connect
    self.connection = self.get_new_connection(conn_params)
                      ^^^^^^^^^^^^^^^^^^^^^^^^^^^^^^^^^^^^
  File "C:\mysite\venv\Lib\site-packages\django\utils\asyncio.py", line 26, in inner
    return func(*args, **kwargs)
           ^^^^^^^^^^^^^^^^^^^^^
  File "C:\mysite\venv\Lib\site-packages\django\db\backends\postgresql\base.py", line 275, in get_new_connection
    connection = self.Database.connect(**conn_params)
                 ^^^^^^^^^^^^^^^^^^^^^^^^^^^^^^^^^^^^
  File "C:\mysite\venv\Lib\site-packages\psycopg2\__init__.py", line 122, in connect
    conn = _connect(dsn, connection_factory=connection_factory, **kwasync)
           ^^^^^^^^^^^^^^^^^^^^^^^^^^^^^^^^^^^^^^^^^^^^^^^^^^^^^^^^^^^^^^^
django.db.utils.OperationalError: connection to server at "localhost" (::1), port 5433 failed: Connection refused (0x0000274D/10061)
	Is the server running on that host and accepting TCP/IP connections?
connection to server at "localhost" (127.0.0.1), port 5433 failed: Connection refused (0x0000274D/10061)
	Is the server running on that host and accepting TCP/IP connections?

Internal Server Error: /admin
Traceback (most recent call last):
  File "C:\mysite\venv\Lib\site-packages\django\contrib\sessions\backends\base.py", line 187, in _get_session
    return self._session_cache
           ^^^^^^^^^^^^^^^^^^^
AttributeError: 'SessionStore' object has no attribute '_session_cache'

During handling of the above exception, another exception occurred:

Traceback (most recent call last):
  File "C:\mysite\venv\Lib\site-packages\django\db\backends\base\base.py", line 289, in ensure_connection
    self.connect()
  File "C:\mysite\venv\Lib\site-packages\django\utils\asyncio.py", line 26, in inner
    return func(*args, **kwargs)
           ^^^^^^^^^^^^^^^^^^^^^
  File "C:\mysite\venv\Lib\site-packages\django\db\backends\base\base.py", line 270, in connect
    self.connection = self.get_new_connection(conn_params)
                      ^^^^^^^^^^^^^^^^^^^^^^^^^^^^^^^^^^^^
  File "C:\mysite\venv\Lib\site-packages\django\utils\asyncio.py", line 26, in inner
    return func(*args, **kwargs)
           ^^^^^^^^^^^^^^^^^^^^^
  File "C:\mysite\venv\Lib\site-packages\django\db\backends\postgresql\base.py", line 275, in get_new_connection
    connection = self.Database.connect(**conn_params)
                 ^^^^^^^^^^^^^^^^^^^^^^^^^^^^^^^^^^^^
  File "C:\mysite\venv\Lib\site-packages\psycopg2\__init__.py", line 122, in connect
    conn = _connect(dsn, connection_factory=connection_factory, **kwasync)
           ^^^^^^^^^^^^^^^^^^^^^^^^^^^^^^^^^^^^^^^^^^^^^^^^^^^^^^^^^^^^^^^
psycopg2.OperationalError: connection to server at "localhost" (::1), port 5433 failed: Connection refused (0x0000274D/10061)
	Is the server running on that host and accepting TCP/IP connections?
connection to server at "localhost" (127.0.0.1), port 5433 failed: Connection refused (0x0000274D/10061)
	Is the server running on that host and accepting TCP/IP connections?


The above exception was the direct cause of the following exception:

Traceback (most recent call last):
  File "C:\mysite\venv\Lib\site-packages\django\core\handlers\exception.py", line 55, in inner
    response = get_response(request)
               ^^^^^^^^^^^^^^^^^^^^^
  File "C:\mysite\venv\Lib\site-packages\django\utils\deprecation.py", line 136, in __call__
    response = self.process_response(request, response)
               ^^^^^^^^^^^^^^^^^^^^^^^^^^^^^^^^^^^^^^^^
  File "C:\mysite\venv\Lib\site-packages\django\contrib\sessions\middleware.py", line 48, in process_response
    if request.session.get_expire_at_browser_close():
       ^^^^^^^^^^^^^^^^^^^^^^^^^^^^^^^^^^^^^^^^^^^^^
  File "C:\mysite\venv\Lib\site-packages\django\contrib\sessions\backends\base.py", line 285, in get_expire_at_browser_close
    if (expiry := self.get("_session_expiry")) is None:
                  ^^^^^^^^^^^^^^^^^^^^^^^^^^^
  File "C:\mysite\venv\Lib\site-packages\django\contrib\sessions\backends\base.py", line 68, in get
    return self._session.get(key, default)
           ^^^^^^^^^^^^^
  File "C:\mysite\venv\Lib\site-packages\django\contrib\sessions\backends\base.py", line 192, in _get_session
    self._session_cache = self.load()
                          ^^^^^^^^^^^
  File "C:\mysite\venv\Lib\site-packages\django\contrib\sessions\backends\db.py", line 42, in load
    s = self._get_session_from_db()
        ^^^^^^^^^^^^^^^^^^^^^^^^^^^
  File "C:\mysite\venv\Lib\site-packages\django\contrib\sessions\backends\db.py", line 32, in _get_session_from_db
    return self.model.objects.get(
           ^^^^^^^^^^^^^^^^^^^^^^^
  File "C:\mysite\venv\Lib\site-packages\django\db\models\manager.py", line 87, in manager_method
    return getattr(self.get_queryset(), name)(*args, **kwargs)
           ^^^^^^^^^^^^^^^^^^^^^^^^^^^^^^^^^^^^^^^^^^^^^^^^^^^
  File "C:\mysite\venv\Lib\site-packages\django\db\models\query.py", line 633, in get
    num = len(clone)
          ^^^^^^^^^^
  File "C:\mysite\venv\Lib\site-packages\django\db\models\query.py", line 380, in __len__
    self._fetch_all()
  File "C:\mysite\venv\Lib\site-packages\django\db\models\query.py", line 1881, in _fetch_all
    self._result_cache = list(self._iterable_class(self))
                         ^^^^^^^^^^^^^^^^^^^^^^^^^^^^^^^^
  File "C:\mysite\venv\Lib\site-packages\django\db\models\query.py", line 91, in __iter__
    results = compiler.execute_sql(
              ^^^^^^^^^^^^^^^^^^^^^
  File "C:\mysite\venv\Lib\site-packages\django\db\models\sql\compiler.py", line 1560, in execute_sql
    cursor = self.connection.cursor()
             ^^^^^^^^^^^^^^^^^^^^^^^^
  File "C:\mysite\venv\Lib\site-packages\django\utils\asyncio.py", line 26, in inner
    return func(*args, **kwargs)
           ^^^^^^^^^^^^^^^^^^^^^
  File "C:\mysite\venv\Lib\site-packages\django\db\backends\base\base.py", line 330, in cursor
    return self._cursor()
           ^^^^^^^^^^^^^^
  File "C:\mysite\venv\Lib\site-packages\django\db\backends\base\base.py", line 306, in _cursor
    self.ensure_connection()
  File "C:\mysite\venv\Lib\site-packages\django\utils\asyncio.py", line 26, in inner
    return func(*args, **kwargs)
           ^^^^^^^^^^^^^^^^^^^^^
  File "C:\mysite\venv\Lib\site-packages\django\db\backends\base\base.py", line 288, in ensure_connection
    with self.wrap_database_errors:
  File "C:\mysite\venv\Lib\site-packages\django\db\utils.py", line 91, in __exit__
    raise dj_exc_value.with_traceback(traceback) from exc_value
  File "C:\mysite\venv\Lib\site-packages\django\db\backends\base\base.py", line 289, in ensure_connection
    self.connect()
  File "C:\mysite\venv\Lib\site-packages\django\utils\asyncio.py", line 26, in inner
    return func(*args, **kwargs)
           ^^^^^^^^^^^^^^^^^^^^^
  File "C:\mysite\venv\Lib\site-packages\django\db\backends\base\base.py", line 270, in connect
    self.connection = self.get_new_connection(conn_params)
                      ^^^^^^^^^^^^^^^^^^^^^^^^^^^^^^^^^^^^
  File "C:\mysite\venv\Lib\site-packages\django\utils\asyncio.py", line 26, in inner
    return func(*args, **kwargs)
           ^^^^^^^^^^^^^^^^^^^^^
  File "C:\mysite\venv\Lib\site-packages\django\db\backends\postgresql\base.py", line 275, in get_new_connection
    connection = self.Database.connect(**conn_params)
                 ^^^^^^^^^^^^^^^^^^^^^^^^^^^^^^^^^^^^
  File "C:\mysite\venv\Lib\site-packages\psycopg2\__init__.py", line 122, in connect
    conn = _connect(dsn, connection_factory=connection_factory, **kwasync)
           ^^^^^^^^^^^^^^^^^^^^^^^^^^^^^^^^^^^^^^^^^^^^^^^^^^^^^^^^^^^^^^^
django.db.utils.OperationalError: connection to server at "localhost" (::1), port 5433 failed: Connection refused (0x0000274D/10061)
	Is the server running on that host and accepting TCP/IP connections?
connection to server at "localhost" (127.0.0.1), port 5433 failed: Connection refused (0x0000274D/10061)
	Is the server running on that host and accepting TCP/IP connections?

"GET /admin HTTP/1.1" 500 205597
Internal Server Error: /
Traceback (most recent call last):
  File "C:\mysite\venv\Lib\site-packages\django\contrib\sessions\backends\base.py", line 187, in _get_session
    return self._session_cache
           ^^^^^^^^^^^^^^^^^^^
AttributeError: 'SessionStore' object has no attribute '_session_cache'

During handling of the above exception, another exception occurred:

Traceback (most recent call last):
  File "C:\mysite\venv\Lib\site-packages\django\db\backends\base\base.py", line 289, in ensure_connection
    self.connect()
  File "C:\mysite\venv\Lib\site-packages\django\utils\asyncio.py", line 26, in inner
    return func(*args, **kwargs)
           ^^^^^^^^^^^^^^^^^^^^^
  File "C:\mysite\venv\Lib\site-packages\django\db\backends\base\base.py", line 270, in connect
    self.connection = self.get_new_connection(conn_params)
                      ^^^^^^^^^^^^^^^^^^^^^^^^^^^^^^^^^^^^
  File "C:\mysite\venv\Lib\site-packages\django\utils\asyncio.py", line 26, in inner
    return func(*args, **kwargs)
           ^^^^^^^^^^^^^^^^^^^^^
  File "C:\mysite\venv\Lib\site-packages\django\db\backends\postgresql\base.py", line 275, in get_new_connection
    connection = self.Database.connect(**conn_params)
                 ^^^^^^^^^^^^^^^^^^^^^^^^^^^^^^^^^^^^
  File "C:\mysite\venv\Lib\site-packages\psycopg2\__init__.py", line 122, in connect
    conn = _connect(dsn, connection_factory=connection_factory, **kwasync)
           ^^^^^^^^^^^^^^^^^^^^^^^^^^^^^^^^^^^^^^^^^^^^^^^^^^^^^^^^^^^^^^^
psycopg2.OperationalError: connection to server at "localhost" (::1), port 5433 failed: Connection refused (0x0000274D/10061)
	Is the server running on that host and accepting TCP/IP connections?
connection to server at "localhost" (127.0.0.1), port 5433 failed: Connection refused (0x0000274D/10061)
	Is the server running on that host and accepting TCP/IP connections?


The above exception was the direct cause of the following exception:

Traceback (most recent call last):
  File "C:\mysite\venv\Lib\site-packages\django\core\handlers\exception.py", line 55, in inner
    response = get_response(request)
               ^^^^^^^^^^^^^^^^^^^^^
  File "C:\mysite\venv\Lib\site-packages\django\utils\deprecation.py", line 136, in __call__
    response = self.process_response(request, response)
               ^^^^^^^^^^^^^^^^^^^^^^^^^^^^^^^^^^^^^^^^
  File "C:\mysite\venv\Lib\site-packages\django\contrib\sessions\middleware.py", line 48, in process_response
    if request.session.get_expire_at_browser_close():
       ^^^^^^^^^^^^^^^^^^^^^^^^^^^^^^^^^^^^^^^^^^^^^
  File "C:\mysite\venv\Lib\site-packages\django\contrib\sessions\backends\base.py", line 285, in get_expire_at_browser_close
    if (expiry := self.get("_session_expiry")) is None:
                  ^^^^^^^^^^^^^^^^^^^^^^^^^^^
  File "C:\mysite\venv\Lib\site-packages\django\contrib\sessions\backends\base.py", line 68, in get
    return self._session.get(key, default)
           ^^^^^^^^^^^^^
  File "C:\mysite\venv\Lib\site-packages\django\contrib\sessions\backends\base.py", line 192, in _get_session
    self._session_cache = self.load()
                          ^^^^^^^^^^^
  File "C:\mysite\venv\Lib\site-packages\django\contrib\sessions\backends\db.py", line 42, in load
    s = self._get_session_from_db()
        ^^^^^^^^^^^^^^^^^^^^^^^^^^^
  File "C:\mysite\venv\Lib\site-packages\django\contrib\sessions\backends\db.py", line 32, in _get_session_from_db
    return self.model.objects.get(
           ^^^^^^^^^^^^^^^^^^^^^^^
  File "C:\mysite\venv\Lib\site-packages\django\db\models\manager.py", line 87, in manager_method
    return getattr(self.get_queryset(), name)(*args, **kwargs)
           ^^^^^^^^^^^^^^^^^^^^^^^^^^^^^^^^^^^^^^^^^^^^^^^^^^^
  File "C:\mysite\venv\Lib\site-packages\django\db\models\query.py", line 633, in get
    num = len(clone)
          ^^^^^^^^^^
  File "C:\mysite\venv\Lib\site-packages\django\db\models\query.py", line 380, in __len__
    self._fetch_all()
  File "C:\mysite\venv\Lib\site-packages\django\db\models\query.py", line 1881, in _fetch_all
    self._result_cache = list(self._iterable_class(self))
                         ^^^^^^^^^^^^^^^^^^^^^^^^^^^^^^^^
  File "C:\mysite\venv\Lib\site-packages\django\db\models\query.py", line 91, in __iter__
    results = compiler.execute_sql(
              ^^^^^^^^^^^^^^^^^^^^^
  File "C:\mysite\venv\Lib\site-packages\django\db\models\sql\compiler.py", line 1560, in execute_sql
    cursor = self.connection.cursor()
             ^^^^^^^^^^^^^^^^^^^^^^^^
  File "C:\mysite\venv\Lib\site-packages\django\utils\asyncio.py", line 26, in inner
    return func(*args, **kwargs)
           ^^^^^^^^^^^^^^^^^^^^^
  File "C:\mysite\venv\Lib\site-packages\django\db\backends\base\base.py", line 330, in cursor
    return self._cursor()
           ^^^^^^^^^^^^^^
  File "C:\mysite\venv\Lib\site-packages\django\db\backends\base\base.py", line 306, in _cursor
    self.ensure_connection()
  File "C:\mysite\venv\Lib\site-packages\django\utils\asyncio.py", line 26, in inner
    return func(*args, **kwargs)
           ^^^^^^^^^^^^^^^^^^^^^
  File "C:\mysite\venv\Lib\site-packages\django\db\backends\base\base.py", line 288, in ensure_connection
    with self.wrap_database_errors:
  File "C:\mysite\venv\Lib\site-packages\django\db\utils.py", line 91, in __exit__
    raise dj_exc_value.with_traceback(traceback) from exc_value
  File "C:\mysite\venv\Lib\site-packages\django\db\backends\base\base.py", line 289, in ensure_connection
    self.connect()
  File "C:\mysite\venv\Lib\site-packages\django\utils\asyncio.py", line 26, in inner
    return func(*args, **kwargs)
           ^^^^^^^^^^^^^^^^^^^^^
  File "C:\mysite\venv\Lib\site-packages\django\db\backends\base\base.py", line 270, in connect
    self.connection = self.get_new_connection(conn_params)
                      ^^^^^^^^^^^^^^^^^^^^^^^^^^^^^^^^^^^^
  File "C:\mysite\venv\Lib\site-packages\django\utils\asyncio.py", line 26, in inner
    return func(*args, **kwargs)
           ^^^^^^^^^^^^^^^^^^^^^
  File "C:\mysite\venv\Lib\site-packages\django\db\backends\postgresql\base.py", line 275, in get_new_connection
    connection = self.Database.connect(**conn_params)
                 ^^^^^^^^^^^^^^^^^^^^^^^^^^^^^^^^^^^^
  File "C:\mysite\venv\Lib\site-packages\psycopg2\__init__.py", line 122, in connect
    conn = _connect(dsn, connection_factory=connection_factory, **kwasync)
           ^^^^^^^^^^^^^^^^^^^^^^^^^^^^^^^^^^^^^^^^^^^^^^^^^^^^^^^^^^^^^^^
django.db.utils.OperationalError: connection to server at "localhost" (::1), port 5433 failed: Connection refused (0x0000274D/10061)
	Is the server running on that host and accepting TCP/IP connections?
connection to server at "localhost" (127.0.0.1), port 5433 failed: Connection refused (0x0000274D/10061)
	Is the server running on that host and accepting TCP/IP connections?

"GET / HTTP/1.1" 500 205681
Internal Server Error: /
Traceback (most recent call last):
  File "C:\mysite\venv\Lib\site-packages\django\contrib\sessions\backends\base.py", line 187, in _get_session
    return self._session_cache
           ^^^^^^^^^^^^^^^^^^^
AttributeError: 'SessionStore' object has no attribute '_session_cache'

During handling of the above exception, another exception occurred:

Traceback (most recent call last):
  File "C:\mysite\venv\Lib\site-packages\django\db\backends\base\base.py", line 289, in ensure_connection
    self.connect()
  File "C:\mysite\venv\Lib\site-packages\django\utils\asyncio.py", line 26, in inner
    return func(*args, **kwargs)
           ^^^^^^^^^^^^^^^^^^^^^
  File "C:\mysite\venv\Lib\site-packages\django\db\backends\base\base.py", line 270, in connect
    self.connection = self.get_new_connection(conn_params)
                      ^^^^^^^^^^^^^^^^^^^^^^^^^^^^^^^^^^^^
  File "C:\mysite\venv\Lib\site-packages\django\utils\asyncio.py", line 26, in inner
    return func(*args, **kwargs)
           ^^^^^^^^^^^^^^^^^^^^^
  File "C:\mysite\venv\Lib\site-packages\django\db\backends\postgresql\base.py", line 275, in get_new_connection
    connection = self.Database.connect(**conn_params)
                 ^^^^^^^^^^^^^^^^^^^^^^^^^^^^^^^^^^^^
  File "C:\mysite\venv\Lib\site-packages\psycopg2\__init__.py", line 122, in connect
    conn = _connect(dsn, connection_factory=connection_factory, **kwasync)
           ^^^^^^^^^^^^^^^^^^^^^^^^^^^^^^^^^^^^^^^^^^^^^^^^^^^^^^^^^^^^^^^
psycopg2.OperationalError: connection to server at "localhost" (::1), port 5433 failed: Connection refused (0x0000274D/10061)
	Is the server running on that host and accepting TCP/IP connections?
connection to server at "localhost" (127.0.0.1), port 5433 failed: Connection refused (0x0000274D/10061)
	Is the server running on that host and accepting TCP/IP connections?


The above exception was the direct cause of the following exception:

Traceback (most recent call last):
  File "C:\mysite\venv\Lib\site-packages\django\core\handlers\exception.py", line 55, in inner
    response = get_response(request)
               ^^^^^^^^^^^^^^^^^^^^^
  File "C:\mysite\venv\Lib\site-packages\django\utils\deprecation.py", line 136, in __call__
    response = self.process_response(request, response)
               ^^^^^^^^^^^^^^^^^^^^^^^^^^^^^^^^^^^^^^^^
  File "C:\mysite\venv\Lib\site-packages\django\contrib\sessions\middleware.py", line 48, in process_response
    if request.session.get_expire_at_browser_close():
       ^^^^^^^^^^^^^^^^^^^^^^^^^^^^^^^^^^^^^^^^^^^^^
  File "C:\mysite\venv\Lib\site-packages\django\contrib\sessions\backends\base.py", line 285, in get_expire_at_browser_close
    if (expiry := self.get("_session_expiry")) is None:
                  ^^^^^^^^^^^^^^^^^^^^^^^^^^^
  File "C:\mysite\venv\Lib\site-packages\django\contrib\sessions\backends\base.py", line 68, in get
    return self._session.get(key, default)
           ^^^^^^^^^^^^^
  File "C:\mysite\venv\Lib\site-packages\django\contrib\sessions\backends\base.py", line 192, in _get_session
    self._session_cache = self.load()
                          ^^^^^^^^^^^
  File "C:\mysite\venv\Lib\site-packages\django\contrib\sessions\backends\db.py", line 42, in load
    s = self._get_session_from_db()
        ^^^^^^^^^^^^^^^^^^^^^^^^^^^
  File "C:\mysite\venv\Lib\site-packages\django\contrib\sessions\backends\db.py", line 32, in _get_session_from_db
    return self.model.objects.get(
           ^^^^^^^^^^^^^^^^^^^^^^^
  File "C:\mysite\venv\Lib\site-packages\django\db\models\manager.py", line 87, in manager_method
    return getattr(self.get_queryset(), name)(*args, **kwargs)
           ^^^^^^^^^^^^^^^^^^^^^^^^^^^^^^^^^^^^^^^^^^^^^^^^^^^
  File "C:\mysite\venv\Lib\site-packages\django\db\models\query.py", line 633, in get
    num = len(clone)
          ^^^^^^^^^^
  File "C:\mysite\venv\Lib\site-packages\django\db\models\query.py", line 380, in __len__
    self._fetch_all()
  File "C:\mysite\venv\Lib\site-packages\django\db\models\query.py", line 1881, in _fetch_all
    self._result_cache = list(self._iterable_class(self))
                         ^^^^^^^^^^^^^^^^^^^^^^^^^^^^^^^^
  File "C:\mysite\venv\Lib\site-packages\django\db\models\query.py", line 91, in __iter__
    results = compiler.execute_sql(
              ^^^^^^^^^^^^^^^^^^^^^
  File "C:\mysite\venv\Lib\site-packages\django\db\models\sql\compiler.py", line 1560, in execute_sql
    cursor = self.connection.cursor()
             ^^^^^^^^^^^^^^^^^^^^^^^^
  File "C:\mysite\venv\Lib\site-packages\django\utils\asyncio.py", line 26, in inner
    return func(*args, **kwargs)
           ^^^^^^^^^^^^^^^^^^^^^
  File "C:\mysite\venv\Lib\site-packages\django\db\backends\base\base.py", line 330, in cursor
    return self._cursor()
           ^^^^^^^^^^^^^^
  File "C:\mysite\venv\Lib\site-packages\django\db\backends\base\base.py", line 306, in _cursor
    self.ensure_connection()
  File "C:\mysite\venv\Lib\site-packages\django\utils\asyncio.py", line 26, in inner
    return func(*args, **kwargs)
           ^^^^^^^^^^^^^^^^^^^^^
  File "C:\mysite\venv\Lib\site-packages\django\db\backends\base\base.py", line 288, in ensure_connection
    with self.wrap_database_errors:
  File "C:\mysite\venv\Lib\site-packages\django\db\utils.py", line 91, in __exit__
    raise dj_exc_value.with_traceback(traceback) from exc_value
  File "C:\mysite\venv\Lib\site-packages\django\db\backends\base\base.py", line 289, in ensure_connection
    self.connect()
  File "C:\mysite\venv\Lib\site-packages\django\utils\asyncio.py", line 26, in inner
    return func(*args, **kwargs)
           ^^^^^^^^^^^^^^^^^^^^^
  File "C:\mysite\venv\Lib\site-packages\django\db\backends\base\base.py", line 270, in connect
    self.connection = self.get_new_connection(conn_params)
                      ^^^^^^^^^^^^^^^^^^^^^^^^^^^^^^^^^^^^
  File "C:\mysite\venv\Lib\site-packages\django\utils\asyncio.py", line 26, in inner
    return func(*args, **kwargs)
           ^^^^^^^^^^^^^^^^^^^^^
  File "C:\mysite\venv\Lib\site-packages\django\db\backends\postgresql\base.py", line 275, in get_new_connection
    connection = self.Database.connect(**conn_params)
                 ^^^^^^^^^^^^^^^^^^^^^^^^^^^^^^^^^^^^
  File "C:\mysite\venv\Lib\site-packages\psycopg2\__init__.py", line 122, in connect
    conn = _connect(dsn, connection_factory=connection_factory, **kwasync)
           ^^^^^^^^^^^^^^^^^^^^^^^^^^^^^^^^^^^^^^^^^^^^^^^^^^^^^^^^^^^^^^^
django.db.utils.OperationalError: connection to server at "localhost" (::1), port 5433 failed: Connection refused (0x0000274D/10061)
	Is the server running on that host and accepting TCP/IP connections?
connection to server at "localhost" (127.0.0.1), port 5433 failed: Connection refused (0x0000274D/10061)
	Is the server running on that host and accepting TCP/IP connections?

"GET / HTTP/1.1" 500 205681
Internal Server Error: /
Traceback (most recent call last):
  File "C:\mysite\venv\Lib\site-packages\django\contrib\sessions\backends\base.py", line 187, in _get_session
    return self._session_cache
           ^^^^^^^^^^^^^^^^^^^
AttributeError: 'SessionStore' object has no attribute '_session_cache'

During handling of the above exception, another exception occurred:

Traceback (most recent call last):
  File "C:\mysite\venv\Lib\site-packages\django\db\backends\base\base.py", line 289, in ensure_connection
    self.connect()
  File "C:\mysite\venv\Lib\site-packages\django\utils\asyncio.py", line 26, in inner
    return func(*args, **kwargs)
           ^^^^^^^^^^^^^^^^^^^^^
  File "C:\mysite\venv\Lib\site-packages\django\db\backends\base\base.py", line 270, in connect
    self.connection = self.get_new_connection(conn_params)
                      ^^^^^^^^^^^^^^^^^^^^^^^^^^^^^^^^^^^^
  File "C:\mysite\venv\Lib\site-packages\django\utils\asyncio.py", line 26, in inner
    return func(*args, **kwargs)
           ^^^^^^^^^^^^^^^^^^^^^
  File "C:\mysite\venv\Lib\site-packages\django\db\backends\postgresql\base.py", line 275, in get_new_connection
    connection = self.Database.connect(**conn_params)
                 ^^^^^^^^^^^^^^^^^^^^^^^^^^^^^^^^^^^^
  File "C:\mysite\venv\Lib\site-packages\psycopg2\__init__.py", line 122, in connect
    conn = _connect(dsn, connection_factory=connection_factory, **kwasync)
           ^^^^^^^^^^^^^^^^^^^^^^^^^^^^^^^^^^^^^^^^^^^^^^^^^^^^^^^^^^^^^^^
psycopg2.OperationalError: connection to server at "localhost" (::1), port 5433 failed: Connection refused (0x0000274D/10061)
	Is the server running on that host and accepting TCP/IP connections?
connection to server at "localhost" (127.0.0.1), port 5433 failed: Connection refused (0x0000274D/10061)
	Is the server running on that host and accepting TCP/IP connections?


The above exception was the direct cause of the following exception:

Traceback (most recent call last):
  File "C:\mysite\venv\Lib\site-packages\django\core\handlers\exception.py", line 55, in inner
    response = get_response(request)
               ^^^^^^^^^^^^^^^^^^^^^
  File "C:\mysite\venv\Lib\site-packages\django\utils\deprecation.py", line 136, in __call__
    response = self.process_response(request, response)
               ^^^^^^^^^^^^^^^^^^^^^^^^^^^^^^^^^^^^^^^^
  File "C:\mysite\venv\Lib\site-packages\django\contrib\sessions\middleware.py", line 48, in process_response
    if request.session.get_expire_at_browser_close():
       ^^^^^^^^^^^^^^^^^^^^^^^^^^^^^^^^^^^^^^^^^^^^^
  File "C:\mysite\venv\Lib\site-packages\django\contrib\sessions\backends\base.py", line 285, in get_expire_at_browser_close
    if (expiry := self.get("_session_expiry")) is None:
                  ^^^^^^^^^^^^^^^^^^^^^^^^^^^
  File "C:\mysite\venv\Lib\site-packages\django\contrib\sessions\backends\base.py", line 68, in get
    return self._session.get(key, default)
           ^^^^^^^^^^^^^
  File "C:\mysite\venv\Lib\site-packages\django\contrib\sessions\backends\base.py", line 192, in _get_session
    self._session_cache = self.load()
                          ^^^^^^^^^^^
  File "C:\mysite\venv\Lib\site-packages\django\contrib\sessions\backends\db.py", line 42, in load
    s = self._get_session_from_db()
        ^^^^^^^^^^^^^^^^^^^^^^^^^^^
  File "C:\mysite\venv\Lib\site-packages\django\contrib\sessions\backends\db.py", line 32, in _get_session_from_db
    return self.model.objects.get(
           ^^^^^^^^^^^^^^^^^^^^^^^
  File "C:\mysite\venv\Lib\site-packages\django\db\models\manager.py", line 87, in manager_method
    return getattr(self.get_queryset(), name)(*args, **kwargs)
           ^^^^^^^^^^^^^^^^^^^^^^^^^^^^^^^^^^^^^^^^^^^^^^^^^^^
  File "C:\mysite\venv\Lib\site-packages\django\db\models\query.py", line 633, in get
    num = len(clone)
          ^^^^^^^^^^
  File "C:\mysite\venv\Lib\site-packages\django\db\models\query.py", line 380, in __len__
    self._fetch_all()
  File "C:\mysite\venv\Lib\site-packages\django\db\models\query.py", line 1881, in _fetch_all
    self._result_cache = list(self._iterable_class(self))
                         ^^^^^^^^^^^^^^^^^^^^^^^^^^^^^^^^
  File "C:\mysite\venv\Lib\site-packages\django\db\models\query.py", line 91, in __iter__
    results = compiler.execute_sql(
              ^^^^^^^^^^^^^^^^^^^^^
  File "C:\mysite\venv\Lib\site-packages\django\db\models\sql\compiler.py", line 1560, in execute_sql
    cursor = self.connection.cursor()
             ^^^^^^^^^^^^^^^^^^^^^^^^
  File "C:\mysite\venv\Lib\site-packages\django\utils\asyncio.py", line 26, in inner
    return func(*args, **kwargs)
           ^^^^^^^^^^^^^^^^^^^^^
  File "C:\mysite\venv\Lib\site-packages\django\db\backends\base\base.py", line 330, in cursor
    return self._cursor()
           ^^^^^^^^^^^^^^
  File "C:\mysite\venv\Lib\site-packages\django\db\backends\base\base.py", line 306, in _cursor
    self.ensure_connection()
  File "C:\mysite\venv\Lib\site-packages\django\utils\asyncio.py", line 26, in inner
    return func(*args, **kwargs)
           ^^^^^^^^^^^^^^^^^^^^^
  File "C:\mysite\venv\Lib\site-packages\django\db\backends\base\base.py", line 288, in ensure_connection
    with self.wrap_database_errors:
  File "C:\mysite\venv\Lib\site-packages\django\db\utils.py", line 91, in __exit__
    raise dj_exc_value.with_traceback(traceback) from exc_value
  File "C:\mysite\venv\Lib\site-packages\django\db\backends\base\base.py", line 289, in ensure_connection
    self.connect()
  File "C:\mysite\venv\Lib\site-packages\django\utils\asyncio.py", line 26, in inner
    return func(*args, **kwargs)
           ^^^^^^^^^^^^^^^^^^^^^
  File "C:\mysite\venv\Lib\site-packages\django\db\backends\base\base.py", line 270, in connect
    self.connection = self.get_new_connection(conn_params)
                      ^^^^^^^^^^^^^^^^^^^^^^^^^^^^^^^^^^^^
  File "C:\mysite\venv\Lib\site-packages\django\utils\asyncio.py", line 26, in inner
    return func(*args, **kwargs)
           ^^^^^^^^^^^^^^^^^^^^^
  File "C:\mysite\venv\Lib\site-packages\django\db\backends\postgresql\base.py", line 275, in get_new_connection
    connection = self.Database.connect(**conn_params)
                 ^^^^^^^^^^^^^^^^^^^^^^^^^^^^^^^^^^^^
  File "C:\mysite\venv\Lib\site-packages\psycopg2\__init__.py", line 122, in connect
    conn = _connect(dsn, connection_factory=connection_factory, **kwasync)
           ^^^^^^^^^^^^^^^^^^^^^^^^^^^^^^^^^^^^^^^^^^^^^^^^^^^^^^^^^^^^^^^
django.db.utils.OperationalError: connection to server at "localhost" (::1), port 5433 failed: Connection refused (0x0000274D/10061)
	Is the server running on that host and accepting TCP/IP connections?
connection to server at "localhost" (127.0.0.1), port 5433 failed: Connection refused (0x0000274D/10061)
	Is the server running on that host and accepting TCP/IP connections?

"GET / HTTP/1.1" 500 205681
Internal Server Error: /
Traceback (most recent call last):
  File "C:\mysite\venv\Lib\site-packages\django\contrib\sessions\backends\base.py", line 187, in _get_session
    return self._session_cache
           ^^^^^^^^^^^^^^^^^^^
AttributeError: 'SessionStore' object has no attribute '_session_cache'

During handling of the above exception, another exception occurred:

Traceback (most recent call last):
  File "C:\mysite\venv\Lib\site-packages\django\db\backends\base\base.py", line 289, in ensure_connection
    self.connect()
  File "C:\mysite\venv\Lib\site-packages\django\utils\asyncio.py", line 26, in inner
    return func(*args, **kwargs)
           ^^^^^^^^^^^^^^^^^^^^^
  File "C:\mysite\venv\Lib\site-packages\django\db\backends\base\base.py", line 270, in connect
    self.connection = self.get_new_connection(conn_params)
                      ^^^^^^^^^^^^^^^^^^^^^^^^^^^^^^^^^^^^
  File "C:\mysite\venv\Lib\site-packages\django\utils\asyncio.py", line 26, in inner
    return func(*args, **kwargs)
           ^^^^^^^^^^^^^^^^^^^^^
  File "C:\mysite\venv\Lib\site-packages\django\db\backends\postgresql\base.py", line 275, in get_new_connection
    connection = self.Database.connect(**conn_params)
                 ^^^^^^^^^^^^^^^^^^^^^^^^^^^^^^^^^^^^
  File "C:\mysite\venv\Lib\site-packages\psycopg2\__init__.py", line 122, in connect
    conn = _connect(dsn, connection_factory=connection_factory, **kwasync)
           ^^^^^^^^^^^^^^^^^^^^^^^^^^^^^^^^^^^^^^^^^^^^^^^^^^^^^^^^^^^^^^^
psycopg2.OperationalError: connection to server at "localhost" (::1), port 5433 failed: Connection refused (0x0000274D/10061)
	Is the server running on that host and accepting TCP/IP connections?
connection to server at "localhost" (127.0.0.1), port 5433 failed: Connection refused (0x0000274D/10061)
	Is the server running on that host and accepting TCP/IP connections?


The above exception was the direct cause of the following exception:

Traceback (most recent call last):
  File "C:\mysite\venv\Lib\site-packages\django\core\handlers\exception.py", line 55, in inner
    response = get_response(request)
               ^^^^^^^^^^^^^^^^^^^^^
  File "C:\mysite\venv\Lib\site-packages\django\utils\deprecation.py", line 136, in __call__
    response = self.process_response(request, response)
               ^^^^^^^^^^^^^^^^^^^^^^^^^^^^^^^^^^^^^^^^
  File "C:\mysite\venv\Lib\site-packages\django\contrib\sessions\middleware.py", line 48, in process_response
    if request.session.get_expire_at_browser_close():
       ^^^^^^^^^^^^^^^^^^^^^^^^^^^^^^^^^^^^^^^^^^^^^
  File "C:\mysite\venv\Lib\site-packages\django\contrib\sessions\backends\base.py", line 285, in get_expire_at_browser_close
    if (expiry := self.get("_session_expiry")) is None:
                  ^^^^^^^^^^^^^^^^^^^^^^^^^^^
  File "C:\mysite\venv\Lib\site-packages\django\contrib\sessions\backends\base.py", line 68, in get
    return self._session.get(key, default)
           ^^^^^^^^^^^^^
  File "C:\mysite\venv\Lib\site-packages\django\contrib\sessions\backends\base.py", line 192, in _get_session
    self._session_cache = self.load()
                          ^^^^^^^^^^^
  File "C:\mysite\venv\Lib\site-packages\django\contrib\sessions\backends\db.py", line 42, in load
    s = self._get_session_from_db()
        ^^^^^^^^^^^^^^^^^^^^^^^^^^^
  File "C:\mysite\venv\Lib\site-packages\django\contrib\sessions\backends\db.py", line 32, in _get_session_from_db
    return self.model.objects.get(
           ^^^^^^^^^^^^^^^^^^^^^^^
  File "C:\mysite\venv\Lib\site-packages\django\db\models\manager.py", line 87, in manager_method
    return getattr(self.get_queryset(), name)(*args, **kwargs)
           ^^^^^^^^^^^^^^^^^^^^^^^^^^^^^^^^^^^^^^^^^^^^^^^^^^^
  File "C:\mysite\venv\Lib\site-packages\django\db\models\query.py", line 633, in get
    num = len(clone)
          ^^^^^^^^^^
  File "C:\mysite\venv\Lib\site-packages\django\db\models\query.py", line 380, in __len__
    self._fetch_all()
  File "C:\mysite\venv\Lib\site-packages\django\db\models\query.py", line 1881, in _fetch_all
    self._result_cache = list(self._iterable_class(self))
                         ^^^^^^^^^^^^^^^^^^^^^^^^^^^^^^^^
  File "C:\mysite\venv\Lib\site-packages\django\db\models\query.py", line 91, in __iter__
    results = compiler.execute_sql(
              ^^^^^^^^^^^^^^^^^^^^^
  File "C:\mysite\venv\Lib\site-packages\django\db\models\sql\compiler.py", line 1560, in execute_sql
    cursor = self.connection.cursor()
             ^^^^^^^^^^^^^^^^^^^^^^^^
  File "C:\mysite\venv\Lib\site-packages\django\utils\asyncio.py", line 26, in inner
    return func(*args, **kwargs)
           ^^^^^^^^^^^^^^^^^^^^^
  File "C:\mysite\venv\Lib\site-packages\django\db\backends\base\base.py", line 330, in cursor
    return self._cursor()
           ^^^^^^^^^^^^^^
  File "C:\mysite\venv\Lib\site-packages\django\db\backends\base\base.py", line 306, in _cursor
    self.ensure_connection()
  File "C:\mysite\venv\Lib\site-packages\django\utils\asyncio.py", line 26, in inner
    return func(*args, **kwargs)
           ^^^^^^^^^^^^^^^^^^^^^
  File "C:\mysite\venv\Lib\site-packages\django\db\backends\base\base.py", line 288, in ensure_connection
    with self.wrap_database_errors:
  File "C:\mysite\venv\Lib\site-packages\django\db\utils.py", line 91, in __exit__
    raise dj_exc_value.with_traceback(traceback) from exc_value
  File "C:\mysite\venv\Lib\site-packages\django\db\backends\base\base.py", line 289, in ensure_connection
    self.connect()
  File "C:\mysite\venv\Lib\site-packages\django\utils\asyncio.py", line 26, in inner
    return func(*args, **kwargs)
           ^^^^^^^^^^^^^^^^^^^^^
  File "C:\mysite\venv\Lib\site-packages\django\db\backends\base\base.py", line 270, in connect
    self.connection = self.get_new_connection(conn_params)
                      ^^^^^^^^^^^^^^^^^^^^^^^^^^^^^^^^^^^^
  File "C:\mysite\venv\Lib\site-packages\django\utils\asyncio.py", line 26, in inner
    return func(*args, **kwargs)
           ^^^^^^^^^^^^^^^^^^^^^
  File "C:\mysite\venv\Lib\site-packages\django\db\backends\postgresql\base.py", line 275, in get_new_connection
    connection = self.Database.connect(**conn_params)
                 ^^^^^^^^^^^^^^^^^^^^^^^^^^^^^^^^^^^^
  File "C:\mysite\venv\Lib\site-packages\psycopg2\__init__.py", line 122, in connect
    conn = _connect(dsn, connection_factory=connection_factory, **kwasync)
           ^^^^^^^^^^^^^^^^^^^^^^^^^^^^^^^^^^^^^^^^^^^^^^^^^^^^^^^^^^^^^^^
django.db.utils.OperationalError: connection to server at "localhost" (::1), port 5433 failed: Connection refused (0x0000274D/10061)
	Is the server running on that host and accepting TCP/IP connections?
connection to server at "localhost" (127.0.0.1), port 5433 failed: Connection refused (0x0000274D/10061)
	Is the server running on that host and accepting TCP/IP connections?

"GET / HTTP/1.1" 500 205681
Internal Server Error: /
Traceback (most recent call last):
  File "C:\mysite\venv\Lib\site-packages\django\contrib\sessions\backends\base.py", line 187, in _get_session
    return self._session_cache
           ^^^^^^^^^^^^^^^^^^^
AttributeError: 'SessionStore' object has no attribute '_session_cache'

During handling of the above exception, another exception occurred:

Traceback (most recent call last):
  File "C:\mysite\venv\Lib\site-packages\django\db\backends\base\base.py", line 289, in ensure_connection
    self.connect()
  File "C:\mysite\venv\Lib\site-packages\django\utils\asyncio.py", line 26, in inner
    return func(*args, **kwargs)
           ^^^^^^^^^^^^^^^^^^^^^
  File "C:\mysite\venv\Lib\site-packages\django\db\backends\base\base.py", line 270, in connect
    self.connection = self.get_new_connection(conn_params)
                      ^^^^^^^^^^^^^^^^^^^^^^^^^^^^^^^^^^^^
  File "C:\mysite\venv\Lib\site-packages\django\utils\asyncio.py", line 26, in inner
    return func(*args, **kwargs)
           ^^^^^^^^^^^^^^^^^^^^^
  File "C:\mysite\venv\Lib\site-packages\django\db\backends\postgresql\base.py", line 275, in get_new_connection
    connection = self.Database.connect(**conn_params)
                 ^^^^^^^^^^^^^^^^^^^^^^^^^^^^^^^^^^^^
  File "C:\mysite\venv\Lib\site-packages\psycopg2\__init__.py", line 122, in connect
    conn = _connect(dsn, connection_factory=connection_factory, **kwasync)
           ^^^^^^^^^^^^^^^^^^^^^^^^^^^^^^^^^^^^^^^^^^^^^^^^^^^^^^^^^^^^^^^
psycopg2.OperationalError: connection to server at "localhost" (::1), port 5433 failed: Connection refused (0x0000274D/10061)
	Is the server running on that host and accepting TCP/IP connections?
connection to server at "localhost" (127.0.0.1), port 5433 failed: Connection refused (0x0000274D/10061)
	Is the server running on that host and accepting TCP/IP connections?


The above exception was the direct cause of the following exception:

Traceback (most recent call last):
  File "C:\mysite\venv\Lib\site-packages\django\core\handlers\exception.py", line 55, in inner
    response = get_response(request)
               ^^^^^^^^^^^^^^^^^^^^^
  File "C:\mysite\venv\Lib\site-packages\django\utils\deprecation.py", line 136, in __call__
    response = self.process_response(request, response)
               ^^^^^^^^^^^^^^^^^^^^^^^^^^^^^^^^^^^^^^^^
  File "C:\mysite\venv\Lib\site-packages\django\contrib\sessions\middleware.py", line 48, in process_response
    if request.session.get_expire_at_browser_close():
       ^^^^^^^^^^^^^^^^^^^^^^^^^^^^^^^^^^^^^^^^^^^^^
  File "C:\mysite\venv\Lib\site-packages\django\contrib\sessions\backends\base.py", line 285, in get_expire_at_browser_close
    if (expiry := self.get("_session_expiry")) is None:
                  ^^^^^^^^^^^^^^^^^^^^^^^^^^^
  File "C:\mysite\venv\Lib\site-packages\django\contrib\sessions\backends\base.py", line 68, in get
    return self._session.get(key, default)
           ^^^^^^^^^^^^^
  File "C:\mysite\venv\Lib\site-packages\django\contrib\sessions\backends\base.py", line 192, in _get_session
    self._session_cache = self.load()
                          ^^^^^^^^^^^
  File "C:\mysite\venv\Lib\site-packages\django\contrib\sessions\backends\db.py", line 42, in load
    s = self._get_session_from_db()
        ^^^^^^^^^^^^^^^^^^^^^^^^^^^
  File "C:\mysite\venv\Lib\site-packages\django\contrib\sessions\backends\db.py", line 32, in _get_session_from_db
    return self.model.objects.get(
           ^^^^^^^^^^^^^^^^^^^^^^^
  File "C:\mysite\venv\Lib\site-packages\django\db\models\manager.py", line 87, in manager_method
    return getattr(self.get_queryset(), name)(*args, **kwargs)
           ^^^^^^^^^^^^^^^^^^^^^^^^^^^^^^^^^^^^^^^^^^^^^^^^^^^
  File "C:\mysite\venv\Lib\site-packages\django\db\models\query.py", line 633, in get
    num = len(clone)
          ^^^^^^^^^^
  File "C:\mysite\venv\Lib\site-packages\django\db\models\query.py", line 380, in __len__
    self._fetch_all()
  File "C:\mysite\venv\Lib\site-packages\django\db\models\query.py", line 1881, in _fetch_all
    self._result_cache = list(self._iterable_class(self))
                         ^^^^^^^^^^^^^^^^^^^^^^^^^^^^^^^^
  File "C:\mysite\venv\Lib\site-packages\django\db\models\query.py", line 91, in __iter__
    results = compiler.execute_sql(
              ^^^^^^^^^^^^^^^^^^^^^
  File "C:\mysite\venv\Lib\site-packages\django\db\models\sql\compiler.py", line 1560, in execute_sql
    cursor = self.connection.cursor()
             ^^^^^^^^^^^^^^^^^^^^^^^^
  File "C:\mysite\venv\Lib\site-packages\django\utils\asyncio.py", line 26, in inner
    return func(*args, **kwargs)
           ^^^^^^^^^^^^^^^^^^^^^
  File "C:\mysite\venv\Lib\site-packages\django\db\backends\base\base.py", line 330, in cursor
    return self._cursor()
           ^^^^^^^^^^^^^^
  File "C:\mysite\venv\Lib\site-packages\django\db\backends\base\base.py", line 306, in _cursor
    self.ensure_connection()
  File "C:\mysite\venv\Lib\site-packages\django\utils\asyncio.py", line 26, in inner
    return func(*args, **kwargs)
           ^^^^^^^^^^^^^^^^^^^^^
  File "C:\mysite\venv\Lib\site-packages\django\db\backends\base\base.py", line 288, in ensure_connection
    with self.wrap_database_errors:
  File "C:\mysite\venv\Lib\site-packages\django\db\utils.py", line 91, in __exit__
    raise dj_exc_value.with_traceback(traceback) from exc_value
  File "C:\mysite\venv\Lib\site-packages\django\db\backends\base\base.py", line 289, in ensure_connection
    self.connect()
  File "C:\mysite\venv\Lib\site-packages\django\utils\asyncio.py", line 26, in inner
    return func(*args, **kwargs)
           ^^^^^^^^^^^^^^^^^^^^^
  File "C:\mysite\venv\Lib\site-packages\django\db\backends\base\base.py", line 270, in connect
    self.connection = self.get_new_connection(conn_params)
                      ^^^^^^^^^^^^^^^^^^^^^^^^^^^^^^^^^^^^
  File "C:\mysite\venv\Lib\site-packages\django\utils\asyncio.py", line 26, in inner
    return func(*args, **kwargs)
           ^^^^^^^^^^^^^^^^^^^^^
  File "C:\mysite\venv\Lib\site-packages\django\db\backends\postgresql\base.py", line 275, in get_new_connection
    connection = self.Database.connect(**conn_params)
                 ^^^^^^^^^^^^^^^^^^^^^^^^^^^^^^^^^^^^
  File "C:\mysite\venv\Lib\site-packages\psycopg2\__init__.py", line 122, in connect
    conn = _connect(dsn, connection_factory=connection_factory, **kwasync)
           ^^^^^^^^^^^^^^^^^^^^^^^^^^^^^^^^^^^^^^^^^^^^^^^^^^^^^^^^^^^^^^^
django.db.utils.OperationalError: connection to server at "localhost" (::1), port 5433 failed: Connection refused (0x0000274D/10061)
	Is the server running on that host and accepting TCP/IP connections?
connection to server at "localhost" (127.0.0.1), port 5433 failed: Connection refused (0x0000274D/10061)
	Is the server running on that host and accepting TCP/IP connections?

"GET / HTTP/1.1" 500 205681
Not Found: /admin
"GET /admin HTTP/1.1" 404 5127
Not Found: /store
"GET /store HTTP/1.1" 404 5125
"GET /api/carts/ HTTP/1.1" 200 260
"GET /cart/ HTTP/1.1" 200 5899
"GET / HTTP/1.1" 200 2403
Watching for file changes with StatReloader
"GET /cart/ HTTP/1.1" 302 0
"GET /login/?next=/cart/ HTTP/1.1" 200 697
Not Found: /favicon.ico
"GET /favicon.ico HTTP/1.1" 404 6455
Unauthorized: /api/auth/login/
"POST /api/auth/login/ HTTP/1.1" 401 63
"POST /login/?next=/cart/ HTTP/1.1" 200 788
"GET / HTTP/1.1" 200 2049
"GET /api/products/ HTTP/1.1" 200 2
"GET /products/ HTTP/1.1" 200 2611
"GET /cart/ HTTP/1.1" 302 0
"GET /login/?next=/cart/ HTTP/1.1" 200 697
"GET /register/ HTTP/1.1" 200 6105
"POST /api/auth/register/ HTTP/1.1" 201 96
"POST /register/ HTTP/1.1" 200 6720
"GET /profile/ HTTP/1.1" 200 7905
"GET /static/store/images/profile-avatar.jpg HTTP/1.1" 404 2020
"GET /cart/ HTTP/1.1" 302 0
"GET /login/ HTTP/1.1" 200 697
"GET / HTTP/1.1" 200 2403
"GET /api/products/ HTTP/1.1" 200 2
"GET /products/ HTTP/1.1" 200 2965
"GET / HTTP/1.1" 200 2403
"GET /api/products/ HTTP/1.1" 200 2
"GET /products/ HTTP/1.1" 200 2965
"GET /cart/ HTTP/1.1" 302 0
"GET /login/ HTTP/1.1" 200 697
"GET / HTTP/1.1" 200 2403
"GET /profile/ HTTP/1.1" 200 7905
"GET /static/store/images/profile-avatar.jpg HTTP/1.1" 404 2020
"POST /logout/ HTTP/1.1" 302 0
"GET / HTTP/1.1" 200 2388
"GET /login/ HTTP/1.1" 200 697
"GET /register/ HTTP/1.1" 200 6105
Bad Request: /api/auth/register/
"POST /api/auth/register/ HTTP/1.1" 400 58
Internal Server Error: /register/
Traceback (most recent call last):
  File "/usr/local/lib/python3.11/site-packages/django/core/handlers/exception.py", line 55, in inner
    response = get_response(request)
               ^^^^^^^^^^^^^^^^^^^^^
  File "/usr/local/lib/python3.11/site-packages/django/core/handlers/base.py", line 204, in _get_response
    self.check_response(response, callback)
  File "/usr/local/lib/python3.11/site-packages/django/core/handlers/base.py", line 332, in check_response
    raise ValueError(
ValueError: The view store.views.view didn't return an HttpResponse object. It returned None instead.
"POST /register/ HTTP/1.1" 500 62056
"GET /api/products/ HTTP/1.1" 200 2
"GET /products/ HTTP/1.1" 200 2611
"GET /cart/ HTTP/1.1" 302 0
"GET /login/?next=/cart/ HTTP/1.1" 200 697
Unauthorized: /api/auth/login/
"POST /api/auth/login/ HTTP/1.1" 401 63
"POST /login/?next=/cart/ HTTP/1.1" 200 788
Unauthorized: /api/auth/login/
"POST /api/auth/login/ HTTP/1.1" 401 63
"POST /login/?next=/cart/ HTTP/1.1" 200 788
"GET /register/ HTTP/1.1" 200 6105
Bad Request: /api/auth/register/
"POST /api/auth/register/ HTTP/1.1" 400 58
Internal Server Error: /register/
Traceback (most recent call last):
  File "/usr/local/lib/python3.11/site-packages/django/core/handlers/exception.py", line 55, in inner
    response = get_response(request)
               ^^^^^^^^^^^^^^^^^^^^^
  File "/usr/local/lib/python3.11/site-packages/django/core/handlers/base.py", line 204, in _get_response
    self.check_response(response, callback)
  File "/usr/local/lib/python3.11/site-packages/django/core/handlers/base.py", line 332, in check_response
    raise ValueError(
ValueError: The view store.views.view didn't return an HttpResponse object. It returned None instead.
"POST /register/ HTTP/1.1" 500 62056
Watching for file changes with StatReloader
Watching for file changes with StatReloader
